Workbook

Sheet Formato
A1: Fecha | F1: Turno
A3: REGISTRO DE VENTAS
A4: Sin registro en dodozooft
A5: Folio Voucher | B5: Forma de Pago | F5: Descripción
B6: Efectivo | C6: Debito | D6: Credito | E6: Transf
A24: Totales | B24: =SUM($B7:$B23) -> 0 | C24: =SUM($C7:$C23) -> 0 | D24: =SUM($D7:$D23) -> 0 | E24: =SUM($E7:$E23) -> 0
J26: TOTAL VENTAS | K26: =$B$24+$C$24+$D$24+$E$24 -> 0
G28: INGRESOS - EGRESOS
A29: VENTAS - INGRESOS | D29: VENTAS | F29: COMPRAS - EGRESOS | I29: SALIDAS A CAJA
C30: Descripcion | E30: Total | I30: Descripcion | K30: Total
C31: Total Efectivo | E31: =B24 -> 0 | I31: Efectivo
C32: Total Debito | E32: =C24 -> 0 | I32: Transferencia
C33: Total Credito | E33: =D24 -> 0 | I33: Otro
C34: Total Transferencia | E34: =E24 -> 0
C35: TOTAL VENTAS | E35: =SUM(E31:E34) -> 0
C36: ENTRADAS A CAJA
C37: Descripcion | E37: Total
C38: Efectivo | I38: TOTAL OTROS EGRESOS | K38: =SUM(K31:K37) -> 0
C39: Otro | I39: RETIRO DE EFECTIVO
C40: TOTAL OTROS INGRESOS | E40: =SUM(E38:E39) -> 0 | I40: Cantidad a Retirar
D41: TOTAL INGRESOS | E41: =E35+E40 -> 0 | J41: TOTAL EGRESOS | K41: =K38+K40 -> 0
G43: ARQUEO DE CAJA
A44: BILLETES | C44: Valor | D44: Cantidad | E44: Total | F44: MONEDAS | I44: Valor | J44: Cantidad | K44: Total
C45: 20000 | E45: =C45*D45 -> 0 | I45: 500 | K45: =I45*J45 -> 0
C46: 10000 | E46: =C46*D46 -> 0 | I46: 100 | K46: =I46*J46 -> 0
C47: 5000 | E47: =C47*D47 -> 0 | I47: 50 | K47: =I47*J47 -> 0
C48: 2000 | E48: =C48*D48 -> 0 | I48: 10 | K48: =I48*J48 -> 0
C49: 1000 | E49: =C49*D49 -> 0
D50: TOTAL BILLETES | E50: =SUM(E45:E49) -> 0 | J50: TOTAL MONEDAS | K50: =SUM(K45:K49) -> 0
H52: RESUMEN ARQUEO DE CAJA
B54: OBSERVACIONES: | H54: APERTURA DE CAJA | I54: 0
H56: TOTAL EFECTIVO FISICO | I56: =E50+K50 -> 0
H58: TOTAL VENTAS | I58: =K26 -> 0
H60: ENTRADAS A CAJA | I60: =E38 -> 0
H62: SALIDAS A CAJA | I62: =K31+K40 -> 0
H64: TOTAL EN CAJA CON APERTURA | I64: =I54+I58+I60-I62 -> 0
H66: TOTAL EN CAJA | I66: =I64-I54 -> 0
H68: CAJA FINAL EFECTIVO | I68: =I54+E31+(E38-(K31+K40)) -> 0
H70: DIFERENCIA | I70: =I56-I68 -> 0

Sheet 27-07-2024
A1: Fecha | C1: 45500 | F1: Turno | H1: Augustina y Sasha- Turno completo
A3: REGISTRO DE VENTAS
A4: Sin registro en dodozooft
A5: Folio Voucher | B5: Forma de Pago | F5: Descripción
B6: Efectivo | C6: Debito | D6: Credito | E6: Transf
A7: 104 | C7: 35000 | F7: Esterilización felina
A8: 105 | C8: 143500 | F8: Hemograma + P. bioquímico +electrolitos (16.000) + cistocentesis (35.000) + Urianálisis+UP (18.000)+ Eco FAST (25.000)
A9: 106 | C9: 80000 | F9: Ecografía exótico+sedación
A10: 96 | C10: 16700 | F10: dermisolona
A11: 107 | D11: 24990 | F11: sedación felina
A12: 108 | C12: 20990 | F12: Paga pendiente: en dodo hacer boleta de tto (30.990) y descontar 10.000
A13: 109 | C13: 24990 | F13: tratamiento
A14: 110 | C14: 25000 | F14: castración
A15: 111 | C15: 20000 | F15: consulta exótico
A16: 97 | C16: 25200 | F16: 2 x sustrato my pet litter (7.500) + juguete timoty zanahoria (10.200)
A17: 112 | C17: 38480 | F17: 6663: aplicación mebermic (5.500) + antirrábica + sextuple
A18: 113 | C18: 372000 | F18: 6664: Pago1: Hosp 24 hrs (50.000)+tto intrahosp (24.990)+anestesia inhalatoria (45.000)+ enfermería (25.000) + cirugía oncológica (160.000) + cirugía reconstructiva (110.000) +biopsia (28.000) + insumos (30.000)
A19: 114 | D19: 100000 | F19: 6664:Pago2: Hosp 24 hrs (50.000)+tto intrahosp (24.990)+anestesia inhalatoria (45.000)+ enfermería (25.000) + cirugía oncológica (160.000) + cirugía reconstructiva (110.000) +biopsia (28.000) + insumos (30.000)
B20: 10000 | F20: 6665: CONSULTA
A21: 115 | C21: 7500 | F21: 6666: corte de uñas
A22: 98 | C22: 12400 | F22: 20943: Naxpet
A24: Totales | B24: =SUM($B7:$B23) -> 10000 | C24: =SUM($C7:$C23) -> 821760 | D24: =SUM($D7:$D23) -> 124990 | E24: =SUM($E7:$E23) -> 0
J26: TOTAL VENTAS | K26: =$B$24+$C$24+$D$24+$E$24 -> 956750
G28: INGRESOS - EGRESOS
A29: VENTAS - INGRESOS | D29: VENTAS | F29: COMPRAS - EGRESOS | I29: SALIDAS A CAJA
C30: Descripcion | E30: Total | I30: Descripcion | K30: Total
C31: Total Efectivo | E31: =B24 -> 10000 | I31: Efectivo | K31: 20000
C32: Total Debito | E32: =C24 -> 821760 | I32: Transferencia
C33: Total Credito | E33: =D24 -> 124990 | I33: Otro
C34: Total Transferencia | E34: =E24 -> 0
C35: TOTAL VENTAS | E35: =SUM(E31:E34) -> 956750
C36: ENTRADAS A CAJA
C37: Descripcion | E37: Total
C38: Efectivo | I38: TOTAL OTROS EGRESOS | K38: =SUM(K31:K37) -> 20000
C39: Otro | I39: RETIRO DE EFECTIVO
C40: TOTAL OTROS INGRESOS | E40: =SUM(E38:E39) -> 0 | I40: Cantidad a Retirar
D41: TOTAL INGRESOS | E41: =E35+E40 -> 956750 | J41: TOTAL EGRESOS | K41: =K38+K40 -> 20000
G43: ARQUEO DE CAJA
A44: BILLETES | C44: Valor | D44: Cantidad | E44: Total | F44: MONEDAS | I44: Valor | J44: Cantidad | K44: Total
C45: 20000 | E45: =C45*D45 -> 0 | I45: 500 | J45: 2 | K45: =I45*J45 -> 1000
...

Sheet 26-07-2024
A1: Fecha | C1: 45499 | F1: Turno | H1: Augustina Drago- Medio turno
A3: REGISTRO DE VENTAS
A4: Sin registro en dodozooft
A5: Folio Voucher | B5: Forma de Pago | F5: Descripción
B6: Efectivo | C6: Debito | D6: Credito | E6: Transf
A7: 100 | C7: 35000 | F7: Esterilización felina
A8: 93 | C8: 17490 | F8: Nexgard 10-25kg
A9: 101 | C9: 35000 | F9: Domicilio exótico
A10: 102 | C10: 250000 | F10: cirugía piometra
A11: 103 | C11: 17990 | F11: vacuna
A12: 94*AFECTA | C12: 25000 | F12: hospitalización
A24: Totales | B24: =SUM($B7:$B23) -> 0 | C24: =SUM($C7:$C23) -> 380480 | D24: =SUM($D7:$D23) -> 0 | E24: =SUM($E7:$E23) -> 0
J26: TOTAL VENTAS | K26: =$B$24+$C$24+$D$24+$E$24 -> 380480
G28: INGRESOS - EGRESOS
A29: VENTAS - INGRESOS | D29: VENTAS | F29: COMPRAS - EGRESOS | I29: SALIDAS A CAJA
C30: Descripcion | E30: Total | I30: Descripcion | K30: Total
C31: Total Efectivo | E31: =B24 -> 0 | I31: Efectivo
C32: Total Debito | E32: =C24 -> 380480 | I32: Transferencia
C33: Total Credito | E33: =D24 -> 0 | I33: Otro
C34: Total Transferencia | E34: =E24 -> 0
C35: TOTAL VENTAS | E35: =SUM(E31:E34) -> 380480
C36: ENTRADAS A CAJA
C37: Descripcion | E37: Total
C38: Efectivo | I38: TOTAL OTROS EGRESOS | K38: =SUM(K31:K37) -> 0
C39: Otro | I39: RETIRO DE EFECTIVO
C40: TOTAL OTROS INGRESOS | E40: =SUM(E38:E39) -> 0 | I40: Cantidad a Retirar
D41: TOTAL INGRESOS | E41: =E35+E40 -> 380480 | J41: TOTAL EGRESOS | K41: =K38+K40 -> 0
G43: ARQUEO DE CAJA
A44: BILLETES | C44: Valor | D44: Cantidad | E44: Total | F44: MONEDAS | I44: Valor | J44: Cantidad | K44: Total
C45: 20000 | D45: 1 | E45: =C45*D45 -> 20000 | I45: 500 | J45: 2 | K45: =I45*J45 -> 1000
C46: 10000 | E46: =C46*D46 -> 0 | I46: 100 | J46: 31 | K46: =I46*J46 -> 3100
C47: 5000 | E47: =C47*D47 -> 0 | I47: 50 | J47: 8 | K47: =I47*J47 -> 400
C48: 2000 | E48: =C48*D48 -> 0 | I48: 10 | J48: 13 | K48: =I48*J48 -> 130
C49: 1000 | E49: =C49*D49 -> 0
D50: TOTAL BILLETES | E50: =SUM(E45:E49) -> 20000 | J50: TOTAL MONEDAS | K50: =SUM(K45:K49) -> 4630
H52: RESUMEN ARQUEO DE CAJA
B54: OBSERVACIONES: | H54: APERTURA DE CAJA | I54: 24630
H56: TOTAL EFECTIVO FISICO | I56: =E50+K50 -> 24630
H58: TOTAL VENTAS | I58: =K26 -> 380480
H60: ENTRADAS A CAJA | I60: =E38 -> 0
...

Sheet 25-07-2024
A1: Fecha | C1: 45498 | F1: Turno | H1: Augustina turno completo
A3: REGISTRO DE VENTAS
A4: Sin registro en dodozooft
A5: Folio Voucher | B5: Forma de Pago | F5: Descripción
B6: Efectivo | C6: Debito | D6: Credito | E6: Transf
A7: 95 | C7: 45000 | F7: 6644: radiografia
B8: 10000 | F8: 6645: consulta
A9: 96 | C9: 17990 | F9: 6646: triplefelina
A10: 97 | C10: 196090 | F10: 6647: hosp 24hrs
A11: 98 | C11: 25000 | F11: 6648: Hosp 3 (25.000)
A12: 99 | C12: 17990 | F12: 6649: vacuna sextuple
A24: Totales | B24: =SUM($B7:$B23) -> 10000 | C24: =SUM($C7:$C23) -> 302070 | D24: =SUM($D7:$D23) -> 0 | E24: =SUM($E7:$E23) -> 0
J26: TOTAL VENTAS | K26: =$B$24+$C$24+$D$24+$E$24 -> 312070
G28: INGRESOS - EGRESOS
A29: VENTAS - INGRESOS | D29: VENTAS | F29: COMPRAS - EGRESOS | I29: SALIDAS A CAJA
C30: Descripcion | E30: Total | I30: Descripcion | K30: Total
C31: Total Efectivo | E31: =B24 -> 10000 | I31: Efectivo
C32: Total Debito | E32: =C24 -> 302070 | I32: Transferencia
C33: Total Credito | E33: =D24 -> 0 | I33: Otro
C34: Total Transferencia | E34: =E24 -> 0
C35: TOTAL VENTAS | E35: =SUM(E31:E34) -> 312070
C36: ENTRADAS A CAJA
C37: Descripcion | E37: Total
C38: Efectivo | I38: TOTAL OTROS EGRESOS | K38: =SUM(K31:K37) -> 0
C39: Otro | I39: RETIRO DE EFECTIVO
C40: TOTAL OTROS INGRESOS | E40: =SUM(E38:E39) -> 0 | I40: Cantidad a Retirar
D41: TOTAL INGRESOS | E41: =E35+E40 -> 312070 | J41: TOTAL EGRESOS | K41: =K38+K40 -> 0
G43: ARQUEO DE CAJA
A44: BILLETES | C44: Valor | D44: Cantidad | E44: Total | F44: MONEDAS | I44: Valor | J44: Cantidad | K44: Total
C45: 20000 | D45: 1 | E45: =C45*D45 -> 20000 | I45: 500 | J45: 2 | K45: =I45*J45 -> 1000
C46: 10000 | E46: =C46*D46 -> 0 | I46: 100 | J46: 31 | K46: =I46*J46 -> 3100
C47: 5000 | E47: =C47*D47 -> 0 | I47: 50 | J47: 8 | K47: =I47*J47 -> 400
C48: 2000 | E48: =C48*D48 -> 0 | I48: 10 | J48: 13 | K48: =I48*J48 -> 130
C49: 1000 | E49: =C49*D49 -> 0
D50: TOTAL BILLETES | E50: =SUM(E45:E49) -> 20000 | J50: TOTAL MONEDAS | K50: =SUM(K45:K49) -> 4630
H52: RESUMEN ARQUEO DE CAJA
B54: OBSERVACIONES: | H54: APERTURA DE CAJA | I54: 14630
H56: TOTAL EFECTIVO FISICO | I56: =E50+K50 -> 24630
H58: TOTAL VENTAS | I58: =K26 -> 312070
H60: ENTRADAS A CAJA | I60: =E38 -> 0
...

Sheet 24-07-2024 
A1: Fecha | C1: 45497 | F1: Turno | H1: Augustina Drago-Turno completo
A3: REGISTRO DE VENTAS
A4: Sin registro en dodozooft
A5: Folio Voucher | B5: Forma de Pago | F5: Descripción
B6: Efectivo | C6: Debito | D6: Credito | E6: Transf
A7: 91 | C7: 10000 | F7: 6639: medio pago de tto 30.990
A8: 92 | C8: 68500 | F8: 6640: 35000 perfil+toma de muestras 17500+ exam lab 13000+3000 retiro
A9: 93 | C9: 195490 | F9: 6641: Hospital conejo: consulta exotico + hospital 24 hrs (50) + tto 2 (30.990) + hm+pb +45rx
B10: 20000 | F10: 6642: consulta exótico
A11: 90 | C11: 2990 | F11: 20938: shaky pollo
A12: 94 | C12: 25000 | F12: 6643: Hosp 3 (25000)
A24: Totales | B24: =SUM($B7:$B23) -> 20000 | C24: =SUM($C7:$C23) -> 301980 | D24: =SUM($D7:$D23) -> 0 | E24: =SUM($E7:$E23) -> 0
J26: TOTAL VENTAS | K26: =$B$24+$C$24+$D$24+$E$24 -> 321980
G28: INGRESOS - EGRESOS
A29: VENTAS - INGRESOS | D29: VENTAS | F29: COMPRAS - EGRESOS | I29: SALIDAS A CAJA
C30: Descripcion | E30: Total | I30: Descripcion | K30: Total
C31: Total Efectivo | E31: =B24 -> 20000 | I31: Efectivo | K31: 60000
C32: Total Debito | E32: =C24 -> 301980 | I32: Transferencia
C33: Total Credito | E33: =D24 -> 0 | I33: Otro
C34: Total Transferencia | E34: =E24 -> 0
C35: TOTAL VENTAS | E35: =SUM(E31:E34) -> 321980
C36: ENTRADAS A CAJA
C37: Descripcion | E37: Total
C38: Efectivo | I38: TOTAL OTROS EGRESOS | K38: =SUM(K31:K37) -> 60000
C39: Otro | I39: RETIRO DE EFECTIVO
C40: TOTAL OTROS INGRESOS | E40: =SUM(E38:E39) -> 0 | I40: Cantidad a Retirar
D41: TOTAL INGRESOS | E41: =E35+E40 -> 321980 | J41: TOTAL EGRESOS | K41: =K38+K40 -> 60000
G43: ARQUEO DE CAJA
A44: BILLETES | C44: Valor | D44: Cantidad | E44: Total | F44: MONEDAS | I44: Valor | J44: Cantidad | K44: Total
C45: 20000 | E45: =C45*D45 -> 0 | I45: 500 | J45: 2 | K45: =I45*J45 -> 1000
C46: 10000 | D46: 1 | E46: =C46*D46 -> 10000 | I46: 100 | J46: 31 | K46: =I46*J46 -> 3100
C47: 5000 | E47: =C47*D47 -> 0 | I47: 50 | J47: 8 | K47: =I47*J47 -> 400
C48: 2000 | E48: =C48*D48 -> 0 | I48: 10 | J48: 13 | K48: =I48*J48 -> 130
C49: 1000 | E49: =C49*D49 -> 0
D50: TOTAL BILLETES | E50: =SUM(E45:E49) -> 10000 | J50: TOTAL MONEDAS | K50: =SUM(K45:K49) -> 4630
H52: RESUMEN ARQUEO DE CAJA
B54: OBSERVACIONES: | H54: APERTURA DE CAJA | I54: 54630
B56: RETIRO CAJA 60.000 | H56: TOTAL EFECTIVO FISICO | I56: =E50+K50 -> 14630
H58: TOTAL VENTAS | I58: =K26 -> 321980
H60: ENTRADAS A CAJA | I60: =E38 -> 0
...

Sheet 23-07-2024
A1: Fecha | C1: 45496 | F1: Turno | H1: Augustina Drago-Turno completo
A3: REGISTRO DE VENTAS
A4: CON registro en dodozooft
A5: Folio Voucher | B5: Forma de Pago | F5: Descripción
B6: Efectivo | C6: Debito | D6: Credito | E6: Transf
A7: 85 | C7: 50000 | F7: 6632: Consulta y eutanasia hamster
A8: 86 | C8: 152100 | F8: 6634: examen leucemia (35.000)+ 2 calibralife (2x3800)+hemograma y perfil bioquímico (49.500) + consulta (10.000) + hospitalización 24hrs (50.000)
A9: 87 | C9: 10000 | F9: 6633: consulta
A10: 88 | D10: 151690 | F10: 6635: Hospitalización 24hrs (50.000)+Hemograma y perfil bioquimico (49.500) + tratamientos intrahospitalario (30.990) + alimentacion medicada (10.600)
A11: 89 | C11: 17990 | F11: 6636: vacuna leucemia
A12: 90 | C12: 10000 | F12: 6637: consulta
B13: 7500 | F13: 6638: corte de uñas
A24: Totales | B24: =SUM($B7:$B23) -> 7500 | C24: =SUM($C7:$C23) -> 240090 | D24: =SUM($D7:$D23) -> 151690 | E24: =SUM($E7:$E23) -> 0
J26: TOTAL VENTAS | K26: =$B$24+$C$24+$D$24+$E$24 -> 399280
G28: INGRESOS - EGRESOS
A29: VENTAS - INGRESOS | D29: VENTAS | F29: COMPRAS - EGRESOS | I29: SALIDAS A CAJA
C30: Descripcion | E30: Total | I30: Descripcion | K30: Total
C31: Total Efectivo | E31: =B24 -> 7500 | I31: Efectivo | K31: 30000
C32: Total Debito | E32: =C24 -> 240090 | I32: Transferencia
C33: Total Credito | E33: =D24 -> 151690 | I33: Otro
C34: Total Transferencia | E34: =E24 -> 0
C35: TOTAL VENTAS | E35: =SUM(E31:E34) -> 399280
C36: ENTRADAS A CAJA
C37: Descripcion | E37: Total
C38: Efectivo | I38: TOTAL OTROS EGRESOS | K38: =SUM(K31:K37) -> 30000
C39: Otro | I39: RETIRO DE EFECTIVO
C40: TOTAL OTROS INGRESOS | E40: =SUM(E38:E39) -> 0 | I40: Cantidad a Retirar
D41: TOTAL INGRESOS | E41: =E35+E40 -> 399280 | J41: TOTAL EGRESOS | K41: =K38+K40 -> 30000
G43: ARQUEO DE CAJA
A44: BILLETES | C44: Valor | D44: Cantidad | E44: Total | F44: MONEDAS | I44: Valor | J44: Cantidad | K44: Total
C45: 20000 | E45: =C45*D45 -> 0 | I45: 500 | J45: 2 | K45: =I45*J45 -> 1000
C46: 10000 | D46: 5 | E46: =C46*D46 -> 50000 | I46: 100 | J46: 31 | K46: =I46*J46 -> 3100
C47: 5000 | E47: =C47*D47 -> 0 | I47: 50 | J47: 8 | K47: =I47*J47 -> 400
C48: 2000 | E48: =C48*D48 -> 0 | I48: 10 | J48: 13 | K48: =I48*J48 -> 130
C49: 1000 | E49: =C49*D49 -> 0
D50: TOTAL BILLETES | E50: =SUM(E45:E49) -> 50000 | J50: TOTAL MONEDAS | K50: =SUM(K45:K49) -> 4630
H52: RESUMEN ARQUEO DE CAJA
B54: OBSERVACIONES: | H54: APERTURA DE CAJA | I54: 77130
B56: 10.000 retiro caja + 20.000 pago Jimena | H56: TOTAL EFECTIVO FISICO | I56: =E50+K50 -> 54630
H58: TOTAL VENTAS | I58: =K26 -> 399280
...

Sheet 22-07-2024
A1: Fecha | F1: Turno
A3: REGISTRO DE VENTAS
A4: CON registro en dodozooft
A5: Folio Voucher | B5: Forma de Pago | F5: Descripción
B6: Efectivo | C6: Debito | D6: Credito | E6: Transf
A7: 83 | C7: 27500 | F7: 6630: consulta+ desp int y ext
A8: 86 | C8: 28600 | F8: 20936: Pipeta puppy + arnes gato+ collar fluorescente gato
A9: 84 | C9: 10000 | F9: 6631: consulta
A10: 87 | C10: 16700 | F10: 20937: dermisolona
A24: Totales | B24: =SUM($B7:$B23) -> 0 | C24: =SUM($C7:$C23) -> 82800 | D24: =SUM($D7:$D23) -> 0 | E24: =SUM($E7:$E23) -> 0
J26: TOTAL VENTAS | K26: =$B$24+$C$24+$D$24+$E$24 -> 82800
G28: INGRESOS - EGRESOS
A29: VENTAS - INGRESOS | D29: VENTAS | F29: COMPRAS - EGRESOS | I29: SALIDAS A CAJA
C30: Descripcion | E30: Total | I30: Descripcion | K30: Total
C31: Total Efectivo | E31: =B24 -> 0 | I31: Efectivo
C32: Total Debito | E32: =C24 -> 82800 | I32: Transferencia
C33: Total Credito | E33: =D24 -> 0 | I33: Otro
C34: Total Transferencia | E34: =E24 -> 0
C35: TOTAL VENTAS | E35: =SUM(E31:E34) -> 82800
C36: ENTRADAS A CAJA
C37: Descripcion | E37: Total
C38: Efectivo | I38: TOTAL OTROS EGRESOS | K38: =SUM(K31:K37) -> 0
C39: Otro | I39: RETIRO DE EFECTIVO
C40: TOTAL OTROS INGRESOS | E40: =SUM(E38:E39) -> 0 | I40: Cantidad a Retirar
D41: TOTAL INGRESOS | E41: =E35+E40 -> 82800 | J41: TOTAL EGRESOS | K41: =K38+K40 -> 0
G43: ARQUEO DE CAJA
A44: BILLETES | C44: Valor | D44: Cantidad | E44: Total | F44: MONEDAS | I44: Valor | J44: Cantidad | K44: Total
C45: 20000 | E45: =C45*D45 -> 0 | I45: 500 | J45: 3 | K45: =I45*J45 -> 1500
C46: 10000 | D46: 7 | E46: =C46*D46 -> 70000 | I46: 100 | J46: 31 | K46: =I46*J46 -> 3100
C47: 5000 | E47: =C47*D47 -> 0 | I47: 50 | J47: 8 | K47: =I47*J47 -> 400
C48: 2000 | D48: 1 | E48: =C48*D48 -> 2000 | I48: 10 | J48: 13 | K48: =I48*J48 -> 130
C49: 1000 | E49: =C49*D49 -> 0
D50: TOTAL BILLETES | E50: =SUM(E45:E49) -> 72000 | J50: TOTAL MONEDAS | K50: =SUM(K45:K49) -> 5130
H52: RESUMEN ARQUEO DE CAJA
B54: OBSERVACIONES: | H54: APERTURA DE CAJA | I54: 77130
H56: TOTAL EFECTIVO FISICO | I56: =E50+K50 -> 77130
H58: TOTAL VENTAS | I58: =K26 -> 82800
H60: ENTRADAS A CAJA | I60: =E38 -> 0
H62: SALIDAS A CAJA | I62: =K31+K40 -> 0
H64: TOTAL EN CAJA CON APERTURA | I64: =I54+I58+I60-I62 -> 159930
...

Sheet 19-07-2024
A1: Fecha | C1: 45492 | F1: Turno | H1: completo- Augustina Drago
A3: REGISTRO DE VENTAS
A4: CON registro en dodozooft
A5: Folio Voucher | B5: Forma de Pago | F5: Descripción
B6: Efectivo | C6: Debito | D6: Credito | E6: Transf
B7: 2800 | F7: 20933calibra adulto salmon lata// pendiente pago 400 pesos
A8: 80 | D8: 35980 | F8: 6627 vacuna triple felina + vacuna antirrabica
A9: 81 | D9: 25490 | F9: 6628 vacuna triple felina+ desparacitación interna + aplicación pipeta
A10: 83 | D10: 12500 | F10: 20934 revolution puppy
A11: 82 | D11: 7500 | F11: 6629 corte de uñas
A12: 84 | C12: 8000 | F12: 20935 2 struvita calibra+ 400 pesos de diferencia de calibra salmon
A24: Totales | B24: =SUM($B7:$B23) -> 2800 | C24: =SUM($C7:$C23) -> 8000 | D24: =SUM($D7:$D23) -> 81470 | E24: =SUM($E7:$E23) -> 0
J26: TOTAL VENTAS | K26: =$B$24+$C$24+$D$24+$E$24 -> 92270
G28: INGRESOS - EGRESOS
A29: VENTAS - INGRESOS | D29: VENTAS | F29: COMPRAS - EGRESOS | I29: SALIDAS A CAJA
C30: Descripcion | E30: Total | I30: Descripcion | K30: Total
C31: Total Efectivo | E31: =B24 -> 2800 | I31: Efectivo
C32: Total Debito | E32: =C24 -> 8000 | I32: Transferencia
C33: Total Credito | E33: =D24 -> 81470 | I33: Otro
C34: Total Transferencia | E34: =E24 -> 0
C35: TOTAL VENTAS | E35: =SUM(E31:E34) -> 92270
C36: ENTRADAS A CAJA
C37: Descripcion | E37: Total
C38: Efectivo | I38: TOTAL OTROS EGRESOS | K38: =SUM(K31:K37) -> 0
C39: Otro | I39: RETIRO DE EFECTIVO
C40: TOTAL OTROS INGRESOS | E40: =SUM(E38:E39) -> 0 | I40: Cantidad a Retirar
D41: TOTAL INGRESOS | E41: =E35+E40 -> 92270 | J41: TOTAL EGRESOS | K41: =K38+K40 -> 0
G43: ARQUEO DE CAJA
A44: BILLETES | C44: Valor | D44: Cantidad | E44: Total | F44: MONEDAS | I44: Valor | J44: Cantidad | K44: Total
C45: 20000 | E45: =C45*D45 -> 0 | I45: 500 | J45: 3 | K45: =I45*J45 -> 1500
C46: 10000 | D46: 7 | E46: =C46*D46 -> 70000 | I46: 100 | J46: 31 | K46: =I46*J46 -> 3100
C47: 5000 | E47: =C47*D47 -> 0 | I47: 50 | J47: 8 | K47: =I47*J47 -> 400
C48: 2000 | D48: 1 | E48: =C48*D48 -> 2000 | I48: 10 | J48: 13 | K48: =I48*J48 -> 130
C49: 1000 | E49: =C49*D49 -> 0
D50: TOTAL BILLETES | E50: =SUM(E45:E49) -> 72000 | J50: TOTAL MONEDAS | K50: =SUM(K45:K49) -> 5130
H52: RESUMEN ARQUEO DE CAJA
B54: OBSERVACIONES: | H54: APERTURA DE CAJA | I54: 74730
B56: Los 400 pesos de diferencia fueron pagados con debito | H56: TOTAL EFECTIVO FISICO | I56: =E50+K50 -> 77130
H58: TOTAL VENTAS | I58: =K26 -> 92270
H60: ENTRADAS A CAJA | I60: =E38 -> 0
...

Sheet 16-07-2024
A1: Fecha | C1: 45489 | F1: Turno | H1: Completo Augustina Drago
A3: REGISTRO DE VENTAS
A4: con registro en dodozooft
A5: Folio Voucher | B5: Forma de Pago | F5: Descripción
B6: Efectivo | C6: Debito | D6: Credito | E6: Transf
A7: 77 | C7: 25000 | F7: promoción castración 6622
A8: 78 | C8: 32980 | F8: vacuna rabia+ vacuna octuple 6623
B9: 35000 | F9: 6624 esterilización
B10: 24990 | F10: 6625 tto 1
B11: 19690 | F11: doximicin + ketoprofeno + shaky (?)premio 20929
A12: 80 | C12: 17500 | F12: calibra life gato 1,5 kg 2230
A13: 79 | C13: 24990 | F13: tratamiento 1 6626
D14: 31100 | F14: 20931 alimento renal calibra + calibra struvita
B15: 3800 | F15: recovery 20932
A24: Totales | B24: =SUM($B7:$B23) -> 83480 | C24: =SUM($C7:$C23) -> 100470 | D24: =SUM($D7:$D23) -> 31100 | E24: =SUM($E7:$E23) -> 0
J26: TOTAL VENTAS | K26: =$B$24+$C$24+$D$24+$E$24 -> 215050
G28: INGRESOS - EGRESOS
A29: VENTAS - INGRESOS | D29: VENTAS | F29: COMPRAS - EGRESOS | I29: SALIDAS A CAJA
C30: Descripcion | E30: Total | I30: Descripcion | K30: Total
C31: Total Efectivo | E31: =B24 -> 83480 | I31: Efectivo | K31: 45000
C32: Total Debito | E32: =C24 -> 100470 | I32: Transferencia
C33: Total Credito | E33: =D24 -> 31100 | I33: Otro
C34: Total Transferencia | E34: =E24 -> 0
C35: TOTAL VENTAS | E35: =SUM(E31:E34) -> 215050
C36: ENTRADAS A CAJA
C37: Descripcion | E37: Total
C38: Efectivo | I38: TOTAL OTROS EGRESOS | K38: =SUM(K31:K37) -> 45000
C39: Otro | I39: RETIRO DE EFECTIVO
C40: TOTAL OTROS INGRESOS | E40: =SUM(E38:E39) -> 0 | I40: Cantidad a Retirar | K40: 100000
D41: TOTAL INGRESOS | E41: =E35+E40 -> 215050 | J41: TOTAL EGRESOS | K41: =K38+K40 -> 145000
G43: ARQUEO DE CAJA
A44: BILLETES | C44: Valor | D44: Cantidad | E44: Total | F44: MONEDAS | I44: Valor | J44: Cantidad | K44: Total
C45: 20000 | E45: =C45*D45 -> 0 | I45: 500 | J45: 3 | K45: =I45*J45 -> 1500
C46: 10000 | D46: 7 | E46: =C46*D46 -> 70000 | I46: 100 | J46: 27 | K46: =I46*J46 -> 2700
C47: 5000 | E47: =C47*D47 -> 0 | I47: 50 | J47: 8 | K47: =I47*J47 -> 400
C48: 2000 | E48: =C48*D48 -> 0 | I48: 10 | J48: 13 | K48: =I48*J48 -> 130
C49: 1000 | E49: =C49*D49 -> 0
D50: TOTAL BILLETES | E50: =SUM(E45:E49) -> 70000 | J50: TOTAL MONEDAS | K50: =SUM(K45:K49) -> 4730
H52: RESUMEN ARQUEO DE CAJA
B54: OBSERVACIONES: | H54: APERTURA DE CAJA | I54: 136250
...

Sheet 15-07-2024
A1: Fecha | F1: Turno
A3: REGISTRO DE VENTAS
A4: Sin registro en dodozooft
A5: Folio Voucher | B5: Forma de Pago | F5: Descripción
B6: Efectivo | C6: Debito | D6: Credito | E6: Transf
B7: 35000 | F7: castación gato, boleta pendiente al whatsApp
A8: 72 | D8: 28990 | F8: vacuna+frontline+mebermic
A9: 76 | D9: 19400 | F9: 8mebermic + 2 premios
A10: 73 | C10: 59500 | F10: eutanasia
B11: 59500 | F11: examenes de sangre+consulta
A12: 74 | C12: 30990 | F12: TTO 2
A13: 75 | C13: 24990 | F13: TTO 1
A14: 77 | C14: 12600 | F14: doximicin
B15: 10000 | F15: consulta
A16: 76 | C16: 159300 | F16: hospitalización 24hrs+consulta+sonda+latita
A17: 78 | C17: 3800 | F17: recovery
A24: Totales | B24: =SUM($B7:$B23) -> 104500 | C24: =SUM($C7:$C23) -> 291180 | D24: =SUM($D7:$D23) -> 48390 | E24: =SUM($E7:$E23) -> 0
J26: TOTAL VENTAS | K26: =$B$24+$C$24+$D$24+$E$24 -> 444070
G28: INGRESOS - EGRESOS
A29: VENTAS - INGRESOS | D29: VENTAS | F29: COMPRAS - EGRESOS | I29: SALIDAS A CAJA
C30: Descripcion | E30: Total | I30: Descripcion | K30: Total
C31: Total Efectivo | E31: =B24 -> 104500 | I31: Efectivo
C32: Total Debito | E32: =C24 -> 291180 | I32: Transferencia
C33: Total Credito | E33: =D24 -> 48390 | I33: Otro
C34: Total Transferencia | E34: =E24 -> 0
C35: TOTAL VENTAS | E35: =SUM(E31:E34) -> 444070
C36: ENTRADAS A CAJA
C37: Descripcion | E37: Total
C38: Efectivo | I38: TOTAL OTROS EGRESOS | K38: =SUM(K31:K37) -> 0
C39: Otro | I39: RETIRO DE EFECTIVO
C40: TOTAL OTROS INGRESOS | E40: =SUM(E38:E39) -> 0 | I40: Cantidad a Retirar
D41: TOTAL INGRESOS | E41: =E35+E40 -> 444070 | J41: TOTAL EGRESOS | K41: =K38+K40 -> 0
G43: ARQUEO DE CAJA
A44: BILLETES | C44: Valor | D44: Cantidad | E44: Total | F44: MONEDAS | I44: Valor | J44: Cantidad | K44: Total
C45: 20000 | D45: 5 | E45: =C45*D45 -> 100000 | I45: 500 | J45: 3 | K45: =I45*J45 -> 1500
C46: 10000 | D46: 1 | E46: =C46*D46 -> 10000 | I46: 100 | J46: 32 | K46: =I46*J46 -> 3200
C47: 5000 | E47: =C47*D47 -> 0 | I47: 50 | J47: 8 | K47: =I47*J47 -> 400
C48: 2000 | E48: =C48*D48 -> 0 | I48: 10 | J48: 15 | K48: =I48*J48 -> 150
C49: 1000 | D49: 21 | E49: =C49*D49 -> 21000
D50: TOTAL BILLETES | E50: =SUM(E45:E49) -> 131000 | J50: TOTAL MONEDAS | K50: =SUM(K45:K49) -> 5250
...

Sheet 13-07-2024
A1: Fecha | C1: 45486 | F1: Turno | H1: Ronald Diaz
A3: REGISTRO DE VENTAS
A4: Sin registro en dodozooft
A5: Folio Voucher | B5: Forma de Pago | F5: Descripción
B6: Efectivo | C6: Debito | D6: Credito | E6: Transf
A7: 65 | C7: 45000 | F7: Ecografia
A8: 66 | C8: 78900 | F8: Examenes (h+pb+THC)
A9: 67 / 70 | C9: =89500+25000 -> 114500 | F9: Hospital Ambulatorio + Examenes (h+pb+Leucemia/sida)
A10: 68 | C10: 10000 | F10: Consulta
A11: 69 | D11: 174000 | F11: Procedimiento quirugico + hemograma
A12: 71 | C12: 122700 | F12: Hospital Ambulatorio + Examenes (h+pb+)
A13: 74 | C13: 12300 | F13: Rostrum raza grande + Ketoprofeno
A24: Totales | B24: =SUM($B7:$B23) -> 0 | C24: =SUM($C7:$C23) -> 383400 | D24: =SUM($D7:$D23) -> 174000 | E24: =SUM($E7:$E23) -> 0
J26: TOTAL VENTAS | K26: =$B$24+$C$24+$D$24+$E$24 -> 557400
G28: INGRESOS - EGRESOS
A29: VENTAS - INGRESOS | D29: VENTAS | F29: COMPRAS - EGRESOS | I29: SALIDAS A CAJA
C30: Descripcion | E30: Total | I30: Descripcion | K30: Total
C31: Total Efectivo | E31: =B24 -> 0 | I31: Efectivo | K31: =30000+8300+5000+65000 -> 108300
C32: Total Debito | E32: =C24 -> 383400 | I32: Transferencia
C33: Total Credito | E33: =D24 -> 174000 | I33: Otro
C34: Total Transferencia | E34: =E24 -> 0
C35: TOTAL VENTAS | E35: =SUM(E31:E34) -> 557400
C36: ENTRADAS A CAJA
C37: Descripcion | E37: Total
C38: Efectivo | E38: 100000 | I38: TOTAL OTROS EGRESOS | K38: =SUM(K31:K37) -> 108300
C39: Otro | I39: RETIRO DE EFECTIVO
C40: TOTAL OTROS INGRESOS | E40: =SUM(E38:E39) -> 100000 | I40: Cantidad a Retirar
D41: TOTAL INGRESOS | E41: =E35+E40 -> 657400 | J41: TOTAL EGRESOS | K41: =K38+K40 -> 108300
G43: ARQUEO DE CAJA
A44: BILLETES | C44: Valor | D44: Cantidad | E44: Total | F44: MONEDAS | I44: Valor | J44: Cantidad | K44: Total
C45: 20000 | E45: =C45*D45 -> 0 | I45: 500 | J45: 4 | K45: =I45*J45 -> 2000
C46: 10000 | E46: =C46*D46 -> 0 | I46: 100 | J46: 32 | K46: =I46*J46 -> 3200
C47: 5000 | D47: 1 | E47: =C47*D47 -> 5000 | I47: 50 | J47: 8 | K47: =I47*J47 -> 400
C48: 2000 | E48: =C48*D48 -> 0 | I48: 10 | J48: 15 | K48: =I48*J48 -> 150
C49: 1000 | D49: 21 | E49: =C49*D49 -> 21000
D50: TOTAL BILLETES | E50: =SUM(E45:E49) -> 26000 | J50: TOTAL MONEDAS | K50: =SUM(K45:K49) -> 5750
H52: RESUMEN ARQUEO DE CAJA
B54: OBSERVACIONES: | H54: APERTURA DE CAJA | I54: ='12-07-2024'!I68 -> 40050
B56: Ingreso $100.000 Ecografia $30.000 + Almuerzo $8.300 + Agua $5.000 + AnimaLab $65.000 | H56: TOTAL EFECTIVO FISICO | I56: =E50+K50 -> 31750
H58: TOTAL VENTAS | I58: =K26 -> 557400
...

Sheet 12-07-2024
A1: Fecha | C1: 45485 | F1: Turno | H1: Ronald Diaz
A3: REGISTRO DE VENTAS
A4: Sin registro en dodozooft
A5: Folio Voucher | B5: Forma de Pago | F5: Descripción
B6: Efectivo | C6: Debito | D6: Credito | E6: Transf
A7: 63 | C7: 25000 | F7: Castración promocion
A8: 72 | C8: 4100 | F8: Ketoprofeno 10mg
A9: 64 | C9: 47770 | F9: Vacuna antirranica+Vacuna TF+ Advantage hasta 4kg + Desp Interna
B10: 155000 | F10: Procedimiento Quirurgico
A24: Totales | B24: =SUM($B7:$B23) -> 155000 | C24: =SUM($C7:$C23) -> 76870 | D24: =SUM($D7:$D23) -> 0 | E24: =SUM($E7:$E23) -> 0
J26: TOTAL VENTAS | K26: =$B$24+$C$24+$D$24+$E$24 -> 231870
G28: INGRESOS - EGRESOS
A29: VENTAS - INGRESOS | D29: VENTAS | F29: COMPRAS - EGRESOS | I29: SALIDAS A CAJA
C30: Descripcion | E30: Total | I30: Descripcion | K30: Total
C31: Total Efectivo | E31: =B24 -> 155000 | I31: Efectivo | K31: 23000
C32: Total Debito | E32: =C24 -> 76870 | I32: Transferencia
C33: Total Credito | E33: =D24 -> 0 | I33: Otro
C34: Total Transferencia | E34: =E24 -> 0
C35: TOTAL VENTAS | E35: =SUM(E31:E34) -> 231870
C36: ENTRADAS A CAJA
C37: Descripcion | E37: Total
C38: Efectivo | I38: TOTAL OTROS EGRESOS | K38: =SUM(K31:K37) -> 23000
C39: Otro | I39: RETIRO DE EFECTIVO
C40: TOTAL OTROS INGRESOS | E40: =SUM(E38:E39) -> 0 | I40: Cantidad a Retirar | K40: 160000
D41: TOTAL INGRESOS | E41: =E35+E40 -> 231870 | J41: TOTAL EGRESOS | K41: =K38+K40 -> 183000
G43: ARQUEO DE CAJA
A44: BILLETES | C44: Valor | D44: Cantidad | E44: Total | F44: MONEDAS | I44: Valor | J44: Cantidad | K44: Total
C45: 20000 | E45: =C45*D45 -> 0 | I45: 500 | J45: 3 | K45: =I45*J45 -> 1500
C46: 10000 | E46: =C46*D46 -> 0 | I46: 100 | J46: 30 | K46: =I46*J46 -> 3000
C47: 5000 | D47: 3 | E47: =C47*D47 -> 15000 | I47: 50 | J47: 8 | K47: =I47*J47 -> 400
C48: 2000 | E48: =C48*D48 -> 0 | I48: 10 | J48: 15 | K48: =I48*J48 -> 150
C49: 1000 | D49: 20 | E49: =C49*D49 -> 20000
D50: TOTAL BILLETES | E50: =SUM(E45:E49) -> 35000 | J50: TOTAL MONEDAS | K50: =SUM(K45:K49) -> 5050
H52: RESUMEN ARQUEO DE CAJA
B54: OBSERVACIONES: | H54: APERTURA DE CAJA | I54: ='11-07-2024'!I68 -> 68050
B56: AnimaLab $23.000 + Retiro efectivo $160.000 | H56: TOTAL EFECTIVO FISICO | I56: =E50+K50 -> 40050
H58: TOTAL VENTAS | I58: =K26 -> 231870
H60: ENTRADAS A CAJA | I60: =E38 -> 0
H62: SALIDAS A CAJA | I62: =K31+K40 -> 183000
H64: TOTAL EN CAJA CON APERTURA | I64: =I54+I58+I60-I62 -> 116920
...

Sheet 11-07-2024
A1: Fecha | C1: 45484 | F1: Turno | H1: Ronald Diaz
A3: REGISTRO DE VENTAS
A4: Sin registro en dodozooft
A5: Folio Voucher | B5: Forma de Pago | F5: Descripción
B6: Efectivo | C6: Debito | D6: Credito | E6: Transf
A7: 55 | D7: 55000 | F7: H+PB+Coagulación
A8: 56 / 60 | C8: =30000+30000 -> 60000 | F8: Procedimiento quirurgico
A9: 57 | D9: 45000 | F9: Radiografia
A10: 58 | D10: 45000 | F10: Radiografia
A11: 59 / 61 | C11: =77500+87300 -> 164800 | F11: Procedimiento quirurgico + Ketoprofeo 10mg + Rostrum 50mg
A12: 62 | C12: 24500 | F12: Consulta + Sustrato Zupet
A24: Totales | B24: =SUM($B7:$B23) -> 0 | C24: =SUM($C7:$C23) -> 249300 | D24: =SUM($D7:$D23) -> 145000 | E24: =SUM($E7:$E23) -> 0
J26: TOTAL VENTAS | K26: =$B$24+$C$24+$D$24+$E$24 -> 394300
G28: INGRESOS - EGRESOS
A29: VENTAS - INGRESOS | D29: VENTAS | F29: COMPRAS - EGRESOS | I29: SALIDAS A CAJA
C30: Descripcion | E30: Total | I30: Descripcion | K30: Total
C31: Total Efectivo | E31: =B24 -> 0 | I31: Efectivo
C32: Total Debito | E32: =C24 -> 249300 | I32: Transferencia
C33: Total Credito | E33: =D24 -> 145000 | I33: Otro
C34: Total Transferencia | E34: =E24 -> 0
C35: TOTAL VENTAS | E35: =SUM(E31:E34) -> 394300
C36: ENTRADAS A CAJA
C37: Descripcion | E37: Total
C38: Efectivo | I38: TOTAL OTROS EGRESOS | K38: =SUM(K31:K37) -> 0
C39: Otro | I39: RETIRO DE EFECTIVO
C40: TOTAL OTROS INGRESOS | E40: =SUM(E38:E39) -> 0 | I40: Cantidad a Retirar
D41: TOTAL INGRESOS | E41: =E35+E40 -> 394300 | J41: TOTAL EGRESOS | K41: =K38+K40 -> 0
G43: ARQUEO DE CAJA
A44: BILLETES | C44: Valor | D44: Cantidad | E44: Total | F44: MONEDAS | I44: Valor | J44: Cantidad | K44: Total
C45: 20000 | E45: =C45*D45 -> 0 | I45: 500 | J45: 3 | K45: =I45*J45 -> 1500
C46: 10000 | D46: 2 | E46: =C46*D46 -> 20000 | I46: 100 | J46: 30 | K46: =I46*J46 -> 3000
C47: 5000 | D47: 4 | E47: =C47*D47 -> 20000 | I47: 50 | J47: 8 | K47: =I47*J47 -> 400
C48: 2000 | E48: =C48*D48 -> 0 | I48: 10 | J48: 15 | K48: =I48*J48 -> 150
C49: 1000 | D49: 23 | E49: =C49*D49 -> 23000
D50: TOTAL BILLETES | E50: =SUM(E45:E49) -> 63000 | J50: TOTAL MONEDAS | K50: =SUM(K45:K49) -> 5050
H52: RESUMEN ARQUEO DE CAJA
B54: OBSERVACIONES: | H54: APERTURA DE CAJA | I54: ='10-07-2024'!I68 -> 68050
H56: TOTAL EFECTIVO FISICO | I56: =E50+K50 -> 68050
H58: TOTAL VENTAS | I58: =K26 -> 394300
H60: ENTRADAS A CAJA | I60: =E38 -> 0
...

Sheet 10-07-2024
A1: Fecha | C1: 45483 | F1: Turno | H1: Ronald Diaz
A3: REGISTRO DE VENTAS
A4: Sin registro en dodozooft
A5: Folio Voucher | B5: Forma de Pago | F5: Descripción
B6: Efectivo | C6: Debito | D6: Credito | E6: Transf
A7: 52 | C7: 21980 | F7: Vacuna + Snack Pata pollo
A8: 53 | C8: 24990 | F8: Tratamiento 1
A9: 54 | C9: 185000 | F9: Procedimiento quirurgico
A24: Totales | B24: =SUM($B7:$B23) -> 0 | C24: =SUM($C7:$C23) -> 231970 | D24: =SUM($D7:$D23) -> 0 | E24: =SUM($E7:$E23) -> 0
J26: TOTAL VENTAS | K26: =$B$24+$C$24+$D$24+$E$24 -> 231970
G28: INGRESOS - EGRESOS
A29: VENTAS - INGRESOS | D29: VENTAS | F29: COMPRAS - EGRESOS | I29: SALIDAS A CAJA
C30: Descripcion | E30: Total | I30: Descripcion | K30: Total
C31: Total Efectivo | E31: =B24 -> 0 | I31: Efectivo
C32: Total Debito | E32: =C24 -> 231970 | I32: Transferencia
C33: Total Credito | E33: =D24 -> 0 | I33: Otro
C34: Total Transferencia | E34: =E24 -> 0
C35: TOTAL VENTAS | E35: =SUM(E31:E34) -> 231970
C36: ENTRADAS A CAJA
C37: Descripcion | E37: Total
C38: Efectivo | I38: TOTAL OTROS EGRESOS | K38: =SUM(K31:K37) -> 0
C39: Otro | I39: RETIRO DE EFECTIVO
C40: TOTAL OTROS INGRESOS | E40: =SUM(E38:E39) -> 0 | I40: Cantidad a Retirar
D41: TOTAL INGRESOS | E41: =E35+E40 -> 231970 | J41: TOTAL EGRESOS | K41: =K38+K40 -> 0
G43: ARQUEO DE CAJA
A44: BILLETES | C44: Valor | D44: Cantidad | E44: Total | F44: MONEDAS | I44: Valor | J44: Cantidad | K44: Total
C45: 20000 | E45: =C45*D45 -> 0 | I45: 500 | J45: 3 | K45: =I45*J45 -> 1500
C46: 10000 | D46: 2 | E46: =C46*D46 -> 20000 | I46: 100 | J46: 30 | K46: =I46*J46 -> 3000
C47: 5000 | D47: 4 | E47: =C47*D47 -> 20000 | I47: 50 | J47: 8 | K47: =I47*J47 -> 400
C48: 2000 | E48: =C48*D48 -> 0 | I48: 10 | J48: 15 | K48: =I48*J48 -> 150
C49: 1000 | D49: 23 | E49: =C49*D49 -> 23000
D50: TOTAL BILLETES | E50: =SUM(E45:E49) -> 63000 | J50: TOTAL MONEDAS | K50: =SUM(K45:K49) -> 5050
H52: RESUMEN ARQUEO DE CAJA
B54: OBSERVACIONES: | H54: APERTURA DE CAJA | I54: ='09-07-2024'!I68 -> 68050
H56: TOTAL EFECTIVO FISICO | I56: =E50+K50 -> 68050
H58: TOTAL VENTAS | I58: =K26 -> 231970
H60: ENTRADAS A CAJA | I60: =E38 -> 0
H62: SALIDAS A CAJA | I62: =K31+K40 -> 0
H64: TOTAL EN CAJA CON APERTURA | I64: =I54+I58+I60-I62 -> 300020
H66: TOTAL EN CAJA | I66: =I64-I54 -> 231970
...

Sheet 09-07-2024
A1: Fecha | C1: 45482 | F1: Turno | H1: Augustina Drago
A3: REGISTRO DE VENTAS
A4: Sin registro en dodozooft
A5: Folio Voucher | B5: Forma de Pago | F5: Descripción
B6: Efectivo | C6: Debito | D6: Credito | E6: Transf
A7: 68 | C7: 21700 | F7: Doximicin comprimidos+Naxpet jarabe
A8: 46 | C8: 14990 | F8: vacuna antirrabica
A9: 49 | D9: 185000 | F9: urgencia sutura compleja
A10: 50 | C10: 24990 | F10: tto inyectable
A11: 69 | C11: 7800 | F11: (3x2 oferta) sheeke tasty
A12: 51 | C12: 37480 | F12: vacuna antirrabica + vacuna triple felina+ corte de uñas
A13: 70 | D13: 21700 | F13: Arnés gato+ jueguete petplay+ (3x2 oferta) shaky tasty
B14: 12400 | F14: Naxpet raza grande
A24: Totales | B24: =SUM($B7:$B23) -> 12400 | C24: =SUM($C7:$C23) -> 106960 | D24: =SUM($D7:$D23) -> 206700 | E24: =SUM($E7:$E23) -> 0
J26: TOTAL VENTAS | K26: =$B$24+$C$24+$D$24+$E$24 -> 326060
G28: INGRESOS - EGRESOS
A29: VENTAS - INGRESOS | D29: VENTAS | F29: COMPRAS - EGRESOS | I29: SALIDAS A CAJA
C30: Descripcion | E30: Total | I30: Descripcion | K30: Total
C31: Total Efectivo | E31: =B24 -> 12400 | I31: Efectivo
C32: Total Debito | E32: =C24 -> 106960 | I32: Transferencia
C33: Total Credito | E33: =D24 -> 206700 | I33: Otro
C34: Total Transferencia | E34: =E24 -> 0
C35: TOTAL VENTAS | E35: =SUM(E31:E34) -> 326060
C36: ENTRADAS A CAJA
C37: Descripcion | E37: Total
C38: Efectivo | I38: TOTAL OTROS EGRESOS | K38: =SUM(K31:K37) -> 0
C39: Otro | I39: RETIRO DE EFECTIVO
C40: TOTAL OTROS INGRESOS | E40: =SUM(E38:E39) -> 0 | I40: Cantidad a Retirar
D41: TOTAL INGRESOS | E41: =E35+E40 -> 326060 | J41: TOTAL EGRESOS | K41: =K38+K40 -> 0
G43: ARQUEO DE CAJA
A44: BILLETES | C44: Valor | D44: Cantidad | E44: Total | F44: MONEDAS | I44: Valor | J44: Cantidad | K44: Total
C45: 20000 | E45: =C45*D45 -> 0 | I45: 500 | J45: 3 | K45: =I45*J45 -> 1500
C46: 10000 | D46: 2 | E46: =C46*D46 -> 20000 | I46: 100 | J46: 30 | K46: =I46*J46 -> 3000
C47: 5000 | D47: 4 | E47: =C47*D47 -> 20000 | I47: 50 | J47: 8 | K47: =I47*J47 -> 400
C48: 2000 | E48: =C48*D48 -> 0 | I48: 10 | J48: 15 | K48: =I48*J48 -> 150
C49: 1000 | D49: 23 | E49: =C49*D49 -> 23000
D50: TOTAL BILLETES | E50: =SUM(E45:E49) -> 63000 | J50: TOTAL MONEDAS | K50: =SUM(K45:K49) -> 5050
H52: RESUMEN ARQUEO DE CAJA
B54: OBSERVACIONES: | H54: APERTURA DE CAJA | I54: ='08-07-2024'!I68 -> 55650
H56: TOTAL EFECTIVO FISICO | I56: =E50+K50 -> 68050
...

Sheet 08-07-2024
A1: Fecha | C1: 45481 | F1: Turno | H1: Ronald Díaz
A3: REGISTRO DE VENTAS
A4: Sin registro en dodozooft
A5: Folio Voucher | B5: Forma de Pago | F5: Descripción
B6: Efectivo | C6: Debito | D6: Credito | E6: Transf
A7: 44 | C7: 80000 | F7: Esterilizacion+castración gato
A8: 45 | C8: 35000 | F8: Castracion gato
A9: 46 | C9: 17990 | F9: Vacuna octuple
A10: 47 | C10: 35980 | F10: Vacuna Antirrabica + Octuple
B11: 20000 | F11: Ingreso abono de H+PB (programado proximo 08/08/2024)
A24: Totales | B24: =SUM($B7:$B23) -> 20000 | C24: =SUM($C7:$C23) -> 168970 | D24: =SUM($D7:$D23) -> 0 | E24: =SUM($E7:$E23) -> 0
J26: TOTAL VENTAS | K26: =$B$24+$C$24+$D$24+$E$24 -> 188970
G28: INGRESOS - EGRESOS
A29: VENTAS - INGRESOS | D29: VENTAS | F29: COMPRAS - EGRESOS | I29: SALIDAS A CAJA
C30: Descripcion | E30: Total | I30: Descripcion | K30: Total
C31: Total Efectivo | E31: =B24 -> 20000 | I31: Efectivo
C32: Total Debito | E32: =C24 -> 168970 | I32: Transferencia
C33: Total Credito | E33: =D24 -> 0 | I33: Otro
C34: Total Transferencia | E34: =E24 -> 0
C35: TOTAL VENTAS | E35: =SUM(E31:E34) -> 188970
C36: ENTRADAS A CAJA
C37: Descripcion | E37: Total
C38: Efectivo | I38: TOTAL OTROS EGRESOS | K38: =SUM(K31:K37) -> 0
C39: Otro | I39: RETIRO DE EFECTIVO
C40: TOTAL OTROS INGRESOS | E40: =SUM(E38:E39) -> 0 | I40: Cantidad a Retirar | K40: 40000
D41: TOTAL INGRESOS | E41: =E35+E40 -> 188970 | J41: TOTAL EGRESOS | K41: =K38+K40 -> 40000
G43: ARQUEO DE CAJA
A44: BILLETES | C44: Valor | D44: Cantidad | E44: Total | F44: MONEDAS | I44: Valor | J44: Cantidad | K44: Total
C45: 20000 | E45: =C45*D45 -> 0 | I45: 500 | J45: 3 | K45: =I45*J45 -> 1500
C46: 10000 | D46: 1 | E46: =C46*D46 -> 10000 | I46: 100 | J46: 26 | K46: =I46*J46 -> 2600
C47: 5000 | D47: 4 | E47: =C47*D47 -> 20000 | I47: 50 | J47: 8 | K47: =I47*J47 -> 400
C48: 2000 | E48: =C48*D48 -> 0 | I48: 10 | J48: 15 | K48: =I48*J48 -> 150
C49: 1000 | D49: 21 | E49: =C49*D49 -> 21000
D50: TOTAL BILLETES | E50: =SUM(E45:E49) -> 51000 | J50: TOTAL MONEDAS | K50: =SUM(K45:K49) -> 4650
H52: RESUMEN ARQUEO DE CAJA
B54: OBSERVACIONES: | H54: APERTURA DE CAJA | I54: ='06-07-2024'!I68 -> 75650
B56: Ingreso $20.000 (H+PB proximo 08/08/2024) + Retiro efectivo $40.000 | H56: TOTAL EFECTIVO FISICO | I56: =E50+K50 -> 55650
H58: TOTAL VENTAS | I58: =K26 -> 188970
H60: ENTRADAS A CAJA | I60: =E38 -> 0
H62: SALIDAS A CAJA | I62: =K31+K40 -> 40000
...

Sheet 06-07-2024
A1: Fecha | C1: 45479 | F1: Turno | H1: Augustina Drago turno completo
A3: REGISTRO DE VENTAS
A4: Sin registro en dodozooft
A5: Folio Voucher | B5: Forma de Pago | F5: Descripción
B6: Efectivo | C6: Debito | D6: Credito | E6: Transf
A7: 41 | C7: 34500 | F7: consulta+citología
B8: 7500 | F8: corte de uñas
B9: 8000 | F9: consulta descuento adulto mayor
A10: 42 | C10: 24990 | F10: tto+consulta
A11: 43 | C11: 17990 | F11: vacuna
A12: 66 | C12: 5100 | F12: 3 mebermic
A24: Totales | B24: =SUM($B7:$B23) -> 15500 | C24: =SUM($C7:$C23) -> 82580 | D24: =SUM($D7:$D23) -> 0 | E24: =SUM($E7:$E23) -> 0
J26: TOTAL VENTAS | K26: =$B$24+$C$24+$D$24+$E$24 -> 98080
G28: INGRESOS - EGRESOS
A29: VENTAS - INGRESOS | D29: VENTAS | F29: COMPRAS - EGRESOS | I29: SALIDAS A CAJA
C30: Descripcion | E30: Total | I30: Descripcion | K30: Total
C31: Total Efectivo | E31: =B24 -> 15500 | I31: Efectivo | K31: 17000
C32: Total Debito | E32: =C24 -> 82580 | I32: Transferencia
C33: Total Credito | E33: =D24 -> 0 | I33: Otro
C34: Total Transferencia | E34: =E24 -> 0
C35: TOTAL VENTAS | E35: =SUM(E31:E34) -> 98080
C36: ENTRADAS A CAJA
C37: Descripcion | E37: Total
C38: Efectivo | I38: TOTAL OTROS EGRESOS | K38: =SUM(K31:K37) -> 17000
C39: Otro | I39: RETIRO DE EFECTIVO
C40: TOTAL OTROS INGRESOS | E40: =SUM(E38:E39) -> 0 | I40: Cantidad a Retirar
D41: TOTAL INGRESOS | E41: =E35+E40 -> 98080 | J41: TOTAL EGRESOS | K41: =K38+K40 -> 17000
G43: ARQUEO DE CAJA
A44: BILLETES | C44: Valor | D44: Cantidad | E44: Total | F44: MONEDAS | I44: Valor | J44: Cantidad | K44: Total
C45: 20000 | D45: 1 | E45: =C45*D45 -> 20000 | I45: 500 | J45: 3 | K45: =I45*J45 -> 1500
C46: 10000 | D46: 1 | E46: =C46*D46 -> 10000 | I46: 100 | J46: 26 | K46: =I46*J46 -> 2600
C47: 5000 | D47: 4 | E47: =C47*D47 -> 20000 | I47: 50 | J47: 8 | K47: =I47*J47 -> 400
C48: 2000 | E48: =C48*D48 -> 0 | I48: 10 | J48: 15 | K48: =I48*J48 -> 150
C49: 1000 | D49: 21 | E49: =C49*D49 -> 21000
D50: TOTAL BILLETES | E50: =SUM(E45:E49) -> 71000 | J50: TOTAL MONEDAS | K50: =SUM(K45:K49) -> 4650
H52: RESUMEN ARQUEO DE CAJA
B54: OBSERVACIONES: | H54: APERTURA DE CAJA | I54: 77150
B56: vinieron de animal lab a retirar una muestra de citología ($17.000) | H56: TOTAL EFECTIVO FISICO | I56: =E50+K50 -> 75650
H58: TOTAL VENTAS | I58: =K26 -> 98080
H60: ENTRADAS A CAJA | I60: =E38 -> 0
...

Sheet 22-06-2024
A1: Fecha | C1: 45465 | F1: Turno | H1: Paula D.
A3: REGISTRO DE VENTAS
A4: Pendientes en Dodozooft
A5: Folio Voucher | B5: Forma de Pago | F5: Descripción | K5: Veterinario
B6: Efectivo | C6: Debito | D6: Credito | E6: Transferencia
E7: 74500 | F7: Domicilio + H +PB | K7: Paula D.
C8: 20000 | F8: Consulta exotico | K8: Paula D.
B9: 17990 | F9: Triple Felina | K9: Paula D.
C10: 17990 | F10: sextuple | K10: Paula D.
A24: Totales | B24: =SUM($B7:$B23) -> 17990 | C24: =SUM($C7:$C23) -> 37990 | D24: =SUM($D7:$D23) -> 0 | E24: =SUM($E7:$E23) -> 74500
J26: TOTAL VENTAS | K26: =$B$24+$C$24+$D$24+$E$24 -> 130480
G28: INGRESOS - EGRESOS
A29: VENTAS - INGRESOS | D29: VENTAS | F29: COMPRAS - EGRESOS | I29: SALIDAS A CAJA
C30: Descripcion | E30: Total | I30: Descripcion | K30: Total
C31: Total Efectivo | E31: =B24 -> 17990 | I31: Efectivo
C32: Total Debito | E32: =C24 -> 37990 | I32: Transferencia
C33: Total Credito | E33: =D24 -> 0 | I33: Otro
C34: Total Transferencia | E34: =E24 -> 74500
C35: TOTAL VENTAS | E35: =SUM(E31:E34) -> 130480
C36: ENTRADAS A CAJA
C37: Descripcion | E37: Total
C38: Efectivo | I38: TOTAL OTROS EGRESOS | K38: =SUM(K31:K37) -> 0
C39: Otro | I39: RETIRO DE EFECTIVO
C40: TOTAL OTROS INGRESOS | E40: =SUM(E38:E39) -> 0 | I40: Cantidad a Retirar
D41: TOTAL INGRESOS | E41: =E35+E40 -> 130480 | J41: TOTAL EGRESOS | K41: =K38+K40 -> 0
G43: ARQUEO DE CAJA
A44: BILLETES | C44: Valor | D44: Cantidad | E44: Total | F44: MONEDAS | I44: Valor | J44: Cantidad | K44: Total
C45: 20000 | E45: =C45*D45 -> 0 | I45: 500 | K45: =I45*J45 -> 0
C46: 10000 | E46: =C46*D46 -> 0 | I46: 100 | K46: =I46*J46 -> 0
C47: 5000 | E47: =C47*D47 -> 0 | I47: 50 | K47: =I47*J47 -> 0
C48: 2000 | E48: =C48*D48 -> 0 | I48: 10 | K48: =I48*J48 -> 0
C49: 1000 | E49: =C49*D49 -> 0
D50: TOTAL BILLETES | E50: =SUM(E45:E49) -> 0 | J50: TOTAL MONEDAS | K50: =SUM(K45:K49) -> 0
H52: RESUMEN ARQUEO DE CAJA
B54: OBSERVACIONES: | H54: APERTURA DE CAJA | I54: 0
H56: TOTAL EFECTIVO FISICO | I56: =E50+K50 -> 0
H58: TOTAL VENTAS | I58: =K26 -> 130480
H60: ENTRADAS A CAJA | I60: =E38 -> 0
H62: SALIDAS A CAJA | I62: =K31+K40 -> 0
H64: TOTAL EN CAJA CON APERTURA | I64: =I54+I58+I60-I62 -> 130480
...
