Workbook

Sheet MES 23
Q1: LIBRO DE VENTAS | MES 2023
A3: AFECTA | J3: EXENTA | T3: EFECTIVO | V3: TRANSBANK | Z3: TRANSFERENCIA | AB3: CAJA DIARIA | AD3: c/d 10 días
A4: Fecha | B4: Boletas | D4: Efectivo | E4: Transbank | G4: Transf | H4: TOTAL | J4: Fecha | K4: Boletas | M4: Efectivo | N4: Transbank | P4: Transf | Q4: TOTAL | V4: Debito | W4: Credito | X4: Total
B5: Desde | C5: Hasta | E5: Debito | F5: Credito | K5: Desde | L5: Hasta | N5: Debito | O5: Credito
A6: 1 | B6: ='01'!A8 | D6: ='01'!C18 -> 0 | E6: ='01'!D18 -> 0 | F6: ='01'!E18 -> 0 | G6: ='01'!F18 -> 0 | H6: =D6+E6+F6+G6 -> 0 | J6: 1 | K6: ='01'!G8 | M6: ='01'!I18 -> 52500 | N6: ='01'!J18 -> 149980 | O6: ='01'!K18 -> 0 | P6: ='01'!L18 -> 45000 | Q6: =M6+N6+O6+P6 -> 247480 | T6: =D6+M6 -> 52500 | V6: =E6+N6 -> 149980 | W6: =F6+O6 -> 0 | X6: =V6+W6 -> 149980 | Z6: =G6+P6 -> 45000 | AB6: =D6+E6+F6+G6+M6+N6+O6+P6 -> 247480
A7: =1+A6 -> 2 | B7: ='02'!A8 | D7: ='02'!C25 -> 0 | E7: ='02'!D25 -> 0 | F7: ='02'!E25 -> 0 | G7: ='02'!F25 -> 0 | H7: =D7+E7+F7+G7 -> 0 | J7: 2 | K7: ='02'!G8 | M7: ='02'!I25 -> 0 | N7: ='02'!J25 -> 0 | O7: ='02'!K25 -> 0 | P7: ='02'!L25 -> 0 | Q7: =M7+N7+O7+P7 -> 0 | T7: =D7+M7 -> 0 | V7: =E7+N7 -> 0 | W7: =F7+O7 -> 0 | X7: =V7+W7 -> 0 | Z7: =G7+P7 -> 0 | AB7: =D7+E7+F7+G7+M7+N7+O7+P7 -> 0
A8: =1+A7 -> 3 | B8: ='03'!A8 | D8: ='03'!C18 -> 0 | E8: ='03'!D18 -> 0 | F8: ='03'!E18 -> 0 | G8: ='03'!F18 -> 0 | H8: =D8+E8+F8+G8 -> 0 | J8: 3 | K8: ='03'!G8 | M8: ='03'!I18 -> 10000 | N8: ='03'!J18 -> 391490 | O8: ='03'!K18 -> 0 | P8: ='03'!L18 -> 35000 | Q8: =M8+N8+O8+P8 -> 436490 | T8: =D8+M8 -> 10000 | V8: =E8+N8 -> 391490 | W8: =F8+O8 -> 0 | X8: =V8+W8 -> 391490 | Z8: =G8+P8 -> 35000 | AB8: =D8+E8+F8+G8+M8+N8+O8+P8 -> 436490
A9: =1+A8 -> 4 | B9: ='04'!A8 | D9: ='04'!C18 -> 0 | E9: ='04'!D18 -> 0 | F9: ='04'!E18 -> 0 | G9: ='04'!F18 -> 0 | H9: =D9+E9+F9+G9 -> 0 | J9: 4 | K9: ='04'!G8 | M9: ='04'!I18 -> 0 | N9: ='04'!J18 -> 45000 | O9: ='04'!K18 -> 0 | P9: ='04'!L18 -> 10000 | Q9: =M9+N9+O9+P9 -> 55000 | T9: =D9+M9 -> 0 | V9: =E9+N9 -> 45000 | W9: =F9+O9 -> 0 | X9: =V9+W9 -> 45000 | Z9: =G9+P9 -> 10000 | AB9: =D9+E9+F9+G9+M9+N9+O9+P9 -> 55000
A10: =1+A9 -> 5 | B10: ='05'!A8 -> 1789 | D10: ='05'!C19 -> 0 | E10: ='05'!D19 -> 7500 | F10: ='05'!E19 -> 0 | G10: ='05'!F19 -> 0 | H10: =D10+E10+F10+G10 -> 7500 | J10: 5 | K10: ='05'!G8 -> 1785 | M10: ='05'!I19 -> 0 | N10: ='05'!J19 -> 259530 | O10: ='05'!K19 -> 217000 | P10: ='05'!L19 -> 0 | Q10: =M10+N10+O10+P10 -> 476530 | T10: =D10+M10 -> 0 | V10: =E10+N10 -> 267030 | W10: =F10+O10 -> 217000 | X10: =V10+W10 -> 484030 | Z10: =G10+P10 -> 0 | AB10: =D10+E10+F10+G10+M10+N10+O10+P10 -> 484030
A11: 6 | B11: ='06'!A8 -> 668 | D11: ='06'!C16 -> 3200 | E11: ='06'!D16 -> 21400 | F11: ='06'!E16 -> 0 | G11: ='06'!F16 -> 0 | H11: =D11+E11+F11+G11 -> 24600 | J11: 6 | K11: ='06'!G8 | M11: ='06'!I16 -> 0 | N11: ='06'!J16 -> 144490 | O11: ='06'!K16 -> 0 | P11: ='06'!L16 -> 0 | Q11: =M11+N11+O11+P11 -> 144490 | T11: =D11+M11 -> 3200 | V11: =E11+N11 -> 165890 | W11: =F11+O11 -> 0 | X11: =V11+W11 -> 165890 | Z11: =G11+P11 -> 0 | AB11: =D11+E11+F11+G11+M11+N11+O11+P11 -> 169090
A12: 7 | B12: ='07'!A8 -> 1791 | D12: ='07'!C17 -> 0 | E12: ='07'!D17 -> 8600 | F12: ='07'!E17 -> 20000 | G12: ='07'!F17 -> 0 | H12: =D12+E12+F12+G12 -> 28600 | J12: 7 | K12: ='07'!G8 | M12: ='07'!I17 -> 28000 | N12: ='07'!J17 -> 440490 | O12: ='07'!K17 -> 439500 | P12: ='07'!L17 -> 40000 | Q12: =M12+N12+O12+P12 -> 947990 | T12: =D12+M12 -> 28000 | V12: =E12+N12 -> 449090 | W12: =F12+O12 -> 459500 | X12: =V12+W12 -> 908590 | Z12: =G12+P12 -> 40000 | AB12: =D12+E12+F12+G12+M12+N12+O12+P12 -> 976590
A13: 8 | B13: ='08'!A8 -> 672 | D13: ='08'!C25 -> 0 | E13: ='08'!D25 -> 15670 | F13: ='08'!E25 -> 0 | G13: ='08'!F25 -> 0 | H13: =D13+E13+F13+G13 -> 15670 | J13: 8 | K13: ='08'!G8 -> 1795 | M13: ='08'!I25 -> 0 | N13: ='08'!J25 -> 351970 | O13: ='08'!K25 -> 31980 | P13: ='08'!L25 -> 14500 | Q13: =M13+N13+O13+P13 -> 398450 | T13: =D13+M13 -> 0 | V13: =E13+N13 -> 367640 | W13: =F13+O13 -> 31980 | X13: =V13+W13 -> 399620 | Z13: =G13+P13 -> 14500 | AB13: =D13+E13+F13+G13+M13+N13+O13+P13 -> 414120
A14: =1+A13 -> 9 | B14: ='09'!A8 | D14: ='09'!C25 -> 0 | E14: ='09'!D25 -> 0 | F14: ='09'!E25 -> 0 | G14: ='09'!F25 -> 0 | H14: =D14+E14+F14+G14 -> 0 | J14: 9 | K14: ='09'!G8 | M14: ='09'!I25 -> 0 | N14: ='09'!J25 -> 0 | O14: ='09'!K25 -> 0 | P14: ='09'!L25 -> 0 | Q14: =M14+N14+O14+P14 -> 0 | T14: =D14+M14 -> 0 | V14: =E14+N14 -> 0 | W14: =F14+O14 -> 0 | X14: =V14+W14 -> 0 | Z14: =G14+P14 -> 0 | AB14: =D14+E14+F14+G14+M14+N14+O14+P14 -> 0
A15: =1+A14 -> 10 | B15: ='10'!A8 | D15: ='10'!C17 -> 1980 | E15: ='10'!D17 -> 30190 | F15: ='10'!E17 -> 0 | G15: ='10'!F17 -> 0 | H15: =D15+E15+F15+G15 -> 32170 | J15: 10 | K15: ='10'!G8 | M15: ='10'!I17 -> 0 | N15: ='10'!J17 -> 178430 | O15: ='10'!K17 -> 10000 | P15: ='10'!L17 -> 10000 | Q15: =M15+N15+O15+P15 -> 198430 | T15: =D15+M15 -> 1980 | V15: =E15+N15 -> 208620 | W15: =F15+O15 -> 10000 | X15: =V15+W15 -> 218620 | Z15: =G15+P15 -> 10000 | AB15: =D15+E15+F15+G15+M15+N15+O15+P15 -> 230600
A16: =1+A15 -> 11 | B16: ='11'!A8 -> 677 | D16: ='11'!C20 -> 0 | E16: ='11'!D20 -> 18800 | F16: ='11'!E20 -> 0 | G16: ='11'!F20 -> 0 | H16: =D16+E16+F16+G16 -> 18800 | J16: 11 | K16: ='11'!G8 -> 1811 | M16: ='11'!I20 -> 0 | N16: ='11'!J20 -> 378970 | O16: ='11'!K20 -> 181700 | P16: ='11'!L20 -> 10000 | Q16: =M16+N16+O16+P16 -> 570670 | T16: =D16+M16 -> 0 | V16: =E16+N16 -> 397770 | W16: =F16+O16 -> 181700 | X16: =V16+W16 -> 579470 | Z16: =G16+P16 -> 10000 | AB16: =D16+E16+F16+G16+M16+N16+O16+P16 -> 589470 | AD16: =SUM(AB6:AB16) -> 3602870
A17: =1+A16 -> 12 | B17: ='12'!A8 | D17: ='12'!C18 -> 4890 | E17: ='12'!D18 -> 0 | F17: ='12'!E18 -> 0 | G17: ='12'!F18 -> 0 | H17: =D17+E17+F17+G17 -> 4890 | J17: 12 | K17: ='12'!G8 -> 1815 | M17: ='12'!I18 -> 59500 | N17: ='12'!J18 -> 334480 | O17: ='12'!K18 -> 0 | P17: ='12'!L18 -> 0 | Q17: =M17+N17+O17+P17 -> 393980 | T17: =D17+M17 -> 64390 | V17: =E17+N17 -> 334480 | W17: =F17+O17 -> 0 | X17: =V17+W17 -> 334480 | Z17: =G17+P17 -> 0 | AB17: =D17+E17+F17+G17+M17+N17+O17+P17 -> 398870
A18: =1+A17 -> 13 | B18: ='13'!A8 -> 679 | D18: ='13'!C17 -> 0 | E18: ='13'!D17 -> 31350 | F18: ='13'!E17 -> 0 | G18: ='13'!F17 -> 0 | H18: =D18+E18+F18+G18 -> 31350 | J18: 13 | K18: ='13'!G8 | M18: ='13'!I17 -> 0 | N18: ='13'!J17 -> 0 | O18: ='13'!K17 -> 0 | P18: ='13'!L17 -> 111500 | Q18: =M18+N18+O18+P18 -> 111500 | T18: =D18+M18 -> 0 | V18: =E18+N18 -> 31350 | W18: =F18+O18 -> 0 | X18: =V18+W18 -> 31350 | Z18: =G18+P18 -> 111500 | AB18: =D18+E18+F18+G18+M18+N18+O18+P18 -> 142850
A19: =1+A18 -> 14 | B19: ='14'!A8 -> 681 | D19: ='14'!C19 -> 3200 | E19: ='14'!D19 -> 19700 | F19: ='14'!E19 -> 0 | G19: ='14'!F19 -> 0 | H19: =D19+E19+F19+G19 -> 22900 | J19: 14 | K19: ='14'!G8 -> 1816 | M19: ='14'!I19 -> 8100 | N19: ='14'!J19 -> 59990 | O19: ='14'!K19 -> 74490 | P19: ='14'!L19 -> 0 | Q19: =M19+N19+O19+P19 -> 142580 | T19: =D19+M19 -> 11300 | V19: =E19+N19 -> 79690 | W19: =F19+O19 -> 74490 | X19: =V19+W19 -> 154180 | Z19: =G19+P19 -> 0 | AB19: =D19+E19+F19+G19+M19+N19+O19+P19 -> 165480
A20: =1+A19 -> 15 | B20: ='15'!A8 | D20: ='15'!C17 -> 0 | E20: ='15'!D17 -> 0 | F20: ='15'!E17 -> 0 | G20: ='15'!F17 -> 0 | H20: =D20+E20+F20+G20 -> 0 | J20: 15 | K20: ='15'!G8 -> 1820 | M20: ='15'!I17 -> 0 | N20: ='15'!J17 -> 155980 | O20: ='15'!K17 -> 0 | P20: ='15'!L17 -> 425000 | Q20: =M20+N20+O20+P20 -> 580980 | T20: =D20+M20 -> 0 | V20: =E20+N20 -> 155980 | W20: =F20+O20 -> 0 | X20: =V20+W20 -> 155980 | Z20: =G20+P20 -> 425000 | AB20: =D20+E20+F20+G20+M20+N20+O20+P20 -> 580980
A21: =1+A20 -> 16 | B21: ='16'!A8 | D21: ='16'!C25 -> 0 | E21: ='16'!D25 -> 0 | F21: ='16'!E25 -> 0 | G21: ='16'!F25 -> 0 | H21: =D21+E21+F21+G21 -> 0 | J21: 16 | K21: ='16'!G8 | M21: ='16'!I25 -> 0 | N21: ='16'!J25 -> 0 | O21: ='16'!K25 -> 0 | P21: ='16'!L25 -> 0 | Q21: =M21+N21+O21+P21 -> 0 | T21: =D21+M21 -> 0 | V21: =E21+N21 -> 0 | W21: =F21+O21 -> 0 | X21: =V21+W21 -> 0 | Z21: =G21+P21 -> 0 | AB21: =D21+E21+F21+G21+M21+N21+O21+P21 -> 0
A22: =1+A21 -> 17 | B22: ='17'!A8 -> 684 | D22: ='17'!C19 -> 0 | E22: ='17'!D19 -> 29690 | F22: ='17'!E19 -> 0 | G22: ='17'!F19 -> 0 | H22: =D22+E22+F22+G22 -> 29690 | J22: 17 | K22: ='17'!G8 -> 1827 | M22: ='17'!I19 -> 0 | N22: ='17'!J19 -> 438470 | O22: ='17'!K19 -> 20980 | P22: ='17'!L19 -> 105000 | Q22: =M22+N22+O22+P22 -> 564450 | T22: =D22+M22 -> 0 | V22: =E22+N22 -> 468160 | W22: =F22+O22 -> 20980 | X22: =V22+W22 -> 489140 | Z22: =G22+P22 -> 105000 | AB22: =D22+E22+F22+G22+M22+N22+O22+P22 -> 594140
A23: =1+A22 -> 18 | B23: ='18'!A8 -> 688 | D23: ='18'!C19 -> 0 | E23: ='18'!D19 -> 13550 | F23: ='18'!E19 -> 0 | G23: ='18'!F19 -> 0 | H23: =D23+E23+F23+G23 -> 13550 | J23: 18 | K23: ='18'!G8 | M23: ='18'!I19 -> 35000 | N23: ='18'!J19 -> 0 | O23: ='18'!K19 -> 0 | P23: ='18'!L19 -> 0 | Q23: =M23+N23+O23+P23 -> 35000 | T23: =D23+M23 -> 35000 | V23: =E23+N23 -> 13550 | W23: =F23+O23 -> 0 | X23: =V23+W23 -> 13550 | Z23: =G23+P23 -> 0 | AB23: =D23+E23+F23+G23+M23+N23+O23+P23 -> 48550
A24: =1+A23 -> 19 | B24: ='19'!A8 | D24: ='19'!C14 -> 0 | E24: ='19'!D14 -> 0 | F24: ='19'!E14 -> 0 | G24: ='19'!F14 -> 0 | H24: =D24+E24+F24+G24 -> 0 | J24: 19 | K24: ='19'!G8 | M24: ='19'!I14 -> 105000 | N24: ='19'!J14 -> 0 | O24: ='19'!K14 -> 0 | P24: ='19'!L14 -> 0 | Q24: =M24+N24+O24+P24 -> 105000 | T24: =D24+M24 -> 105000 | V24: =E24+N24 -> 0 | W24: =F24+O24 -> 0 | X24: =V24+W24 -> 0 | Z24: =G24+P24 -> 0 | AB24: =D24+E24+F24+G24+M24+N24+O24+P24 -> 105000
A25: =1+A24 -> 20 | B25: ='20'!A8 | D25: ='20'!C17 -> 0 | E25: ='20'!D17 -> 0 | F25: ='20'!E17 -> 0 | G25: ='20'!F17 -> 0 | H25: =D25+E25+F25+G25 -> 0 | J25: 20 | K25: ='20'!G8 -> 1833 | M25: ='20'!I17 -> 0 | N25: ='20'!J17 -> 0 | O25: ='20'!K17 -> 205500 | P25: ='20'!L17 -> 0 | Q25: =M25+N25+O25+P25 -> 205500 | T25: =D25+M25 -> 0 | V25: =E25+N25 -> 0 | W25: =F25+O25 -> 205500 | X25: =V25+W25 -> 205500 | Z25: =G25+P25 -> 0 | AB25: =D25+E25+F25+G25+M25+N25+O25+P25 -> 205500
A26: =1+A25 -> 21 | B26: ='21'!A8 | D26: ='21'!C17 -> 0 | E26: ='21'!D17 -> 0 | F26: ='21'!E17 -> 0 | G26: ='21'!F17 -> 0 | H26: =D26+E26+F26+G26 -> 0 | J26: 21 | K26: ='21'!G8 | M26: ='21'!I17 -> 30490 | N26: ='21'!J17 -> 155480 | O26: ='21'!K17 -> 0 | P26: ='21'!L17 -> 0 | Q26: =M26+N26+O26+P26 -> 185970 | T26: =D26+M26 -> 30490 | V26: =E26+N26 -> 155480 | W26: =F26+O26 -> 0 | X26: =V26+W26 -> 155480 | Z26: =G26+P26 -> 0 | AB26: =D26+E26+F26+G26+M26+N26+O26+P26 -> 185970 | AD26: =SUM(AB17:AB26) -> 2427340
A27: =1+A26 -> 22 | B27: ='22'!A8 -> 31010 | D27: ='22'!C18 -> 0 | E27: ='22'!D18 -> 11990 | F27: ='22'!E18 -> 10500 | G27: ='22'!F18 -> 0 | H27: =D27+E27+F27+G27 -> 22490 | J27: 22 | K27: ='22'!G8 -> 1838 | M27: ='22'!I18 -> 40000 | N27: ='22'!J18 -> 88480 | O27: ='22'!K18 -> 255000 | P27: ='22'!L18 -> 0 | Q27: =M27+N27+O27+P27 -> 383480 | T27: =D27+M27 -> 40000 | V27: =E27+N27 -> 100470 | W27: =F27+O27 -> 265500 | X27: =V27+W27 -> 365970 | Z27: =G27+P27 -> 0 | AB27: =D27+E27+F27+G27+M27+N27+O27+P27 -> 405970
A28: =1+A27 -> 23 | B28: ='23'!A8 | D28: ='23'!C25 -> 0 | E28: ='23'!D25 -> 0 | F28: ='23'!E25 -> 0 | G28: ='23'!F25 -> 0 | H28: =D28+E28+F28+G28 -> 0 | J28: 23 | K28: ='23'!G8 | M28: ='23'!I25 -> 0 | N28: ='23'!J25 -> 0 | O28: ='23'!K25 -> 0 | P28: ='23'!L25 -> 0 | Q28: =M28+N28+O28+P28 -> 0 | T28: =D28+M28 -> 0 | V28: =E28+N28 -> 0 | W28: =F28+O28 -> 0 | X28: =V28+W28 -> 0 | Z28: =G28+P28 -> 0 | AB28: =D28+E28+F28+G28+M28+N28+O28+P28 -> 0
A29: =1+A28 -> 24 | B29: ='24'!A8 | D29: ='24'!C16 -> 3800 | E29: ='24'!D16 -> 0 | F29: ='24'!E16 -> 0 | G29: ='24'!F16 -> 0 | H29: =D29+E29+F29+G29 -> 3800 | J29: 24 | K29: ='24'!G8 | M29: ='24'!I16 -> 0 | N29: ='24'!J16 -> 15990 | O29: ='24'!K16 -> 421000 | P29: ='24'!L16 -> 10000 | Q29: =M29+N29+O29+P29 -> 446990 | T29: =D29+M29 -> 3800 | V29: =E29+N29 -> 15990 | W29: =F29+O29 -> 421000 | X29: =V29+W29 -> 436990 | Z29: =G29+P29 -> 10000 | AB29: =D29+E29+F29+G29+M29+N29+O29+P29 -> 450790
A30: =1+A29 -> 25 | B30: ='25'!A8 | D30: ='25'!C19 -> 0 | E30: ='25'!D19 -> 0 | F30: ='25'!E19 -> 0 | G30: ='25'!F19 -> 0 | H30: =D30+E30+F30+G30 -> 0 | J30: 25 | K30: ='25'!G8 | M30: ='25'!I19 -> 0 | N30: ='25'!J19 -> 15990 | O30: ='25'!K19 -> 0 | P30: ='25'!L19 -> 0 | Q30: =M30+N30+O30+P30 -> 15990 | T30: =D30+M30 -> 0 | V30: =E30+N30 -> 15990 | W30: =F30+O30 -> 0 | X30: =V30+W30 -> 15990 | Z30: =G30+P30 -> 0 | AB30: =D30+E30+F30+G30+M30+N30+O30+P30 -> 15990
A31: =1+A30 -> 26 | B31: ='26'!A8 -> 695 | D31: ='26'!C17 -> 0 | E31: ='26'!D17 -> 22900 | F31: ='26'!E17 -> 0 | G31: ='26'!F17 -> 0 | H31: =D31+E31+F31+G31 -> 22900 | J31: 26 | K31: ='26'!G8 | M31: ='26'!I17 -> 0 | N31: ='26'!J17 -> 321990 | O31: ='26'!K17 -> 10000 | P31: ='26'!L17 -> 0 | Q31: =M31+N31+O31+P31 -> 331990 | T31: =D31+M31 -> 0 | V31: =E31+N31 -> 344890 | W31: =F31+O31 -> 10000 | X31: =V31+W31 -> 354890 | Z31: =G31+P31 -> 0 | AB31: =D31+E31+F31+G31+M31+N31+O31+P31 -> 354890
A32: =1+A31 -> 27 | B32: ='27'!A8 | D32: ='27'!C21 -> 7400 | E32: ='27'!D21 -> 12500 | F32: ='27'!E21 -> 0 | G32: ='27'!F21 -> 0 | H32: =D32+E32+F32+G32 -> 19900 | J32: 27 | K32: ='27'!G8 | M32: ='27'!I21 -> 59500 | N32: ='27'!J21 -> 648470 | O32: ='27'!K21 -> 324500 | P32: ='27'!L21 -> 40000 | Q32: =M32+N32+O32+P32 -> 1072470 | T32: =D32+M32 -> 66900 | V32: =E32+N32 -> 660970 | W32: =F32+O32 -> 324500 | X32: =V32+W32 -> 985470 | Z32: =G32+P32 -> 40000 | AB32: =D32+E32+F32+G32+M32+N32+O32+P32 -> 1092370
A33: 28 | B33: ='28'!A8 | D33: ='28'!C18 -> 0 | E33: ='28'!D18 -> 18290 | F33: ='28'!E18 -> 0 | G33: ='28'!F18 -> 0 | H33: =D33+E33+F33+G33 -> 18290 | J33: 28 | K33: ='28'!G8 | M33: ='28'!I18 -> 0 | N33: ='28'!J18 -> 269980 | O33: ='28'!K18 -> 0 | P33: ='28'!L18 -> 0 | Q33: =M33+N33+O33+P33 -> 269980 | T33: =D33+M33 -> 0 | V33: =E33+N33 -> 288270 | W33: =F33+O33 -> 0 | X33: =V33+W33 -> 288270 | Z33: =G33+P33 -> 0 | AB33: =D33+E33+F33+G33+M33+N33+O33+P33 -> 288270
A34: 29 | B34: ='29'!A8 -> 699 | D34: ='29'!C19 -> 0 | E34: ='29'!D19 -> 18460 | F34: ='29'!E19 -> 21990 | G34: ='29'!F19 -> 0 | H34: =D34+E34+F34+G34 -> 40450 | J34: 29 | K34: ='29'!G8 -> 1856 | M34: ='29'!I19 -> 22990 | N34: ='29'!J19 -> 217980 | O34: ='29'!K19 -> 31980 | P34: ='29'!L19 -> 0 | Q34: =M34+N34+O34+P34 -> 272950 | T34: =D34+M34 -> 22990 | V34: =E34+N34 -> 236440 | W34: =F34+O34 -> 53970 | X34: =V34+W34 -> 290410 | Z34: =G34+P34 -> 0 | AB34: =D34+E34+F34+G34+M34+N34+O34+P34 -> 313400
A35: 30 | B35: ='30'!A8 | D35: ='30'!C25 -> 0 | E35: ='30'!D25 -> 0 | F35: ='30'!E25 -> 0 | G35: ='30'!F25 -> 0 | H35: =D35+E35+F35+G35 -> 0 | J35: 30 | K35: ='30'!G8 | M35: ='30'!I25 -> 0 | N35: ='30'!J25 -> 0 | O35: ='30'!K25 -> 0 | P35: ='30'!L25 -> 0 | Q35: =M35+N35+O35+P35 -> 0 | T35: =D35+M35 -> 0 | V35: =E35+N35 -> 0 | W35: =F35+O35 -> 0 | X35: =V35+W35 -> 0 | Z35: =G35+P35 -> 0 | AB35: =D35+E35+F35+G35+M35+N35+O35+P35 -> 0
A36: 31 | B36: ='31'!A8 | D36: ='31'!C25 -> 0 | E36: ='31'!D25 -> 0 | F36: ='31'!E25 -> 0 | G36: ='31'!F25 -> 0 | H36: =D36+E36+F36+G36 -> 0 | J36: 31 | K36: ='31'!G8 | M36: ='31'!I25 -> 0 | Q36: =M36+N36+O36+P36 -> 0 | T36: =D36+M36 -> 0 | V36: =E36+N36 -> 0 | W36: =F36+O36 -> 0 | X36: =V36+W36 -> 0 | Z36: =G36+P36 -> 0 | AB36: =D36+E36+F36+G36+M36+N36+O36+P36 -> 0 | AD36: =SUM(AB27:AB36) -> 2921680
B37: TOTALES | D37: =SUM(D6:D36) -> 24470 | E37: =SUM(E6:E36) -> 280590 | F37: =SUM(F6:F36) -> 52490 | G37: =SUM(G6:G36) -> 0 | H37: =SUM(H6:H36) -> 357550 | K37: TOTALES | M37: =SUM(M6:M36) -> 451080 | N37: =SUM(N6:N36) -> 5063630 | O37: =SUM(O6:O36) -> 2223630 | P37: =SUM(P6:P36) -> 856000 | Q37: =SUM(Q6:Q36) -> 8594340 | R37: Total | T37: =SUM(T6:T36) -> 475550 | V37: =SUM(V6:V36) -> 5344220 | W37: =SUM(W6:W36) -> 2276120 | X37: =SUM(X6:X36) -> 7620340 | Z37: =SUM(Z6:Z36) -> 856000 | AB37: =SUM(AB6:AB36) -> 8951890
Q38: =Q37/1.19 -> 7222134.5 | R38: Neto | V38: =V37*1.49% -> 79628.878 | W38: =W37*2.95% -> 67145.54 | X38: =V38+W38 -> 146774.42
B39: Total Ventas Mes | D39: =H37+Q37 -> 8951890 | F39: T.Transbank | G39: T. Efectivo | H39: T. Transf | Q39: =Q38*0.19 -> 1372205.5 | R39: IVA | V39: =V38*19% -> 15129.487 | W39: =W38*19% -> 12757.653 | X39: =V39+W39 -> 27887.139
F40: =E37+F37+N37+O37 -> 7620340 | G40: =D37+M37 -> 475550 | H40: =G37+P37 -> 856000 | V40: =V37-V38-V39 -> 5249461.6 | W40: =W37-W38-W39 -> 2196216.8 | X40: =X37-X38-X39 -> 7445678.4 | AB40: =AB37/27 -> 331551.48 | AC40: Promedio Diario
B41: Declaracion de IVA a pagar | V41: Neto -1,49% | W41: Neto -2,95%
...

Sheet 31
A1: Fecha | F1: Vendedor
A2: Mes | F2: Turno | I2: Completo
F4: REGISTRO DE VENTAS
A5: BOLETAS AFECTA | G5: BOLETAS EXENTA
A6: Folio Voucher | B6: Folio Boleta | C6: Forma de Pago | G6: Folio Voucher | H6: Folio Boleta | I6: Forma de Pago
C7: Efectivo | D7: Debito | E7: Credito | F7: Transf | I7: Efectivo | J7: Debito | K7: Credito | L7: Transf
B25: Totales | C25: =SUM($C8:$C24) -> 0 | D25: =SUM($D8:$D24) -> 0 | E25: =SUM($E8:$E24) -> 0 | F25: =SUM($F8:$F24) -> 0 | H25: Totales | I25: =SUM($I8:$I24) -> 0 | J25: =SUM($J8:$J24) -> 0 | K25: =SUM($K8:$K24) -> 0 | L25: =SUM($L8:$L24) -> 0
K27: TOTAL VENTAS | L27: =$C$25+$D$25+$E$25+$F$25+$I$25+$J$25+$K$25+$L$25 -> 0
G29: INGRESOS - EGRESOS
A30: VENTAS - INGRESOS | E30: VENTAS | G30: COMPRAS - EGRESOS | J30: SALIDAS A CAJA
D31: Descripcion | F31: Total | J31: Descripcion | L31: Total
D32: Total Efectivo | F32: =C25+I25 -> 0 | J32: Efectivo
D33: Total Debito | F33: =D25+J25 -> 0 | J33: Transferencia
D34: Total Credito | F34: =E25+K25 -> 0 | J34: Otro
D35: Total Transferencia | F35: =F25+L25 -> 0
D36: TOTAL VENTAS | F36: =SUM(F32:F35) -> 0
D37: ENTRADAS A CAJA
D38: Descripcion | F38: Total
D39: Efectivo | F39: 0 | J39: TOTAL OTROS EGRESOS | L39: =SUM(L32:L38) -> 0
D40: Otro | J40: RETIRO DE EFECTIVO
D41: TOTAL OTROS INGRESOS | F41: =SUM(F39:F40) -> 0 | J41: Cantidad a Retirar
E42: TOTAL INGRESOS | F42: =F36+F41 -> 0 | K42: TOTAL EGRESOS | L42: =L39+L41 -> 0
G44: ARQUEO DE CAJA
A45: BILLETES | D45: Valor | E45: Cantidad | F45: Total | G45: MONEDAS | J45: Valor | K45: Cantidad | L45: Total
D46: 20000 | F46: =D46*E46 -> 0 | J46: 500 | L46: =J46*K46 -> 0
D47: 10000 | F47: =D47*E47 -> 0 | J47: 100 | L47: =J47*K47 -> 0
D48: 5000 | F48: =D48*E48 -> 0 | J48: 50 | L48: =J48*K48 -> 0
D49: 2000 | F49: =D49*E49 -> 0 | J49: 10 | L49: =J49*K49 -> 0
D50: 1000 | F50: =D50*E50 -> 0
E51: TOTAL BILLETES | F51: =SUM(F46:F50) -> 0 | K51: TOTAL MONEDAS | L51: =SUM(L46:L50) -> 0
I53: RESUMEN ARQUEO DE CAJA
B55: OBSERVACIONES: | I55: APERTURA DE CAJA | J55: ='30'!J69 -> 36460
I57: TOTAL EFECTIVO FISICO | J57: =F51+L51 -> 0
I59: TOTAL VENTAS | J59: =L27 -> 0
I61: ENTRADAS A CAJA | J61: =F39 -> 0
I63: SALIDAS A CAJA | J63: =L32+L41 -> 0
I65: TOTAL EN CAJA CON APERTURA | J65: =J55+J59+J61-J63 -> 36460
I67: TOTAL EN CAJA | J67: =J65-J55 -> 0
I69: CAJA FINAL EFECTIVO | J69: =J55+F32+(F39-(L32+L41)) -> 36460
I71: DIFERENCIA | J71: =J57-J69 -> -36460

Sheet 30
A1: Fecha | F1: Vendedor
A2: Mes | F2: Turno | I2: Completo
F4: REGISTRO DE VENTAS
A5: BOLETAS AFECTA | G5: BOLETAS EXENTA
A6: Folio Voucher | B6: Folio Boleta | C6: Forma de Pago | G6: Folio Voucher | H6: Folio Boleta | I6: Forma de Pago
C7: Efectivo | D7: Debito | E7: Credito | F7: Transf | I7: Efectivo | J7: Debito | K7: Credito | L7: Transf
B25: Totales | C25: =SUM($C8:$C24) -> 0 | D25: =SUM($D8:$D24) -> 0 | E25: =SUM($E8:$E24) -> 0 | F25: =SUM($F8:$F24) -> 0 | H25: Totales | I25: =SUM($I8:$I24) -> 0 | J25: =SUM($J8:$J24) -> 0 | K25: =SUM($K8:$K24) -> 0 | L25: =SUM($L8:$L24) -> 0
K27: TOTAL VENTAS | L27: =$C$25+$D$25+$E$25+$F$25+$I$25+$J$25+$K$25+$L$25 -> 0
G29: INGRESOS - EGRESOS
A30: VENTAS - INGRESOS | E30: VENTAS | G30: COMPRAS - EGRESOS | J30: SALIDAS A CAJA
D31: Descripcion | F31: Total | J31: Descripcion | L31: Total
D32: Total Efectivo | F32: =C25+I25 -> 0 | J32: Efectivo
D33: Total Debito | F33: =D25+J25 -> 0 | J33: Transferencia
D34: Total Credito | F34: =E25+K25 -> 0 | J34: Otro
D35: Total Transferencia | F35: =F25+L25 -> 0
D36: TOTAL VENTAS | F36: =SUM(F32:F35) -> 0
D37: ENTRADAS A CAJA
D38: Descripcion | F38: Total
D39: Efectivo | F39: 0 | J39: TOTAL OTROS EGRESOS | L39: =SUM(L32:L38) -> 0
D40: Otro | J40: RETIRO DE EFECTIVO
D41: TOTAL OTROS INGRESOS | F41: =SUM(F39:F40) -> 0 | J41: Cantidad a Retirar
E42: TOTAL INGRESOS | F42: =F36+F41 -> 0 | K42: TOTAL EGRESOS | L42: =L39+L41 -> 0
G44: ARQUEO DE CAJA
A45: BILLETES | D45: Valor | E45: Cantidad | F45: Total | G45: MONEDAS | J45: Valor | K45: Cantidad | L45: Total
D46: 20000 | F46: =D46*E46 -> 0 | J46: 500 | L46: =J46*K46 -> 0
D47: 10000 | F47: =D47*E47 -> 0 | J47: 100 | L47: =J47*K47 -> 0
D48: 5000 | F48: =D48*E48 -> 0 | J48: 50 | L48: =J48*K48 -> 0
D49: 2000 | F49: =D49*E49 -> 0 | J49: 10 | L49: =J49*K49 -> 0
D50: 1000 | F50: =D50*E50 -> 0
E51: TOTAL BILLETES | F51: =SUM(F46:F50) -> 0 | K51: TOTAL MONEDAS | L51: =SUM(L46:L50) -> 0
I53: RESUMEN ARQUEO DE CAJA
B55: OBSERVACIONES: | I55: APERTURA DE CAJA | J55: ='29'!J63 -> 36460
I57: TOTAL EFECTIVO FISICO | J57: =F51+L51 -> 0
I59: TOTAL VENTAS | J59: =L27 -> 0
I61: ENTRADAS A CAJA | J61: =F39 -> 0
I63: SALIDAS A CAJA | J63: =L32+L41 -> 0
I65: TOTAL EN CAJA CON APERTURA | J65: =J55+J59+J61-J63 -> 36460
I67: TOTAL EN CAJA | J67: =J65-J55 -> 0
I69: CAJA FINAL EFECTIVO | J69: =J55+F32+(F39-(L32+L41)) -> 36460
I71: DIFERENCIA | J71: =J57-J69 -> -36460

Sheet 29
A1: Fecha | C1: 45990 | F1: Vendedor | I1: Katherine Martinez
A2: Mes | C2: Noviembre | F2: Turno | I2: Completo
F4: REGISTRO DE VENTAS
A5: BOLETAS AFECTA | G5: BOLETAS EXENTA
A6: Folio Voucher | B6: Folio Boleta | C6: Forma de Pago | G6: Folio Voucher | H6: Folio Boleta | I6: Forma de Pago
C7: Efectivo | D7: Debito | E7: Credito | F7: Transf | I7: Efectivo | J7: Debito | K7: Credito | L7: Transf
A8: 699 | B8: 21507 | D8: 3960 | G8: 1856 | H8: 9049 | J8: 85000
A9: 700 | B9: 21508 | E9: 990 | G9: 1857 | H9: 9050 | J9: 40000
A10: 701 | B10: 21509 | D10: 14500 | G10: 1858 | H10: 9051 | J10: 49500
A11: 703 | B11: 21510 | E11: 21000 | H11: 9052 | I11: 12990
G12: 1859 | H12: 9053 | J12: 14500
H13: 9054 | I13: 10000
G14: 1860 | H14: 9055 | K14: 31980
G15: 1861 | H15: 9056 | J15: 28980
B19: Totales | C19: =SUM($C8:$C18) -> 0 | D19: =SUM($D8:$D18) -> 18460 | E19: =SUM($E8:$E18) -> 21990 | F19: =SUM($F8:$F18) -> 0 | H19: Totales | I19: =SUM($I8:$I18) -> 22990 | J19: =SUM($J8:$J18) -> 217980 | K19: =SUM($K8:$K18) -> 31980 | L19: =SUM($L8:$L18) -> 0
K21: TOTAL VENTAS | L21: =$C$19+$D$19+$E$19+$F$19+$I$19+$J$19+$K$19+$L$19 -> 313400
G23: INGRESOS - EGRESOS
A24: VENTAS - INGRESOS | E24: VENTAS | G24: COMPRAS - EGRESOS | J24: SALIDAS A CAJA
D25: Descripcion | F25: Total | J25: Descripcion | L25: Total
D26: Total Efectivo | F26: =C19+I19 -> 22990 | J26: Efectivo
D27: Total Debito | F27: =D19+J19 -> 236440 | J27: Transferencia
D28: Total Credito | F28: =E19+K19 -> 53970 | J28: Otro
D29: Total Transferencia | F29: =F19+L19 -> 0
D30: TOTAL VENTAS | F30: =SUM(F26:F29) -> 313400
D31: ENTRADAS A CAJA
D32: Descripcion | F32: Total
D33: Efectivo | F33: 0 | J33: TOTAL OTROS EGRESOS | L33: =SUM(L26:L32) -> 0
D34: Otro | J34: RETIRO DE EFECTIVO
D35: TOTAL OTROS INGRESOS | F35: =SUM(F33:F34) -> 0 | J35: Cantidad a Retirar
E36: TOTAL INGRESOS | F36: =F30+F35 -> 313400 | K36: TOTAL EGRESOS | L36: =L33+L35 -> 0
G38: ARQUEO DE CAJA
A39: BILLETES | D39: Valor | E39: Cantidad | F39: Total | G39: MONEDAS | J39: Valor | K39: Cantidad | L39: Total
D40: 20000 | F40: =D40*E40 -> 0 | J40: 500 | K40: 1 | L40: =J40*K40 -> 500
D41: 10000 | E41: 3 | F41: =D41*E41 -> 30000 | J41: 100 | K41: 11 | L41: =J41*K41 -> 1100
D42: 5000 | F42: =D42*E42 -> 0 | J42: 50 | K42: 10 | L42: =J42*K42 -> 500
D43: 2000 | F43: =D43*E43 -> 0 | J43: 10 | K43: 36 | L43: =J43*K43 -> 360
D44: 1000 | E44: 4 | F44: =D44*E44 -> 4000
E45: TOTAL BILLETES | F45: =SUM(F40:F44) -> 34000 | K45: TOTAL MONEDAS | L45: =SUM(L40:L44) -> 2460
I47: RESUMEN ARQUEO DE CAJA
B49: OBSERVACIONES: | I49: APERTURA DE CAJA | J49: ='28'!J62 -> 13470
...

Sheet 28
A1: Fecha | C1: 45989 | F1: Vendedor | I1: Sasha Alcala
A2: Mes | C2: NOVIEMBRE | F2: Turno | I2: Completo
F4: REGISTRO DE VENTAS
A5: BOLETAS AFECTA | G5: BOLETAS EXENTA
A6: Folio Voucher | B6: Folio Boleta | C6: Forma de Pago | G6: Folio Voucher | H6: Folio Boleta | I6: Forma de Pago
C7: Efectivo | D7: Debito | E7: Credito | F7: Transf | I7: Efectivo | J7: Debito | K7: Credito | L7: Transf
B8: 21505 | D8: 13990 | H8: 9046 | J8: 18000
A9: 697 | B9: 21506 | D9: 4300 | G9: 1854 | H9: 9047 | J9: 28980
G10: 1855 | H10: 9048 | J10: 223000
B18: Totales | C18: =SUM($C8:$C17) -> 0 | D18: =SUM($D8:$D17) -> 18290 | E18: =SUM($E8:$E17) -> 0 | F18: =SUM($F8:$F17) -> 0 | H18: Totales | I18: =SUM($I8:$I17) -> 0 | J18: =SUM($J8:$J17) -> 269980 | K18: =SUM($K8:$K17) -> 0 | L18: =SUM($L8:$L17) -> 0
K20: TOTAL VENTAS | L20: =$C$18+$D$18+$E$18+$F$18+$I$18+$J$18+$K$18+$L$18 -> 288270
G22: INGRESOS - EGRESOS
A23: VENTAS - INGRESOS | E23: VENTAS | G23: COMPRAS - EGRESOS | J23: SALIDAS A CAJA
D24: Descripcion | F24: Total | J24: Descripcion | L24: Total
D25: Total Efectivo | F25: =C18+I18 -> 0 | J25: Efectivo
D26: Total Debito | F26: =D18+J18 -> 288270 | J26: Transferencia
D27: Total Credito | F27: =E18+K18 -> 0 | J27: Otro
D28: Total Transferencia | F28: =F18+L18 -> 0
D29: TOTAL VENTAS | F29: =SUM(F25:F28) -> 288270
D30: ENTRADAS A CAJA
D31: Descripcion | F31: Total
D32: Efectivo | J32: TOTAL OTROS EGRESOS | L32: =SUM(L25:L31) -> 0
D33: Otro | J33: RETIRO DE EFECTIVO
D34: TOTAL OTROS INGRESOS | F34: =SUM(F32:F33) -> 0 | J34: Cantidad a Retirar
E35: TOTAL INGRESOS | F35: =F29+F34 -> 288270 | K35: TOTAL EGRESOS | L35: =L32+L34 -> 0
G37: ARQUEO DE CAJA
A38: BILLETES | D38: Valor | E38: Cantidad | F38: Total | G38: MONEDAS | J38: Valor | K38: Cantidad | L38: Total
D39: 20000 | F39: =D39*E39 -> 0 | J39: 500 | K39: 1 | L39: =J39*K39 -> 500
D40: 10000 | F40: =D40*E40 -> 0 | J40: 100 | K40: 11 | L40: =J40*K40 -> 1100
D41: 5000 | F41: =D41*E41 -> 0 | J41: 50 | K41: 10 | L41: =J41*K41 -> 500
D42: 2000 | F42: =D42*E42 -> 0 | J42: 10 | K42: 37 | L42: =J42*K42 -> 370
D43: 1000 | E43: 11 | F43: =D43*E43 -> 11000
E44: TOTAL BILLETES | F44: =SUM(F39:F43) -> 11000 | K44: TOTAL MONEDAS | L44: =SUM(L39:L43) -> 2470
I46: RESUMEN ARQUEO DE CAJA
B48: OBSERVACIONES: | I48: APERTURA DE CAJA | J48: ='27'!J65 -> 13470
I50: TOTAL EFECTIVO FISICO | J50: =F44+L44 -> 13470
I52: TOTAL VENTAS | J52: =L20 -> 288270
I54: ENTRADAS A CAJA | J54: =F32
I56: SALIDAS A CAJA | J56: =L25+L34 -> 0
I58: TOTAL EN CAJA CON APERTURA | J58: =J48+J52+J54-J56 -> 301740
...

Sheet 27
A1: Fecha | C1: 45988 | F1: Vendedor | I1: Sasha Alcalá
A2: Mes | C2: NOVIEMBRE | F2: Turno | I2: Completo
F4: REGISTRO DE VENTAS
A5: BOLETAS AFECTA | G5: BOLETAS EXENTA
A6: Folio Voucher | B6: Folio Boleta | C6: Forma de Pago | G6: Folio Voucher | H6: Folio Boleta | I6: Forma de Pago
C7: Efectivo | D7: Debito | E7: Credito | F7: Transf | I7: Efectivo | J7: Debito | K7: Credito | L7: Transf
B8: 21502 | D8: 3900 | H8: 9036 | J8: 27500
B9: 21503 | D9: 8600 | H9: 9037 | J9: 15990
B10: 21504 | C10: 7400 | H10: 9038 | J10: 12990
G11: 1848 | H11: 9039 | J11: 45000
G12: 1849 | H12: 9040 | J12: 204500
G13: 1850 | H13: 9041 | J13: 7500
G14: 1851 | H14: 9042 | J14: 314500
H15: 9043 | I15: 59500
H16: 9044 | J16: 20490
G17: 1853 | H17: 9045 | K17: 324500
H18: 9045 | L18: 40000
B21: Totales | C21: =SUM($C8:$C14) -> 7400 | D21: =SUM($D8:$D14) -> 12500 | E21: =SUM($E8:$E14) -> 0 | F21: =SUM($F8:$F14) -> 0 | H21: Totales | I21: =SUM($I8:$I15) -> 59500 | J21: =SUM($J8:$J16) -> 648470 | K21: =SUM($K8:$K17) -> 324500 | L21: =SUM($L8:$L18) -> 40000
K23: TOTAL VENTAS | L23: =$C$21+$D$21+$E$21+$F$21+$I$21+$J$21+$K$21+$L$21 -> 1092370
G25: INGRESOS - EGRESOS
A26: VENTAS - INGRESOS | E26: VENTAS | G26: COMPRAS - EGRESOS | J26: SALIDAS A CAJA
D27: Descripcion | F27: Total | J27: Descripcion | L27: Total
D28: Total Efectivo | F28: =C21+I21 -> 66900 | J28: Efectivo | L28: 77500
D29: Total Debito | F29: =D21+J21 -> 660970 | J29: Transferencia
D30: Total Credito | F30: =E21+K21 -> 324500 | J30: Otro
D31: Total Transferencia | F31: =F21+L21 -> 40000
D32: TOTAL VENTAS | F32: =SUM(F28:F31) -> 1092370
D33: ENTRADAS A CAJA
D34: Descripcion | F34: Total
D35: Efectivo | J35: TOTAL OTROS EGRESOS | L35: =SUM(L28:L34) -> 77500
D36: Otro | J36: RETIRO DE EFECTIVO
D37: TOTAL OTROS INGRESOS | F37: =SUM(F35:F36) -> 0 | J37: Cantidad a Retirar
E38: TOTAL INGRESOS | F38: =F32+F37 -> 1092370 | K38: TOTAL EGRESOS | L38: =L35+L37 -> 77500
G40: ARQUEO DE CAJA
A41: BILLETES | D41: Valor | E41: Cantidad | F41: Total | G41: MONEDAS | J41: Valor | K41: Cantidad | L41: Total
D42: 20000 | F42: =D42*E42 -> 0 | J42: 500 | K42: 1 | L42: =J42*K42 -> 500
D43: 10000 | F43: =D43*E43 -> 0 | J43: 100 | K43: 11 | L43: =J43*K43 -> 1100
D44: 5000 | F44: =D44*E44 -> 0 | J44: 50 | K44: 10 | L44: =J44*K44 -> 500
D45: 2000 | F45: =D45*E45 -> 0 | J45: 10 | K45: 37 | L45: =J45*K45 -> 370
D46: 1000 | E46: 11 | F46: =D46*E46 -> 11000
...

Sheet 26
A1: Fecha | C1: 45987 | F1: Vendedor | I1: Sasha Alcalá
A2: Mes | C2: NOVIEMBRE | F2: Turno | I2: Completo
F4: REGISTRO DE VENTAS
A5: BOLETAS AFECTA | G5: BOLETAS EXENTA
A6: Folio Voucher | B6: Folio Boleta | C6: Forma de Pago | G6: Folio Voucher | H6: Folio Boleta | I6: Forma de Pago
C7: Efectivo | D7: Debito | E7: Credito | F7: Transf | I7: Efectivo | J7: Debito | K7: Credito | L7: Transf
A8: 695 | B8: 21499 | D8: 10500 | H8: 9032 | J8: 20490
B9: 21500 | D9: 3800 | H9: 9033 | J9: 15000
A10: 1847 | B10: 21501 | D10: 8600 | H10: 9034 | K10: 10000
G11: 18471844 | H11: 9035 | J11: 286500
B17: Totales | C17: =SUM($C8:$C16) -> 0 | D17: =SUM($D8:$D16) -> 22900 | E17: =SUM($E8:$E16) -> 0 | F17: =SUM($F8:$F16) -> 0 | H17: Totales | I17: =SUM($I8:$I16) -> 0 | J17: =SUM($J8:$J16) -> 321990 | K17: =SUM($K8:$K16) -> 10000 | L17: =SUM($L8:$L16) -> 0
K19: TOTAL VENTAS | L19: =$C$17+$D$17+$E$17+$F$17+$I$17+$J$17+$K$17+$L$17 -> 354890
G21: INGRESOS - EGRESOS
A22: VENTAS - INGRESOS | E22: VENTAS | G22: COMPRAS - EGRESOS | J22: SALIDAS A CAJA
D23: Descripcion | F23: Total | J23: Descripcion | L23: Total
D24: Total Efectivo | F24: =C17+I17 -> 0 | J24: Efectivo
D25: Total Debito | F25: =D17+J17 -> 344890 | J25: Transferencia
D26: Total Credito | F26: =E17+K17 -> 10000 | J26: Otro
D27: Total Transferencia | F27: =F17+L17 -> 0
D28: TOTAL VENTAS | F28: =SUM(F24:F27) -> 354890
D29: ENTRADAS A CAJA
D30: Descripcion | F30: Total
D31: Efectivo | F31: 0 | J31: TOTAL OTROS EGRESOS | L31: =SUM(L24:L30) -> 0
D32: Otro | J32: RETIRO DE EFECTIVO
D33: TOTAL OTROS INGRESOS | F33: =SUM(F31:F32) -> 0 | J33: Cantidad a Retirar
E34: TOTAL INGRESOS | F34: =F28+F33 -> 354890 | K34: TOTAL EGRESOS | L34: =L31+L33 -> 0
G36: ARQUEO DE CAJA
A37: BILLETES | D37: Valor | E37: Cantidad | F37: Total | G37: MONEDAS | J37: Valor | K37: Cantidad | L37: Total
D38: 20000 | F38: =D38*E38 -> 0 | J38: 500 | K38: 2 | L38: =J38*K38 -> 1000
D39: 10000 | F39: =D39*E39 -> 0 | J39: 100 | K39: 12 | L39: =J39*K39 -> 1200
D40: 5000 | E40: 1 | F40: =D40*E40 -> 5000 | J40: 50 | K40: 10 | L40: =J40*K40 -> 500
D41: 2000 | F41: =D41*E41 -> 0 | J41: 10 | K41: 37 | L41: =J41*K41 -> 370
D42: 1000 | E42: 16 | F42: =D42*E42 -> 16000
E43: TOTAL BILLETES | F43: =SUM(F38:F42) -> 21000 | K43: TOTAL MONEDAS | L43: =SUM(L38:L42) -> 3070
I45: RESUMEN ARQUEO DE CAJA
B47: OBSERVACIONES: | I47: APERTURA DE CAJA | J47: ='25'!J63 -> 24070
I49: TOTAL EFECTIVO FISICO | J49: =F43+L43 -> 24070
I51: TOTAL VENTAS | J51: =L19 -> 354890
I53: ENTRADAS A CAJA | J53: =F31 -> 0
I55: SALIDAS A CAJA | J55: =L24+L33 -> 0
...

Sheet 25
A1: Fecha | C1: 45986 | F1: Vendedor | I1: Sasha Alcalá
A2: Mes | C2: NOVIEMBRE | F2: Turno | I2: Completo
F4: REGISTRO DE VENTAS
A5: BOLETAS AFECTA | G5: BOLETAS EXENTA
A6: Folio Voucher | B6: Folio Boleta | C6: Forma de Pago | G6: Folio Voucher | H6: Folio Boleta | I6: Forma de Pago
C7: Efectivo | D7: Debito | E7: Credito | F7: Transf | I7: Efectivo | J7: Debito | K7: Credito | L7: Transf
H8: 9031 | J8: 15990
B19: Totales | C19: =SUM($C8:$C18) -> 0 | D19: =SUM($D8:$D18) -> 0 | E19: =SUM($E8:$E18) -> 0 | F19: =SUM($F8:$F18) -> 0 | H19: Totales | I19: =SUM($I8:$I18) -> 0 | J19: =SUM($J8:$J18) -> 15990 | K19: =SUM($K8:$K18) -> 0 | L19: =SUM($L8:$L18) -> 0
K21: TOTAL VENTAS | L21: =$C$19+$D$19+$E$19+$F$19+$I$19+$J$19+$K$19+$L$19 -> 15990
G23: INGRESOS - EGRESOS
A24: VENTAS - INGRESOS | E24: VENTAS | G24: COMPRAS - EGRESOS | J24: SALIDAS A CAJA
D25: Descripcion | F25: Total | J25: Descripcion | L25: Total
D26: Total Efectivo | F26: =C19+I19 -> 0 | J26: Efectivo
D27: Total Debito | F27: =D19+J19 -> 15990 | J27: Transferencia
D28: Total Credito | F28: =E19+K19 -> 0 | J28: Otro
D29: Total Transferencia | F29: =F19+L19 -> 0
D30: TOTAL VENTAS | F30: =SUM(F26:F29) -> 15990
D31: ENTRADAS A CAJA
D32: Descripcion | F32: Total
D33: Efectivo | J33: TOTAL OTROS EGRESOS | L33: =SUM(L26:L32) -> 0
D34: Otro | J34: RETIRO DE EFECTIVO
D35: TOTAL OTROS INGRESOS | F35: =SUM(F33:F34) -> 0 | J35: Cantidad a Retirar
E36: TOTAL INGRESOS | F36: =F30+F35 -> 15990 | K36: TOTAL EGRESOS | L36: =L33+L35 -> 0
G38: ARQUEO DE CAJA
A39: BILLETES | D39: Valor | E39: Cantidad | F39: Total | G39: MONEDAS | J39: Valor | K39: Cantidad | L39: Total
D40: 20000 | F40: =D40*E40 -> 0 | J40: 500 | K40: 2 | L40: =J40*K40 -> 1000
D41: 10000 | F41: =D41*E41 -> 0 | J41: 100 | K41: 12 | L41: =J41*K41 -> 1200
D42: 5000 | E42: 1 | F42: =D42*E42 -> 5000 | J42: 50 | K42: 10 | L42: =J42*K42 -> 500
D43: 2000 | F43: =D43*E43 -> 0 | J43: 10 | K43: 37 | L43: =J43*K43 -> 370
D44: 1000 | E44: 16 | F44: =D44*E44 -> 16000
E45: TOTAL BILLETES | F45: =SUM(F40:F44) -> 21000 | K45: TOTAL MONEDAS | L45: =SUM(L40:L44) -> 3070
I47: RESUMEN ARQUEO DE CAJA
B49: OBSERVACIONES: | I49: APERTURA DE CAJA | J49: ='24'!J60 -> 24070
I51: TOTAL EFECTIVO FISICO | J51: =F45+L45 -> 24070
I53: TOTAL VENTAS | J53: =L21 -> 15990
I55: ENTRADAS A CAJA | J55: =F33
I57: SALIDAS A CAJA | J57: =L26+L35 -> 0
I59: TOTAL EN CAJA CON APERTURA | J59: =J49+J53+J55-J57 -> 40060
I61: TOTAL EN CAJA | J61: =J59-J49 -> 15990
I63: CAJA FINAL EFECTIVO | J63: =J49+F26+(F33-(L26+L35)) -> 24070
...

Sheet 24
A1: Fecha | C1: 45985 | F1: Vendedor | I1: Sasha Alcalá
A2: Mes | C2: NOVIEMBRE | F2: Turno | I2: Completo
F4: REGISTRO DE VENTAS
A5: BOLETAS AFECTA | G5: BOLETAS EXENTA
A6: Folio Voucher | B6: Folio Boleta | C6: Forma de Pago | G6: Folio Voucher | H6: Folio Boleta | I6: Forma de Pago
C7: Efectivo | D7: Debito | E7: Credito | F7: Transf | I7: Efectivo | J7: Debito | K7: Credito | L7: Transf
B8: 21498 | C8: 3800 | H8: 9027 | L8: 10000
G9: 1842 | H9: 9027 | K9: 45000
G10: 1843 | H10: 9028 | J10: 15990
G11: 1841 | H11: 9029 | K11: 197002
G12: 1841 | H12: 9030 | K12: 178998
B16: Totales | C16: =SUM($C8:$C15) -> 3800 | D16: =SUM($D8:$D15) -> 0 | E16: =SUM($E8:$E15) -> 0 | F16: =SUM($F8:$F15) -> 0 | H16: Totales | I16: =SUM($I8:$I15) -> 0 | J16: =SUM($J8:$J15) -> 15990 | K16: =SUM($K8:$K15) -> 421000 | L16: =SUM($L8:$L15) -> 10000
K18: TOTAL VENTAS | L18: =$C$16+$D$16+$E$16+$F$16+$I$16+$J$16+$K$16+$L$16 -> 450790
G20: INGRESOS - EGRESOS
A21: VENTAS - INGRESOS | E21: VENTAS | G21: COMPRAS - EGRESOS | J21: SALIDAS A CAJA
D22: Descripcion | F22: Total | J22: Descripcion | L22: Total
D23: Total Efectivo | F23: =C16+I16 -> 3800 | J23: Efectivo | L23: 20000
D24: Total Debito | F24: =D16+J16 -> 15990 | J24: Transferencia
D25: Total Credito | F25: =E16+K16 -> 421000 | J25: Otro
D26: Total Transferencia | F26: =F16+L16 -> 10000
D27: TOTAL VENTAS | F27: =SUM(F23:F26) -> 450790
D28: ENTRADAS A CAJA
D29: Descripcion | F29: Total
D30: Efectivo | J30: TOTAL OTROS EGRESOS | L30: =SUM(L23:L29) -> 20000
D31: Otro | J31: RETIRO DE EFECTIVO
D32: TOTAL OTROS INGRESOS | F32: =SUM(F30:F31) -> 0 | J32: Cantidad a Retirar
E33: TOTAL INGRESOS | F33: =F27+F32 -> 450790 | K33: TOTAL EGRESOS | L33: =L30+L32 -> 20000
G35: ARQUEO DE CAJA
A36: BILLETES | D36: Valor | E36: Cantidad | F36: Total | G36: MONEDAS | J36: Valor | K36: Cantidad | L36: Total
D37: 20000 | F37: =D37*E37 -> 0 | J37: 500 | L37: =J37*K37 -> 0
D38: 10000 | E38: 1 | F38: =D38*E38 -> 10000 | J38: 100 | K38: 12 | L38: =J38*K38 -> 1200
D39: 5000 | E39: 1 | F39: =D39*E39 -> 5000 | J39: 50 | K39: 10 | L39: =J39*K39 -> 500
D40: 2000 | F40: =D40*E40 -> 0 | J40: 10 | K40: 37 | L40: =J40*K40 -> 370
D41: 1000 | E41: 7 | F41: =D41*E41 -> 7000
E42: TOTAL BILLETES | F42: =SUM(F37:F41) -> 22000 | K42: TOTAL MONEDAS | L42: =SUM(L37:L41) -> 2070
I44: RESUMEN ARQUEO DE CAJA
B46: OBSERVACIONES: | I46: APERTURA DE CAJA | J46: ='23'!J69 -> 40270
B48: ronald | I48: TOTAL EFECTIVO FISICO | J48: =F42+L42 -> 24070
I50: TOTAL VENTAS | J50: =L18 -> 450790
I52: ENTRADAS A CAJA | J52: =F30
...

Sheet 23
A1: Fecha | F1: Vendedor
A2: Mes | F2: Turno | I2: Completo
F4: REGISTRO DE VENTAS
A5: BOLETAS AFECTA | G5: BOLETAS EXENTA
A6: Folio Voucher | B6: Folio Boleta | C6: Forma de Pago | G6: Folio Voucher | H6: Folio Boleta | I6: Forma de Pago
C7: Efectivo | D7: Debito | E7: Credito | F7: Transf | I7: Efectivo | J7: Debito | K7: Credito | L7: Transf
B25: Totales | C25: =SUM($C8:$C24) -> 0 | D25: =SUM($D8:$D24) -> 0 | E25: =SUM($E8:$E24) -> 0 | F25: =SUM($F8:$F24) -> 0 | H25: Totales | I25: =SUM($I8:$I24) -> 0 | J25: =SUM($J8:$J24) -> 0 | K25: =SUM($K8:$K24) -> 0 | L25: =SUM($L8:$L24) -> 0
K27: TOTAL VENTAS | L27: =$C$25+$D$25+$E$25+$F$25+$I$25+$J$25+$K$25+$L$25 -> 0
G29: INGRESOS - EGRESOS
A30: VENTAS - INGRESOS | E30: VENTAS | G30: COMPRAS - EGRESOS | J30: SALIDAS A CAJA
D31: Descripcion | F31: Total | J31: Descripcion | L31: Total
D32: Total Efectivo | F32: =C25+I25 -> 0 | J32: Efectivo
D33: Total Debito | F33: =D25+J25 -> 0 | J33: Transferencia
D34: Total Credito | F34: =E25+K25 -> 0 | J34: Otro
D35: Total Transferencia | F35: =F25+L25 -> 0
D36: TOTAL VENTAS | F36: =SUM(F32:F35) -> 0
D37: ENTRADAS A CAJA
D38: Descripcion | F38: Total
D39: Efectivo | F39: 0 | J39: TOTAL OTROS EGRESOS | L39: =SUM(L32:L38) -> 0
D40: Otro | J40: RETIRO DE EFECTIVO
D41: TOTAL OTROS INGRESOS | F41: =SUM(F39:F40) -> 0 | J41: Cantidad a Retirar
E42: TOTAL INGRESOS | F42: =F36+F41 -> 0 | K42: TOTAL EGRESOS | L42: =L39+L41 -> 0
G44: ARQUEO DE CAJA
A45: BILLETES | D45: Valor | E45: Cantidad | F45: Total | G45: MONEDAS | J45: Valor | K45: Cantidad | L45: Total
D46: 20000 | F46: =D46*E46 -> 0 | J46: 500 | L46: =J46*K46 -> 0
D47: 10000 | F47: =D47*E47 -> 0 | J47: 100 | L47: =J47*K47 -> 0
D48: 5000 | F48: =D48*E48 -> 0 | J48: 50 | L48: =J48*K48 -> 0
D49: 2000 | F49: =D49*E49 -> 0 | J49: 10 | L49: =J49*K49 -> 0
D50: 1000 | F50: =D50*E50 -> 0
E51: TOTAL BILLETES | F51: =SUM(F46:F50) -> 0 | K51: TOTAL MONEDAS | L51: =SUM(L46:L50) -> 0
I53: RESUMEN ARQUEO DE CAJA
B55: OBSERVACIONES: | I55: APERTURA DE CAJA | J55: ='22'!J62 -> 40270
I57: TOTAL EFECTIVO FISICO | J57: =F51+L51 -> 0
I59: TOTAL VENTAS | J59: =L27 -> 0
I61: ENTRADAS A CAJA | J61: =F39 -> 0
I63: SALIDAS A CAJA | J63: =L32+L41 -> 0
I65: TOTAL EN CAJA CON APERTURA | J65: =J55+J59+J61-J63 -> 40270
I67: TOTAL EN CAJA | J67: =J65-J55 -> 0
I69: CAJA FINAL EFECTIVO | J69: =J55+F32+(F39-(L32+L41)) -> 40270
I71: DIFERENCIA | J71: =J57-J69 -> -40270

Sheet 22
A1: Fecha | C1: 45983 | F1: Vendedor | I1: Katherine Martinez
A2: Mes | C2: Noviembre | F2: Turno | I2: Completo
F4: REGISTRO DE VENTAS
A5: BOLETAS AFECTA | G5: BOLETAS EXENTA
A6: Folio Voucher | B6: Folio Boleta | C6: Forma de Pago | G6: Folio Voucher | H6: Folio Boleta | I6: Forma de Pago
C7: Efectivo | D7: Debito | E7: Credito | F7: Transf | I7: Efectivo | J7: Debito | K7: Credito | L7: Transf
A8: 31010 | B8: 21496 | E8: 10500 | G8: 1838 | H8: 9020 | K8: 255000
A9: 690 | B9: 21497 | D9: 11990 | G9: 1836 | H9: 9021 | J9: 24990
G10: 1837 | H10: 9022 | J10: 10000
G11: 1839 | H11: 9023 | J11: 17990
G12: 1840 | H12: 9024 | J12: 35500
H13: 9025 | I13: 10000
H14: 9026 | I14: 30000
B18: Totales | C18: =SUM($C8:$C17) -> 0 | D18: =SUM($D8:$D17) -> 11990 | E18: =SUM($E8:$E17) -> 10500 | F18: =SUM($F8:$F17) -> 0 | H18: Totales | I18: =SUM($I8:$I17) -> 40000 | J18: =SUM($J8:$J17) -> 88480 | K18: =SUM($K8:$K17) -> 255000 | L18: =SUM($L8:$L17) -> 0
K20: TOTAL VENTAS | L20: =$C$18+$D$18+$E$18+$F$18+$I$18+$J$18+$K$18+$L$18 -> 405970
G22: INGRESOS - EGRESOS
A23: VENTAS - INGRESOS | E23: VENTAS | G23: COMPRAS - EGRESOS | J23: SALIDAS A CAJA
D24: Descripcion | F24: Total | J24: Descripcion | L24: Total
D25: Total Efectivo | F25: =C18+I18 -> 40000 | J25: Efectivo | L25: 50000
D26: Total Debito | F26: =D18+J18 -> 100470 | J26: Transferencia
D27: Total Credito | F27: =E18+K18 -> 265500 | J27: Otro
D28: Total Transferencia | F28: =F18+L18 -> 0
D29: TOTAL VENTAS | F29: =SUM(F25:F28) -> 405970
D30: ENTRADAS A CAJA
D31: Descripcion | F31: Total
D32: Efectivo | J32: TOTAL OTROS EGRESOS | L32: =SUM(L25:L31) -> 50000
D33: Otro | J33: RETIRO DE EFECTIVO
D34: TOTAL OTROS INGRESOS | F34: =SUM(F32:F33) -> 0 | J34: Cantidad a Retirar
E35: TOTAL INGRESOS | F35: =F29+F34 -> 405970 | K35: TOTAL EGRESOS | L35: =L32+L34 -> 50000
G37: ARQUEO DE CAJA
A38: BILLETES | D38: Valor | E38: Cantidad | F38: Total | G38: MONEDAS | J38: Valor | K38: Cantidad | L38: Total
D39: 20000 | E39: 1 | F39: =D39*E39 -> 20000 | J39: 500 | L39: =J39*K39 -> 0
D40: 10000 | E40: 1 | F40: =D40*E40 -> 10000 | J40: 100 | K40: 14 | L40: =J40*K40 -> 1400
D41: 5000 | F41: =D41*E41 -> 0 | J41: 50 | K41: 10 | L41: =J41*K41 -> 500
D42: 2000 | F42: =D42*E42 -> 0 | J42: 10 | K42: 37 | L42: =J42*K42 -> 370
D43: 1000 | E43: 8 | F43: =D43*E43 -> 8000
E44: TOTAL BILLETES | F44: =SUM(F39:F43) -> 38000 | K44: TOTAL MONEDAS | L44: =SUM(L39:L43) -> 2270
I46: RESUMEN ARQUEO DE CAJA
B48: OBSERVACIONES: | I48: APERTURA DE CAJA | J48: ='21'!J61 -> 50270
B50: retiro caja 30.000 retiro de caja 20.000 | I50: TOTAL EFECTIVO FISICO | J50: =F44+L44 -> 40270
...

Sheet 21
A1: Fecha | C1: 45982 | F1: Vendedor | I1: Sasha Alcalá
A2: Mes | C2: NOVIEMBRE | F2: Turno | I2: Completo
F4: REGISTRO DE VENTAS
A5: BOLETAS AFECTA | G5: BOLETAS EXENTA
A6: Folio Voucher | B6: Folio Boleta | C6: Forma de Pago | G6: Folio Voucher | H6: Folio Boleta | I6: Forma de Pago
C7: Efectivo | D7: Debito | E7: Credito | F7: Transf | I7: Efectivo | J7: Debito | K7: Credito | L7: Transf
H8: 9014 | I8: 10000
H9: 9015 | J9: 59500
G10: 1834 | H10: 9016 | J10: 15990
H11: 9017 | J11: 24990
H12: 9018 | I12: 20490
G13: 1835 | H13: 9019 | J13: 55000
B17: Totales | C17: =SUM($C8:$C16) -> 0 | D17: =SUM($D8:$D16) -> 0 | E17: =SUM($E8:$E16) -> 0 | F17: =SUM($F8:$F16) -> 0 | H17: Totales | I17: =SUM($I8:$I16) -> 30490 | J17: =SUM($J8:$J16) -> 155480 | K17: =SUM($K8:$K16) -> 0 | L17: =SUM($L8:$L16) -> 0
K19: TOTAL VENTAS | L19: =$C$17+$D$17+$E$17+$F$17+$I$17+$J$17+$K$17+$L$17 -> 185970
G21: INGRESOS - EGRESOS
A22: VENTAS - INGRESOS | E22: VENTAS | G22: COMPRAS - EGRESOS | J22: SALIDAS A CAJA
D23: Descripcion | F23: Total | J23: Descripcion | L23: Total
D24: Total Efectivo | F24: =C17+I17 -> 30490 | J24: Efectivo
D25: Total Debito | F25: =D17+J17 -> 155480 | J25: Transferencia
D26: Total Credito | F26: =E17+K17 -> 0 | J26: Otro
D27: Total Transferencia | F27: =F17+L17 -> 0
D28: TOTAL VENTAS | F28: =SUM(F24:F27) -> 185970
D29: ENTRADAS A CAJA
D30: Descripcion | F30: Total
D31: Efectivo | J31: TOTAL OTROS EGRESOS | L31: =SUM(L24:L30) -> 0
D32: Otro | J32: RETIRO DE EFECTIVO
D33: TOTAL OTROS INGRESOS | F33: =SUM(F31:F32) -> 0 | J33: Cantidad a Retirar
E34: TOTAL INGRESOS | F34: =F28+F33 -> 185970 | K34: TOTAL EGRESOS | L34: =L31+L33 -> 0
G36: ARQUEO DE CAJA
A37: BILLETES | D37: Valor | E37: Cantidad | F37: Total | G37: MONEDAS | J37: Valor | K37: Cantidad | L37: Total
D38: 20000 | E38: 1 | F38: =D38*E38 -> 20000 | J38: 500 | L38: =J38*K38 -> 0
D39: 10000 | E39: 1 | F39: =D39*E39 -> 10000 | J39: 100 | K39: 14 | L39: =J39*K39 -> 1400
D40: 5000 | F40: =D40*E40 -> 0 | J40: 50 | K40: 10 | L40: =J40*K40 -> 500
D41: 2000 | E41: 4 | F41: =D41*E41 -> 8000 | J41: 10 | K41: 37 | L41: =J41*K41 -> 370
D42: 1000 | E42: 10 | F42: =D42*E42 -> 10000
E43: TOTAL BILLETES | F43: =SUM(F38:F42) -> 48000 | K43: TOTAL MONEDAS | L43: =SUM(L38:L42) -> 2270
I45: RESUMEN ARQUEO DE CAJA
B47: OBSERVACIONES: | I47: APERTURA DE CAJA | J47: ='20'!J61 -> 19780
I49: TOTAL EFECTIVO FISICO | J49: =F43+L43 -> 50270
I51: TOTAL VENTAS | J51: =L19 -> 185970
...

Sheet 20
A1: Fecha | C1: 45981 | F1: Vendedor | I1: Sasha Alcala
A2: Mes | C2: NOVIEMBRE | F2: Turno | I2: Completo
F4: REGISTRO DE VENTAS
A5: BOLETAS AFECTA | G5: BOLETAS EXENTA
A6: Folio Voucher | B6: Folio Boleta | C6: Forma de Pago | G6: Folio Voucher | H6: Folio Boleta | I6: Forma de Pago
C7: Efectivo | D7: Debito | E7: Credito | F7: Transf | I7: Efectivo | J7: Debito | K7: Credito | L7: Transf
G8: 1833 | H8: 9013 | K8: 205500
B17: Totales | C17: =SUM($C8:$C16) -> 0 | D17: =SUM($D8:$D16) -> 0 | E17: =SUM($E8:$E16) -> 0 | F17: =SUM($F8:$F16) -> 0 | H17: Totales | I17: =SUM($I8:$I16) -> 0 | J17: =SUM($J8:$J16) -> 0 | K17: =SUM($K8:$K16) -> 205500 | L17: =SUM($L8:$L16) -> 0
K19: TOTAL VENTAS | L19: =$C$17+$D$17+$E$17+$F$17+$I$17+$J$17+$K$17+$L$17 -> 205500
G21: INGRESOS - EGRESOS
A22: VENTAS - INGRESOS | E22: VENTAS | G22: COMPRAS - EGRESOS | J22: SALIDAS A CAJA
D23: Descripcion | F23: Total | J23: Descripcion | L23: Total
D24: Total Efectivo | F24: =C17+I17 -> 0 | J24: Efectivo
D25: Total Debito | F25: =D17+J17 -> 0 | J25: Transferencia
D26: Total Credito | F26: =E17+K17 -> 205500 | J26: Otro
D27: Total Transferencia | F27: =F17+L17 -> 0
D28: TOTAL VENTAS | F28: =SUM(F24:F27) -> 205500
D29: ENTRADAS A CAJA
D30: Descripcion | F30: Total
D31: Efectivo | J31: TOTAL OTROS EGRESOS | L31: =SUM(L24:L30) -> 0
D32: Otro | J32: RETIRO DE EFECTIVO
D33: TOTAL OTROS INGRESOS | F33: =SUM(F31:F32) -> 0 | J33: Cantidad a Retirar
E34: TOTAL INGRESOS | F34: =F28+F33 -> 205500 | K34: TOTAL EGRESOS | L34: =L31+L33 -> 0
G36: ARQUEO DE CAJA
A37: BILLETES | D37: Valor | E37: Cantidad | F37: Total | G37: MONEDAS | J37: Valor | K37: Cantidad | L37: Total
D38: 20000 | F38: =D38*E38 -> 0 | J38: 500 | L38: =J38*K38 -> 0
D39: 10000 | F39: =D39*E39 -> 0 | J39: 100 | K39: 19 | L39: =J39*K39 -> 1900
D40: 5000 | F40: =D40*E40 -> 0 | J40: 50 | K40: 10 | L40: =J40*K40 -> 500
D41: 2000 | E41: 4 | F41: =D41*E41 -> 8000 | J41: 10 | K41: 38 | L41: =J41*K41 -> 380
D42: 1000 | E42: 9 | F42: =D42*E42 -> 9000
E43: TOTAL BILLETES | F43: =SUM(F38:F42) -> 17000 | K43: TOTAL MONEDAS | L43: =SUM(L38:L42) -> 2780
I45: RESUMEN ARQUEO DE CAJA
B47: OBSERVACIONES: | I47: APERTURA DE CAJA | J47: ='19'!J58 -> 19780
I49: TOTAL EFECTIVO FISICO | J49: =F43+L43 -> 19780
I51: TOTAL VENTAS | J51: =L19 -> 205500
I53: ENTRADAS A CAJA | J53: =F31
I55: SALIDAS A CAJA | J55: =L24+L33 -> 0
I57: TOTAL EN CAJA CON APERTURA | J57: =J47+J51+J53-J55 -> 225280
I59: TOTAL EN CAJA | J59: =J57-J47 -> 205500
I61: CAJA FINAL EFECTIVO | J61: =J47+F24+(F31-(L24+L33)) -> 19780
...

Sheet 19
A1: Fecha | C1: 45980 | F1: Vendedor | I1: Sasha Alcalá
A2: Mes | C2: NOVIEMBRE | F2: Turno | I2: Completo
F4: REGISTRO DE VENTAS
A5: BOLETAS AFECTA | G5: BOLETAS EXENTA
A6: Folio Voucher | B6: Folio Boleta | C6: Forma de Pago | G6: Folio Voucher | H6: Folio Boleta | I6: Forma de Pago
C7: Efectivo | D7: Debito | E7: Credito | F7: Transf | I7: Efectivo | J7: Debito | K7: Credito | L7: Transf
H8: 9011 | I8: 25000
H9: 9012 | I9: 80000
B14: Totales | C14: =SUM($C8:$C13) -> 0 | D14: =SUM($D8:$D13) -> 0 | E14: =SUM($E8:$E13) -> 0 | F14: =SUM($F8:$F13) -> 0 | H14: Totales | I14: =SUM($I8:$I13) -> 105000 | J14: =SUM($J8:$J13) -> 0 | K14: =SUM($K8:$K13) -> 0 | L14: =SUM($L8:$L13) -> 0
K16: TOTAL VENTAS | L16: =$C$14+$D$14+$E$14+$F$14+$I$14+$J$14+$K$14+$L$14 -> 105000
G18: INGRESOS - EGRESOS
A19: VENTAS - INGRESOS | E19: VENTAS | G19: COMPRAS - EGRESOS | J19: SALIDAS A CAJA
D20: Descripcion | F20: Total | J20: Descripcion | L20: Total
D21: Total Efectivo | F21: =C14+I14 -> 105000 | J21: Efectivo | L21: 122030
D22: Total Debito | F22: =D14+J14 -> 0 | J22: Transferencia
D23: Total Credito | F23: =E14+K14 -> 0 | J23: Otro
D24: Total Transferencia | F24: =F14+L14 -> 0
D25: TOTAL VENTAS | F25: =SUM(F21:F24) -> 105000
D26: ENTRADAS A CAJA
D27: Descripcion | F27: Total
D28: Efectivo | F28: 0 | J28: TOTAL OTROS EGRESOS | L28: =SUM(L21:L27) -> 122030
D29: Otro | J29: RETIRO DE EFECTIVO
D30: TOTAL OTROS INGRESOS | F30: =SUM(F28:F29) -> 0 | J30: Cantidad a Retirar | L30: 0
E31: TOTAL INGRESOS | F31: =F25+F30 -> 105000 | K31: TOTAL EGRESOS | L31: =L28+L30 -> 122030
G33: ARQUEO DE CAJA
A34: BILLETES | D34: Valor | E34: Cantidad | F34: Total | G34: MONEDAS | J34: Valor | K34: Cantidad | L34: Total
D35: 20000 | F35: =D35*E35 -> 0 | J35: 500 | L35: =J35*K35 -> 0
D36: 10000 | F36: =D36*E36 -> 0 | J36: 100 | K36: 19 | L36: =J36*K36 -> 1900
D37: 5000 | F37: =D37*E37 -> 0 | J37: 50 | K37: 10 | L37: =J37*K37 -> 500
D38: 2000 | E38: 4 | F38: =D38*E38 -> 8000 | J38: 10 | K38: 38 | L38: =J38*K38 -> 380
D39: 1000 | E39: 9 | F39: =D39*E39 -> 9000
E40: TOTAL BILLETES | F40: =SUM(F35:F39) -> 17000 | K40: TOTAL MONEDAS | L40: =SUM(L35:L39) -> 2780
I42: RESUMEN ARQUEO DE CAJA
B44: OBSERVACIONES: | I44: APERTURA DE CAJA | J44: ='18'!J63 -> 36810
B46: a caja, xime y uber | I46: TOTAL EFECTIVO FISICO | J46: =F40+L40 -> 19780
I48: TOTAL VENTAS | J48: =L16 -> 105000
I50: ENTRADAS A CAJA | J50: =F28 -> 0
I52: SALIDAS A CAJA | J52: =L21+L30 -> 122030
I54: TOTAL EN CAJA CON APERTURA | J54: =J44+J48+J50-J52 -> 19780
I56: TOTAL EN CAJA | J56: =J54-J44 -> -17030
...

Sheet 18
A1: Fecha | C1: 45979 | F1: Vendedor | I1: Sasha Alcalá
A2: Mes | C2: Noviembre | F2: Turno | I2: Completo
F4: REGISTRO DE VENTAS
A5: BOLETAS AFECTA | G5: BOLETAS EXENTA
A6: Folio Voucher | B6: Folio Boleta | C6: Forma de Pago | G6: Folio Voucher | H6: Folio Boleta | I6: Forma de Pago
C7: Efectivo | D7: Debito | E7: Credito | F7: Transf | I7: Efectivo | J7: Debito | K7: Credito | L7: Transf
A8: 688 | B8: 21495 | D8: 13550 | H8: 9009 | I8: 10000
H9: 9010 | I9: 25000
B19: Totales | C19: =SUM($C8:$C18) -> 0 | D19: =SUM($D8:$D18) -> 13550 | E19: =SUM($E8:$E18) -> 0 | F19: =SUM($F8:$F18) -> 0 | H19: Totales | I19: =SUM($I8:$I18) -> 35000 | J19: =SUM($J8:$J18) -> 0 | K19: =SUM($K8:$K18) -> 0 | L19: =SUM($L8:$L18) -> 0
K21: TOTAL VENTAS | L21: =$C$19+$D$19+$E$19+$F$19+$I$19+$J$19+$K$19+$L$19 -> 48550
G23: INGRESOS - EGRESOS
A24: VENTAS - INGRESOS | E24: VENTAS | G24: COMPRAS - EGRESOS | J24: SALIDAS A CAJA
D25: Descripcion | F25: Total | J25: Descripcion | L25: Total
D26: Total Efectivo | F26: =C19+I19 -> 35000 | J26: Efectivo | L26: 20000
D27: Total Debito | F27: =D19+J19 -> 13550 | J27: Transferencia
D28: Total Credito | F28: =E19+K19 -> 0 | J28: Otro
D29: Total Transferencia | F29: =F19+L19 -> 0
D30: TOTAL VENTAS | F30: =SUM(F26:F29) -> 48550
D31: ENTRADAS A CAJA
D32: Descripcion | F32: Total
D33: Efectivo | J33: TOTAL OTROS EGRESOS | L33: =SUM(L26:L32) -> 20000
D34: Otro | J34: RETIRO DE EFECTIVO
D35: TOTAL OTROS INGRESOS | F35: =SUM(F33:F34) -> 0 | J35: Cantidad a Retirar
E36: TOTAL INGRESOS | F36: =F30+F35 -> 48550 | K36: TOTAL EGRESOS | L36: =L33+L35 -> 20000
G38: ARQUEO DE CAJA
A39: BILLETES | D39: Valor | E39: Cantidad | F39: Total | G39: MONEDAS | J39: Valor | K39: Cantidad | L39: Total
D40: 20000 | F40: =D40*E40 -> 0 | J40: 500 | L40: =J40*K40 -> 0
D41: 10000 | F41: =D41*E41 -> 0 | J41: 100 | K41: 19 | L41: =J41*K41 -> 1900
D42: 5000 | E42: 5 | F42: =D42*E42 -> 25000 | J42: 50 | K42: 10 | L42: =J42*K42 -> 500
D43: 2000 | F43: =D43*E43 -> 0 | J43: 10 | K43: 41 | L43: =J43*K43 -> 410
D44: 1000 | E44: 9 | F44: =D44*E44 -> 9000
E45: TOTAL BILLETES | F45: =SUM(F40:F44) -> 34000 | K45: TOTAL MONEDAS | L45: =SUM(L40:L44) -> 2810
I47: RESUMEN ARQUEO DE CAJA
B49: OBSERVACIONES: | I49: APERTURA DE CAJA | J49: ='17'!J63 -> 21810
B51: Salida Ronald | I51: TOTAL EFECTIVO FISICO | J51: =F45+L45 -> 36810
I53: TOTAL VENTAS | J53: =L21 -> 48550
I55: ENTRADAS A CAJA | J55: =F33
I57: SALIDAS A CAJA | J57: =L26+L35 -> 20000
I59: TOTAL EN CAJA CON APERTURA | J59: =J49+J53+J55-J57 -> 50360
I61: TOTAL EN CAJA | J61: =J59-J49 -> 28550
...

Sheet 17
A1: Fecha | C1: 45978 | F1: Vendedor | I1: Sasha Alcalá
A2: Mes | C2: NOVIEMBRE | F2: Turno | I2: Completo
F4: REGISTRO DE VENTAS
A5: BOLETAS AFECTA | G5: BOLETAS EXENTA
A6: Folio Voucher | B6: Folio Boleta | C6: Forma de Pago | G6: Folio Voucher | H6: Folio Boleta | I6: Forma de Pago
C7: Efectivo | D7: Debito | E7: Credito | F7: Transf | I7: Efectivo | J7: Debito | K7: Credito | L7: Transf
A8: 684 | B8: 21492 | D8: 14500 | G8: 1827 | H8: 9002 | J8: 24990
A9: 685 | B9: 21493 | D9: 11990 | G9: 1825 | H9: 9003 | J9: 190000
A10: 686 | B10: 21494 | D10: 3200 | G10: 1826 | H10: 9004 | K10: 20980
G11: 18281820 | H11: 9005 | J11: 13990
G12: 1830 | H12: 9006 | J12: 15990
H13: 9007 | L13: 105000
G14: 1831 | H14: 9008 | J14: 193500
B19: Totales | C19: =SUM($C8:$C18) -> 0 | D19: =SUM($D8:$D18) -> 29690 | E19: =SUM($E8:$E18) -> 0 | F19: =SUM($F8:$F18) -> 0 | H19: Totales | I19: =SUM($I8:$I18) -> 0 | J19: =SUM($J8:$J18) -> 438470 | K19: =SUM($K8:$K18) -> 20980 | L19: =SUM($L8:$L18) -> 105000
K21: TOTAL VENTAS | L21: =$C$19+$D$19+$E$19+$F$19+$I$19+$J$19+$K$19+$L$19 -> 594140
G23: INGRESOS - EGRESOS
A24: VENTAS - INGRESOS | E24: VENTAS | G24: COMPRAS - EGRESOS | J24: SALIDAS A CAJA
D25: Descripcion | F25: Total | J25: Descripcion | L25: Total
D26: Total Efectivo | F26: =C19+I19 -> 0 | J26: Efectivo | L26: 9700
D27: Total Debito | F27: =D19+J19 -> 468160 | J27: Transferencia
D28: Total Credito | F28: =E19+K19 -> 20980 | J28: Otro
D29: Total Transferencia | F29: =F19+L19 -> 105000
D30: TOTAL VENTAS | F30: =SUM(F26:F29) -> 594140
D31: ENTRADAS A CAJA
D32: Descripcion | F32: Total
D33: Efectivo | J33: TOTAL OTROS EGRESOS | L33: =SUM(L26:L32) -> 9700
D34: Otro | J34: RETIRO DE EFECTIVO
D35: TOTAL OTROS INGRESOS | F35: =SUM(F33:F34) -> 0 | J35: Cantidad a Retirar
E36: TOTAL INGRESOS | F36: =F30+F35 -> 594140 | K36: TOTAL EGRESOS | L36: =L33+L35 -> 9700
G38: ARQUEO DE CAJA
A39: BILLETES | D39: Valor | E39: Cantidad | F39: Total | G39: MONEDAS | J39: Valor | K39: Cantidad | L39: Total
D40: 20000 | F40: =D40*E40 -> 0 | J40: 500 | L40: =J40*K40 -> 0
D41: 10000 | F41: =D41*E41 -> 0 | J41: 100 | K41: 19 | L41: =J41*K41 -> 1900
D42: 5000 | E42: 1 | F42: =D42*E42 -> 5000 | J42: 50 | K42: 10 | L42: =J42*K42 -> 500
D43: 2000 | F43: =D43*E43 -> 0 | J43: 10 | K43: 41 | L43: =J43*K43 -> 410
D44: 1000 | E44: 14 | F44: =D44*E44 -> 14000
E45: TOTAL BILLETES | F45: =SUM(F40:F44) -> 19000 | K45: TOTAL MONEDAS | L45: =SUM(L40:L44) -> 2810
I47: RESUMEN ARQUEO DE CAJA
B49: OBSERVACIONES: | I49: APERTURA DE CAJA | J49: ='16'!J69 -> 31510
B51: Encomienda Pamela | I51: TOTAL EFECTIVO FISICO | J51: =F45+L45 -> 21810
...

Sheet 16
A1: Fecha | F1: Vendedor
A2: Mes | F2: Turno | I2: Completo
F4: REGISTRO DE VENTAS
A5: BOLETAS AFECTA | G5: BOLETAS EXENTA
A6: Folio Voucher | B6: Folio Boleta | C6: Forma de Pago | G6: Folio Voucher | H6: Folio Boleta | I6: Forma de Pago
C7: Efectivo | D7: Debito | E7: Credito | F7: Transf | I7: Efectivo | J7: Debito | K7: Credito | L7: Transf
B25: Totales | C25: =SUM($C8:$C24) -> 0 | D25: =SUM($D8:$D24) -> 0 | E25: =SUM($E8:$E24) -> 0 | F25: =SUM($F8:$F24) -> 0 | H25: Totales | I25: =SUM($I8:$I24) -> 0 | J25: =SUM($J8:$J24) -> 0 | K25: =SUM($K8:$K24) -> 0 | L25: =SUM($L8:$L24) -> 0
K27: TOTAL VENTAS | L27: =$C$25+$D$25+$E$25+$F$25+$I$25+$J$25+$K$25+$L$25 -> 0
G29: INGRESOS - EGRESOS
A30: VENTAS - INGRESOS | E30: VENTAS | G30: COMPRAS - EGRESOS | J30: SALIDAS A CAJA
D31: Descripcion | F31: Total | J31: Descripcion | L31: Total
D32: Total Efectivo | F32: =C25+I25 -> 0 | J32: Efectivo
D33: Total Debito | F33: =D25+J25 -> 0 | J33: Transferencia
D34: Total Credito | F34: =E25+K25 -> 0 | J34: Otro
D35: Total Transferencia | F35: =F25+L25 -> 0
D36: TOTAL VENTAS | F36: =SUM(F32:F35) -> 0
D37: ENTRADAS A CAJA
D38: Descripcion | F38: Total
D39: Efectivo | J39: TOTAL OTROS EGRESOS | L39: =SUM(L32:L38) -> 0
D40: Otro | J40: RETIRO DE EFECTIVO
D41: TOTAL OTROS INGRESOS | F41: =SUM(F39:F40) -> 0 | J41: Cantidad a Retirar
E42: TOTAL INGRESOS | F42: =F36+F41 -> 0 | K42: TOTAL EGRESOS | L42: =L39+L41 -> 0
G44: ARQUEO DE CAJA
A45: BILLETES | D45: Valor | E45: Cantidad | F45: Total | G45: MONEDAS | J45: Valor | K45: Cantidad | L45: Total
D46: 20000 | F46: =D46*E46 -> 0 | J46: 500 | L46: =J46*K46 -> 0
D47: 10000 | F47: =D47*E47 -> 0 | J47: 100 | L47: =J47*K47 -> 0
D48: 5000 | F48: =D48*E48 -> 0 | J48: 50 | L48: =J48*K48 -> 0
D49: 2000 | F49: =D49*E49 -> 0 | J49: 10 | L49: =J49*K49 -> 0
D50: 1000 | F50: =D50*E50 -> 0
E51: TOTAL BILLETES | F51: =SUM(F46:F50) -> 0 | K51: TOTAL MONEDAS | L51: =SUM(L46:L50) -> 0
I53: RESUMEN ARQUEO DE CAJA
B55: OBSERVACIONES: | I55: APERTURA DE CAJA | J55: ='15'!J61 -> 31510
I57: TOTAL EFECTIVO FISICO | J57: =F51+L51 -> 0
I59: TOTAL VENTAS | J59: =L27 -> 0
I61: ENTRADAS A CAJA | J61: =F39
I63: SALIDAS A CAJA | J63: =L32+L41 -> 0
I65: TOTAL EN CAJA CON APERTURA | J65: =J55+J59+J61-J63 -> 31510
I67: TOTAL EN CAJA | J67: =J65-J55 -> 0
I69: CAJA FINAL EFECTIVO | J69: =J55+F32+(F39-(L32+L41)) -> 31510
I71: DIFERENCIA | J71: =J57-J69 -> -31510

Sheet 15
A1: Fecha | C1: 45976 | F1: Vendedor | I1: Katherine Martinez
A2: Mes | C2: Noviembre | F2: Turno | I2: Completo
F4: REGISTRO DE VENTAS
A5: BOLETAS AFECTA | G5: BOLETAS EXENTA
A6: Folio Voucher | B6: Folio Boleta | C6: Forma de Pago | G6: Folio Voucher | H6: Folio Boleta | I6: Forma de Pago
C7: Efectivo | D7: Debito | E7: Credito | F7: Transf | I7: Efectivo | J7: Debito | K7: Credito | L7: Transf
G8: 1820 | H8: 8996 | J8: 85000
G9: 1821 | H9: 8997 | J9: 10000
G10: 2511 | H10: 8998 | L10: 425000
G11: 1822 | H11: 8999 | J11: 10000
G12: 1823 | H12: 9000 | J12: 15990
G13: 1824 | H13: 9001 | J13: 34990
B17: Totales | C17: =SUM($C8:$C16) -> 0 | D17: =SUM($D8:$D16) -> 0 | E17: =SUM($E8:$E16) -> 0 | F17: =SUM($F8:$F16) -> 0 | H17: Totales | I17: =SUM($I8:$I16) -> 0 | J17: =SUM($J8:$J16) -> 155980 | K17: =SUM($K8:$K16) -> 0 | L17: =SUM($L8:$L16) -> 425000
K19: TOTAL VENTAS | L19: =$C$17+$D$17+$E$17+$F$17+$I$17+$J$17+$K$17+$L$17 -> 580980
G21: INGRESOS - EGRESOS
A22: VENTAS - INGRESOS | E22: VENTAS | G22: COMPRAS - EGRESOS | J22: SALIDAS A CAJA
D23: Descripcion | F23: Total | J23: Descripcion | L23: Total
D24: Total Efectivo | F24: =C17+I17 -> 0 | J24: Efectivo
D25: Total Debito | F25: =D17+J17 -> 155980 | J25: Transferencia
D26: Total Credito | F26: =E17+K17 -> 0 | J26: Otro
D27: Total Transferencia | F27: =F17+L17 -> 425000
D28: TOTAL VENTAS | F28: =SUM(F24:F27) -> 580980
D29: ENTRADAS A CAJA
D30: Descripcion | F30: Total
D31: Efectivo | J31: TOTAL OTROS EGRESOS | L31: =SUM(L24:L30) -> 0
D32: Otro | J32: RETIRO DE EFECTIVO
D33: TOTAL OTROS INGRESOS | F33: =SUM(F31:F32) -> 0 | J33: Cantidad a Retirar
E34: TOTAL INGRESOS | F34: =F28+F33 -> 580980 | K34: TOTAL EGRESOS | L34: =L31+L33 -> 0
G36: ARQUEO DE CAJA
A37: BILLETES | D37: Valor | E37: Cantidad | F37: Total | G37: MONEDAS | J37: Valor | K37: Cantidad | L37: Total
D38: 20000 | F38: =D38*E38 -> 0 | J38: 500 | L38: =J38*K38 -> 0
D39: 10000 | E39: 1 | F39: =D39*E39 -> 10000 | J39: 100 | K39: 16 | L39: =J39*K39 -> 1600
D40: 5000 | F40: =D40*E40 -> 0 | J40: 50 | K40: 10 | L40: =J40*K40 -> 500
D41: 2000 | E41: 2 | F41: =D41*E41 -> 4000 | J41: 10 | K41: 41 | L41: =J41*K41 -> 410
D42: 1000 | E42: 15 | F42: =D42*E42 -> 15000
E43: TOTAL BILLETES | F43: =SUM(F38:F42) -> 29000 | K43: TOTAL MONEDAS | L43: =SUM(L38:L42) -> 2510
I45: RESUMEN ARQUEO DE CAJA
B47: OBSERVACIONES: | I47: APERTURA DE CAJA | J47: ='14'!J63 -> 31510
I49: TOTAL EFECTIVO FISICO | J49: =F43+L43 -> 31510
I51: TOTAL VENTAS | J51: =L19 -> 580980
...

Sheet 14
A1: Fecha | C1: 45975 | F1: Vendedor | I1: Sasha Alcalá
A2: Mes | C2: NOVIEMBRE | F2: Turno | I2: Completo
F4: REGISTRO DE VENTAS
A5: BOLETAS AFECTA | G5: BOLETAS EXENTA
A6: Folio Voucher | B6: Folio Boleta | C6: Forma de Pago | G6: Folio Voucher | H6: Folio Boleta | I6: Forma de Pago
C7: Efectivo | D7: Debito | E7: Credito | F7: Transf | I7: Efectivo | J7: Debito | K7: Credito | L7: Transf
A8: 681 | B8: 21489 | D8: 9200 | G8: 1816 | H8: 8992 | J8: 34990
B9: 21490 | C9: 3200 | G9: 18181819 | H9: 8993 | K9: 74490
A10: 682 | B10: 21491 | D10: 10500 | G10: 1817 | H10: 8994 | J10: 25000
H11: 8995 | I11: 8100
