Workbook

Sheet COMPRAS 2025
O1: CÓDIGO: | P1: PE-LC-01
I2: LIBRO DE COMPRAS 2025 | O2: VERSIÓN: | P2: 1
O3: FECHA: | P3: 45665
A5: ALERTA | B5: DOCUMENTO | C5: EMPRESA | D5: FECHA VENCIMIENTO | E5: FECHA EMISION | F5: N° MES | G5: N° FOLIO | H5: RUT | I5: RAZON SOCIAL | J5: NETO | K5: IVA | L5: MONTO TOTAL | M5: ESTADO | N5: METODO DE PAGO | O5: CENTRO DE COSTOS | P5: DESCRIPCION
A6: ='COMPRAS 2025'!$D6-TODAY() -> -388 | B6: FACTURA | C6: PET EXOTIC LTDA | D6: 45660 | E6: 45660 | F6: =MONTH('COMPRAS 2025'!$E6) -> 1 | G6: 1908941 | H6: 83382700-6 | I6: COMERCIAL ECCSA SA | J6: 327723 | K6: 62267 | L6: ='COMPRAS 2025'!$J6+'COMPRAS 2025'!$K6 -> 389990 | M6: PAGADO | N6: DEBITO | O6: Mercancia - Proveedores
A7: ='COMPRAS 2025'!$D7-TODAY() -> -354 | B7: FACTURA | C7: PET EXOTIC LTDA | D7: 45694 | E7: 45664 | F7: =MONTH('COMPRAS 2025'!$E7) -> 1 | G7: 380775 | H7: 76080982-9 | I7: DIPROVET DISTRIBUIDORA DE PRODUCTOS VETERINARIOS SPA | J7: 100853 | K7: 19162 | L7: ='COMPRAS 2025'!$J7+'COMPRAS 2025'!$K7 -> 120015 | M7: PAGADO | N7: CREDITO | O7: Mercancia - Proveedores
A8: ='COMPRAS 2025'!$D8-TODAY() -> -354 | B8: FACTURA | C8: PET EXOTIC LTDA | D8: 45694 | E8: 45664 | F8: =MONTH('COMPRAS 2025'!$E8) -> 1 | G8: 380776 | H8: 76080982-9 | I8: DIPROVET DISTRIBUIDORA DE PRODUCTOS VETERINARIOS SPA | J8: 132790 | K8: 25230 | L8: ='COMPRAS 2025'!$J8+'COMPRAS 2025'!$K8 -> 158020 | M8: PAGADO | N8: CREDITO | O8: Mercancia - Proveedores
A9: ='COMPRAS 2025'!$D9-TODAY() -> -385 | B9: FACTURA | C9: PET EXOTIC LTDA | D9: 45663 | E9: 45663 | F9: =MONTH('COMPRAS 2025'!$E9) -> 1 | G9: 5483933 | H9: 76979850-1 | I9: FABRICA DE BANDEJAS LIMITADA | J9: 9229 | K9: 1754 | L9: ='COMPRAS 2025'!$J9+'COMPRAS 2025'!$K9 -> 10983 | M9: PAGADO | N9: DEBITO | O9: Mercancia - Proveedores
A10: ='COMPRAS 2025'!$D10-TODAY() -> -389 | B10: FACTURA | C10: PET EXOTIC LTDA | D10: 45659 | E10: 45659 | F10: =MONTH('COMPRAS 2025'!$E10) -> 1 | G10: 216729 | H10: 9538683-0 | I10: CLAUDIO ARANCIBIA DONOSO | J10: 4370 | K10: 830 | L10: ='COMPRAS 2025'!$J10+'COMPRAS 2025'!$K10 -> 5200 | M10: PAGADO | N10: EFECTIVO | O10: Mercancia - Proveedores
A11: ='COMPRAS 2025'!$D11-TODAY() -> -389 | B11: FACTURA | C11: PET EXOTIC LTDA | D11: 45659 | E11: 45659 | F11: =MONTH('COMPRAS 2025'!$E11) -> 1 | G11: 16365 | H11: 16774813-9 | I11: JOSE IGNACIO MORENO URRA | J11: 5882 | K11: 1118 | L11: ='COMPRAS 2025'!$J11+'COMPRAS 2025'!$K11 -> 7000 | M11: PAGADO | N11: DEBITO | O11: Mercancia - Proveedores
A12: ='COMPRAS 2025'!$D12-TODAY() -> -370 | B12: FACTURA | C12: PET EXOTIC LTDA | D12: 45678 | E12: 45678 | F12: =MONTH('COMPRAS 2025'!$E12) -> 1 | G12: 5505318 | H12: 76979850-1 | I12: FABRICA DE BANDEJAS LIMITADA | J12: 16700 | K12: 3173 | L12: ='COMPRAS 2025'!$J12+'COMPRAS 2025'!$K12 -> 19873 | M12: PAGADO | N12: DEBITO | O12: Mercancia - Proveedores
A13: ='COMPRAS 2025'!$D13-TODAY() -> -370 | B13: BOLETA | C13: PET EXOTIC LTDA | D13: 45678 | E13: 45678 | F13: =MONTH('COMPRAS 2025'!$E13) -> 1 | G13: 9683105 | H13: 76979850-1 | I13: FABRICA DE BANDEJAS LIMITADA | J13: 3872 | K13: 736 | L13: ='COMPRAS 2025'!$J13+'COMPRAS 2025'!$K13 -> 4608 | M13: PAGADO | N13: DEBITO | O13: Mercancia - Proveedores
A14: ='COMPRAS 2025'!$D14-TODAY() -> -338 | B14: FACTURA | C14: PET EXOTIC LTDA | D14: 45710 | E14: 45680 | F14: =MONTH('COMPRAS 2025'!$E14) -> 1 | G14: 382918 | H14: 76080982-9 | I14: DIPROVET DISTRIBUIDORA DE PRODUCTOS VETERINARIOS SPA | J14: 72500 | K14: 13775 | L14: ='COMPRAS 2025'!$J14+'COMPRAS 2025'!$K14 -> 86275 | M14: PAGADO | N14: CREDITO | O14: Mercancia - Proveedores
A15: ='COMPRAS 2025'!$D15-TODAY() -> -338 | B15: FACTURA | C15: PET EXOTIC LTDA | D15: 45710 | E15: 45680 | F15: =MONTH('COMPRAS 2025'!$E15) -> 1 | G15: 382917 | H15: 76080982-9 | I15: DIPROVET DISTRIBUIDORA DE PRODUCTOS VETERINARIOS SPA | J15: 66460 | K15: 12627 | L15: ='COMPRAS 2025'!$J15+'COMPRAS 2025'!$K15 -> 79087 | M15: PAGADO | N15: CREDITO | O15: Mercancia - Proveedores
A16: ='COMPRAS 2025'!$D16-TODAY() -> -363 | B16: FACTURA | C16: PET EXOTIC LTDA | D16: 45685 | E16: 45685 | F16: =MONTH('COMPRAS 2025'!$E16) -> 1 | G16: 2796129 | H16: 80478200-1 | I16: ILOP SA | J16: 9479 | K16: 1801 | L16: ='COMPRAS 2025'!$J16+'COMPRAS 2025'!$K16 -> 11280 | M16: PAGADO | N16: DEBITO | O16: Mercancia - Proveedores
A17: ='COMPRAS 2025'!$D17-TODAY() -> -320 | B17: FACTURA | C17: PET EXOTIC LTDA | D17: 45728 | E17: 45698 | F17: =MONTH('COMPRAS 2025'!$E17) -> 2 | G17: 385112 | H17: 76080982-9 | I17: DIPROVET DISTRIBUIDORA DE PRODUCTOS VETERINARIOS SPA | J17: 58850 | K17: 11182 | L17: ='COMPRAS 2025'!$J17+'COMPRAS 2025'!$K17 -> 70032 | M17: PAGADO | N17: CREDITO | O17: Mercancia - Proveedores
... A50: ='COMPRAS 2025'!$D50-TODAY() -> -286 | B50: FACTURA | C50: PET EXOTIC LTDA | D50: 45762 | E50: 45762 | F50: =MONTH('COMPRAS 2025'!$E50) -> 4 | G50: 24004864 | H50: 81201000-K | I50: CENCOSUD RETAIL SA | J50: 12111 | K50: 2301 | L50: ='COMPRAS 2025'!$J50+'COMPRAS 2025'!$K50 -> 14412 | M50: PAGADO | N50: DEBITO | O50: Mercancia - Proveedores
A51: ='COMPRAS 2025'!$D51-TODAY() -> -283 | B51: FACTURA | C51: PET EXOTIC LTDA | D51: 45765 | E51: 45765 | F51: =MONTH('COMPRAS 2025'!$E51) -> 4 | G51: 57266614 | H51: 76134946-5 | I51: SUPERMERCADO LIDER | J51: 16729 | K51: =3179+182 -> 3361 | L51: ='COMPRAS 2025'!$J51+'COMPRAS 2025'!$K51 -> 20090 | M51: PAGADO | N51: DEBITO | O51: Mercancia - Proveedores
A52: ='COMPRAS 2025'!$D52-TODAY() -> -280 | B52: FACTURA | C52: PET EXOTIC LTDA | D52: 45768 | E52: 45768 | F52: =MONTH('COMPRAS 2025'!$E52) -> 4 | G52: 5676738 | H52: 76979850-1 | I52: FABRICA DE BANDEJAS LIMITADA | J52: 7631 | K52: 1450 | L52: ='COMPRAS 2025'!$J52+'COMPRAS 2025'!$K52 -> 9081 | M52: PAGADO | N52: DEBITO | O52: Mercancia - Proveedores
A53: ='COMPRAS 2025'!$D53-TODAY() -> -255 | B53: FACTURA | C53: PET EXOTIC LTDA | D53: 45793 | E53: 45763 | F53: =MONTH('COMPRAS 2025'!$E53) -> 4 | G53: 115157 | H53: 76218200-9 | I53: DYKONOS CIA LIMITADA | J53: 118429 | K53: 22502 | L53: ='COMPRAS 2025'!$J53+'COMPRAS 2025'!$K53 -> 140931 | M53: PAGADO | N53: CREDITO | O53: Mercancia - Proveedores
A54: ='COMPRAS 2025'!$D54-TODAY() -> -255 | B54: FACTURA | C54: PET EXOTIC LTDA | D54: 45793 | E54: 45763 | F54: =MONTH('COMPRAS 2025'!$E54) -> 4 | G54: 115172 | H54: 76218200-9 | I54: DYKONOS CIA LIMITADA | J54: 13402 | K54: 2546 | L54: ='COMPRAS 2025'!$J54+'COMPRAS 2025'!$K54 -> 15948 | M54: PAGADO | N54: CREDITO | O54: Mercancia - Proveedores
A55: ='COMPRAS 2025'!$D55-TODAY() -> -248 | B55: FACTURA | C55: PET EXOTIC LTDA | D55: 45800 | E55: 45770 | F55: =MONTH('COMPRAS 2025'!$E55) -> 4 | G55: 394531 | H55: 76080982-9 | I55: DIPROVET DISTRIBUIDORA DE PRODUCTOS VETERINARIOS SPA | J55: 24980 | K55: 4746 | L55: ='COMPRAS 2025'!$J55+'COMPRAS 2025'!$K55 -> 29726 | M55: PAGADO | N55: CREDITO | O55: Mercancia - Proveedores
A56: ='COMPRAS 2025'!$D56-TODAY() -> -248 | B56: FACTURA | C56: PET EXOTIC LTDA | D56: 45800 | E56: 45770 | F56: =MONTH('COMPRAS 2025'!$E56) -> 4 | G56: 394530 | H56: 76080982-9 | I56: DIPROVET DISTRIBUIDORA DE PRODUCTOS VETERINARIOS SPA | J56: 112840 | K56: 21440 | L56: ='COMPRAS 2025'!$J56+'COMPRAS 2025'!$K56 -> 134280 | M56: PAGADO | N56: CREDITO | O56: Mercancia - Proveedores
A57: ='COMPRAS 2025'!$D57-TODAY() -> -248 | B57: FACTURA | C57: PET EXOTIC LTDA | D57: 45800 | E57: 45770 | F57: =MONTH('COMPRAS 2025'!$E57) -> 4 | G57: 394529 | H57: 76080982-9 | I57: DIPROVET DISTRIBUIDORA DE PRODUCTOS VETERINARIOS SPA | J57: 56660 | K57: 10765 | L57: ='COMPRAS 2025'!$J57+'COMPRAS 2025'!$K57 -> 67425 | M57: PAGADO | N57: CREDITO | O57: Mercancia - Proveedores
A58: ='COMPRAS 2025'!$D58-TODAY() -> -246 | B58: FACTURA | C58: PET EXOTIC LTDA | D58: 45802 | E58: 45772 | F58: =MONTH('COMPRAS 2025'!$E58) -> 4 | G58: 11136 | H58: 76046685-9 | I58: DATAMEDICA S.P.A | J58: 90000 | K58: 17100 | L58: ='COMPRAS 2025'!$J58+'COMPRAS 2025'!$K58 -> 107100 | M58: PAGADO | N58: CREDITO | O58: Mercancia - Proveedores
A59: ='COMPRAS 2025'!$D59-TODAY() -> -241 | B59: FACTURA | C59: PET EXOTIC SPA | D59: 45807 | E59: 45777 | F59: =MONTH('COMPRAS 2025'!$E59) -> 4 | G59: 101182 | H59: 76936850-7 | I59: ANIMAL CARE - ACWS S.A | J59: 89716 | K59: 17046 | L59: ='COMPRAS 2025'!$J59+'COMPRAS 2025'!$K59 -> 106762 | M59: PAGADO | N59: CREDITO | O59: Mercancia - Proveedores
A60: ='COMPRAS 2025'!$D60-TODAY() -> -236 | B60: FACTURA | C60: PET EXOTIC LTDA | D60: 45812 | E60: 45782 | F60: =MONTH('COMPRAS 2025'!$E60) -> 5 | G60: 115481 | H60: 76218200-9 | I60: DYKONOS CIA LIMITADA | J60: 130769 | K60: 24846 | L60: ='COMPRAS 2025'!$J60+'COMPRAS 2025'!$K60 -> 155615 | M60: PAGADO | N60: CREDITO | O60: Mercancia - Proveedores
A61: ='COMPRAS 2025'!$D61-TODAY() -> -236 | B61: NOTA DE CREDITO | C61: PET EXOTIC LTDA | D61: 45812 | E61: 45783 | F61: =MONTH('COMPRAS 2025'!$E61) -> 5 | G61: 10677 | H61: 76218200-9 | I61: DYKONOS CIA LIMITADA | J61: 10500 | K61: 1995 | L61: =-'COMPRAS 2025'!$K61 - 'COMPRAS 2025'!$J61 -> -12495 | M61: PAGADO | N61: CREDITO | O61: Mercancia - Proveedores
A62: ='COMPRAS 2025'!$D62-TODAY() -> -235 | B62: FACTURA | C62: PET EXOTIC LTDA | D62: 45813 | E62: 45783 | F62: =MONTH('COMPRAS 2025'!$E62) -> 5 | G62: 115482 | H62: 76218200-9 | I62: DYKONOS CIA LIMITADA | J62: 14995 | K62: 2849 | L62: ='COMPRAS 2025'!$K62 + 'COMPRAS 2025'!$J62 -> 17844 | M62: PAGADO | N62: CREDITO | O62: Mercancia - Proveedores
A63: ='COMPRAS 2025'!$D63-TODAY() -> -226 | B63: FACTURA | C63: PET EXOTIC LTDA | D63: 45822 | E63: 45792 | F63: =MONTH('COMPRAS 2025'!$E63) -> 5 | G63: 397334 | H63: 76080982-9 | I63: DIPROVET DISTRIBUIDORA DE PRODUCTOS VETERINARIOS SPA | J63: 20560 | K63: 3906 | L63: ='COMPRAS 2025'!$J63+'COMPRAS 2025'!$K63 -> 24466 | M63: PAGADO | N63: CREDITO | O63: Mercancia - Proveedores
A64: ='COMPRAS 2025'!$D64-TODAY() -> -226 | B64: FACTURA | C64: PET EXOTIC LTDA | D64: 45822 | E64: 45792 | F64: =MONTH('COMPRAS 2025'!$E64) -> 5 | G64: 397333 | H64: 76080982-9 | I64: DIPROVET DISTRIBUIDORA DE PRODUCTOS VETERINARIOS SPA | J64: 80500 | K64: 15295 | L64: ='COMPRAS 2025'!$J64+'COMPRAS 2025'!$K64 -> 95795 | M64: PAGADO | N64: CREDITO | O64: Mercancia - Proveedores
A65: ='COMPRAS 2025'!$D65-TODAY() -> -226 | B65: FACTURA | C65: PET EXOTIC LTDA | D65: 45822 | E65: 45792 | F65: =MONTH('COMPRAS 2025'!$E65) -> 5 | G65: 115704 | H65: 76218200-9 | I65: DYKONOS CIA LIMITADA | J65: 7120 | K65: 1353 | L65: ='COMPRAS 2025'!$J65+'COMPRAS 2025'!$K65 -> 8473 | M65: PAGADO | N65: CREDITO | O65: Mercancia - Proveedores
A66: ='COMPRAS 2025'!$D66-TODAY() -> -225 | B66: BOLETA | C66: RONALD RENE MIGUEL DIAZ ROJAS | D66: 45823 | E66: 45792 | F66: =MONTH('COMPRAS 2025'!$E66) -> 5 | G66: 14914 | H66: 76218200-9 | I66: DYKONOS CIA LIMITADA | J66: 44960 | K66: 8542 | L66: ='COMPRAS 2025'!$J66+'COMPRAS 2025'!$K66 -> 53502 | M66: PAGADO | N66: CREDITO | O66: Mercancia - Proveedores
A67: ='COMPRAS 2025'!$D67-TODAY() -> -222 | B67: FACTURA | C67: PET EXOTIC LTDA | D67: 45826 | E67: 45796 | F67: =MONTH('COMPRAS 2025'!$E67) -> 5 | G67: 397616 | H67: 76080982-9 | I67: DIPROVET DISTRIBUIDORA DE PRODUCTOS VETERINARIOS SPA | J67: 11980 | K67: 2276 | L67: ='COMPRAS 2025'!$J67+'COMPRAS 2025'!$K67 -> 14256 | M67: PAGADO | N67: CREDITO | O67: Mercancia - Proveedores
A68: ='COMPRAS 2025'!$D68-TODAY() -> -222 | B68: FACTURA | C68: PET EXOTIC LTDA | D68: 45826 | E68: 45796 | F68: =MONTH('COMPRAS 2025'!$E68) -> 5 | G68: 397617 | H68: 76080982-9 | I68: DIPROVET DISTRIBUIDORA DE PRODUCTOS VETERINARIOS SPA | J68: 12270 | K68: 2331 | L68: ='COMPRAS 2025'!$J68+'COMPRAS 2025'!$K68 -> 14601 | M68: PAGADO | N68: CREDITO | O68: Mercancia - Proveedores
A69: ='COMPRAS 2025'!$D69-TODAY() -> -222 | B69: FACTURA | C69: PET EXOTIC LTDA | D69: 45826 | E69: 45796 | F69: =MONTH('COMPRAS 2025'!$E69) -> 5 | G69: 397615 | H69: 76080982-9 | I69: DIPROVET DISTRIBUIDORA DE PRODUCTOS VETERINARIOS SPA | J69: 102710 | K69: 19515 | L69: ='COMPRAS 2025'!$J69+'COMPRAS 2025'!$K69 -> 122225 | M69: PAGADO | N69: CREDITO | O69: Mercancia - Proveedores
A70: ='COMPRAS 2025'!$D70-TODAY() -> -218 | B70: FACTURA | C70: PET EXOTIC LTDA | D70: 45830 | E70: 45800 | F70: =MONTH('COMPRAS 2025'!$E70) -> 5 | G70: 11230 | H70: 76046685-9 | I70: DATAMEDICA S.P.A | J70: 90000 | K70: 17100 | L70: ='COMPRAS 2025'!$J70+'COMPRAS 2025'!$K70 -> 107100 | M70: PAGADO | N70: CREDITO | O70: Mercancia - Proveedores
A71: ='COMPRAS 2025'!$D71-TODAY() -> -238 | B71: FACTURA | C71: PET EXOTIC LTDA | D71: 45810 | E71: 45810 | F71: =MONTH('COMPRAS 2025'!$E71) -> 6 | G71: 3615 | H71: 762510138 | I71: GRANJA AGRICOLA Y GANADERA LAURA ROSA LIMITADA | J71: 22681 | K71: 4309 | L71: ='COMPRAS 2025'!$J71+'COMPRAS 2025'!$K71 -> 26990 | M71: PAGADO | N71: DEBITO | O71: Mercancia - Proveedores
A72: ='COMPRAS 2025'!$D72-TODAY() -> -205 | B72: FACTURA | C72: PET EXOTIC LTDA | D72: 45843 | E72: 45813 | F72: =MONTH('COMPRAS 2025'!$E72) -> 6 | G72: 399796 | H72: 76080982-9 | I72: DIPROVET DISTRIBUIDORA DE PRODUCTOS VETERINARIOS SPA | J72: 142630 | K72: 27100 | L72: ='COMPRAS 2025'!$J72+'COMPRAS 2025'!$K72 -> 169730 | M72: PAGADO | N72: CREDITO | O72: Mercancia - Proveedores
A73: ='COMPRAS 2025'!$D73-TODAY() -> -205 | B73: FACTURA | C73: PET EXOTIC LTDA | D73: 45843 | E73: 45813 | F73: =MONTH('COMPRAS 2025'!$E73) -> 6 | G73: 399798 | H73: 76080982-9 | I73: DIPROVET DISTRIBUIDORA DE PRODUCTOS VETERINARIOS SPA | J73: 86110 | K73: 16361 | L73: ='COMPRAS 2025'!$J73+'COMPRAS 2025'!$K73 -> 102471 | M73: PAGADO | N73: CREDITO | O73: Mercancia - Proveedores
...

Sheet BOLETAS 2025
L1: CÓDIGO: | M1: PE-LC-01
H2: Registro Boletas 2025 | L2: VERSIÓN: | M2: 1
L3: FECHA: | M3: 45750
A4: ALERTA | B4: DOCUMENTO | C4: EMPRESA | D4: FECHA EMISION | E4: N° MES | F4: N° FOLIO | G4: RUT | H4: RAZON SOCIAL | I4: MONTO TOTAL | J4: ESTADO | K4: METODO DE PAGO | L4: CENTRO DE COSTOS | M4: DESCRIPCION
A5: =D5-TODAY() -> -385 | B5: BOLETA | C5: PET EXOTIC LTDA | D5: 45663 | E5: =MONTH('BOLETAS 2025'!$D5) -> 1 | F5: 1840257 | G5: 77178050-4 | H5: COPEC | I5: 20000 | J5: PAGADO | K5: EFECTIVO | L5: Combustible
A6: =D6-TODAY() -> -381 | B6: BOLETA | C6: PET EXOTIC LTDA | D6: 45667 | E6: =MONTH('BOLETAS 2025'!$D6) -> 1 | F6: 1843124 | G6: 77178050-4 | H6: COPEC | I6: 20000 | J6: PAGADO | K6: EFECTIVO | L6: Combustible
A7: =D7-TODAY() -> -375 | B7: BOLETA | C7: PET EXOTIC LTDA | D7: 45673 | E7: =MONTH('BOLETAS 2025'!$D7) -> 1 | F7: 1846498 | G7: 77178050-4 | H7: COPEC | I7: 20000 | J7: PAGADO | K7: DEBITO | L7: Combustible
A8: =D8-TODAY() -> -369 | B8: BOLETA | C8: PET EXOTIC LTDA | D8: 45679 | E8: =MONTH('BOLETAS 2025'!$D8) -> 1 | F8: 1851121 | G8: 77178050-4 | H8: COPEC | I8: 20000 | J8: PAGADO | K8: DEBITO | L8: Combustible
A9: =D9-TODAY() -> -367 | B9: BOLETA | C9: PET EXOTIC LTDA | D9: 45681 | E9: =MONTH('BOLETAS 2025'!$D9) -> 1 | F9: 2983224 | G9: 76587994-9 | H9: COPEC | I9: 20000 | J9: PAGADO | K9: EFECTIVO | L9: Combustible
A10: =D10-TODAY() -> -362 | B10: BOLETA | C10: PET EXOTIC LTDA | D10: 45686 | E10: =MONTH('BOLETAS 2025'!$D10) -> 1 | F10: 1855115 | G10: 77178050-4 | H10: COPEC | I10: 20000 | J10: PAGADO | K10: EFECTIVO | L10: Combustible
A11: =D11-TODAY() -> -359 | B11: BOLETA | C11: PET EXOTIC LTDA | D11: 45689 | E11: =MONTH('BOLETAS 2025'!$D11) -> 2 | F11: 23752985 | G11: 76358760-6 | H11: INVERSIONES ENEX S.A | I11: 20000 | J11: PAGADO | K11: DEBITO | L11: Combustible
A12: =D12-TODAY() -> -354 | B12: BOLETA | C12: PET EXOTIC LTDA | D12: 45694 | E12: =MONTH('BOLETAS 2025'!$D12) -> 2 | F12: 461600 | G12: 77669674-9 | H12: COPEC | I12: 20000 | J12: PAGADO | K12: DEBITO | L12: Combustible
A13: =D13-TODAY() -> -352 | B13: BOLETA | C13: PET EXOTIC LTDA | D13: 45696 | E13: =MONTH('BOLETAS 2025'!$D13) -> 2 | F13: 157967860 | G13: 94625000-7 | H13: INVERSIONES ENEX S.A | I13: 20000 | J13: PAGADO | K13: EFECTIVO | L13: Combustible
A14: =D14-TODAY() -> -349 | B14: BOLETA | C14: PET EXOTIC LTDA | D14: 45699 | E14: =MONTH('BOLETAS 2025'!$D14) -> 2 | F14: 1864379 | G14: 77178050-4 | H14: COPEC | I14: 20000 | J14: PAGADO | K14: EFECTIVO | L14: Combustible
A15: =D15-TODAY() -> -347 | B15: BOLETA | C15: PET EXOTIC LTDA | D15: 45701 | E15: =MONTH('BOLETAS 2025'!$D15) -> 2 | F15: 3758597 | G15: 76567598-7 | H15: COPEC | I15: 20000 | J15: PAGADO | K15: EFECTIVO | L15: Combustible
A16: =D16-TODAY() -> -345 | B16: BOLETA | C16: PET EXOTIC LTDA | D16: 45703 | E16: =MONTH('BOLETAS 2025'!$D16) -> 2 | F16: 1867122 | G16: 77178050-4 | H16: COPEC | I16: 20000 | J16: PAGADO | K16: EFECTIVO | L16: Combustible
... A22: =D22-TODAY() -> -305 | B22: BOLETA | C22: PET EXOTIC LTDA | D22: 45743 | E22: =MONTH('BOLETAS 2025'!$D22) -> 3 | F22: 3044835 | G22: 76587994-9 | H22: COPEC | I22: 20000 | J22: PAGADO | K22: DEBITO | L22: Combustible
A23: =D23-TODAY() -> -309 | B23: BOLETA | C23: PET EXOTIC LTDA | D23: 45739 | E23: =MONTH('BOLETAS 2025'!$D23) -> 3 | I23: 20000 | J23: PAGADO | K23: DEBITO | L23: Combustible
A24: =D24-TODAY() -> -279 | B24: BOLETA | C24: PET EXOTIC SPA | D24: 45769 | E24: =MONTH('BOLETAS 2025'!$D24) -> 4 | F24: 10865913 | G24: 88192900-7 | H24: FedEx | I24: 7496 | J24: PAGADO | K24: EFECTIVO | L24: Mercancia - Proveedores
A25: =D25-TODAY() -> -264 | B25: BOLETA | C25: PET EXOTIC LTDA | D25: 45784 | E25: =MONTH('BOLETAS 2025'!$D25) -> 5 | F25: 10869319 | G25: 88192900-7 | H25: FedEx | I25: 9587 | J25: PAGADO | K25: EFECTIVO | L25: Mercancia - Proveedores
A26: =D26-TODAY() -> -252 | B26: BOLETA | C26: PET EXOTIC LTDA | D26: 45796 | E26: =MONTH('BOLETAS 2025'!$D26) -> 5 | F26: 10872384 | G26: 88192384 | H26: FedEx | I26: 9587 | J26: PAGADO | K26: EFECTIVO | L26: Mercancia - Proveedores
A27: =D27-TODAY() -> -192 | B27: BOLETA | C27: PET EXOTIC LTDA | D27: 45856 | E27: =MONTH('BOLETAS 2025'!$D27) -> 7 | F27: 10886513 | G27: 881929007 | H27: Fedex | I27: 7130 | J27: PAGADO | K27: EFECTIVO | L27: Mercancia - Proveedores
A28: =D28-TODAY() -> -385 | B28: BOLETA | C28: PET EXOTIC LTDA | D28: 45663 | E28: =MONTH('BOLETAS 2025'!$D28) -> 1 | F28: 234524478 | G28: 59113305 | H28: Farmacia del doctor SIMI | I28: 6570 | J28: PAGADO | K28: DEBITO | L28: Mercancia - Proveedores
A29: =D29-TODAY() -> -376 | B29: BOLETA | C29: PET EXOTIC LTDA | D29: 45672 | E29: =MONTH('BOLETAS 2025'!$D29) -> 1 | F29: 74708079 | G29: 968111302 | H29: FAGASE S.A | I29: 10520 | J29: PAGADO | L29: Mercancia - Proveedores
A30: =D30-TODAY() -> -373 | B30: BOLETA | C30: PET EXOTIC LTDA | D30: 45675 | E30: =MONTH('BOLETAS 2025'!$D30) -> 1 | F30: 1093884396 | H30: SUPERMERCADO LIDER | I30: 10062 | J30: PAGADO | K30: DEBITO | L30: Mercancia - Proveedores
A31: =D31-TODAY() -> -372 | B31: BOLETA | C31: PET EXOTIC LTDA | D31: 45676 | E31: =MONTH('BOLETAS 2025'!$D31) -> 1 | F31: 5373 | G31: 772790058 | H31: INVERSIONES GASTRONOMICAS CHINAM PAS SPA | I31: 10945 | J31: PAGADO | K31: DEBITO | L31: Mercancia - Proveedores
A32: =D32-TODAY() -> -370 | B32: BOLETA | C32: PET EXOTIC LTDA | D32: 45678 | E32: =MONTH('BOLETAS 2025'!$D32) -> 1 | F32: 80435442 | G32: 968111302 | H32: FAGASE S.A | I32: 5070 | J32: PAGADO | K32: CREDITO | L32: Mercancia - Proveedores
A33: =D33-TODAY() -> -370 | B33: BOLETA | C33: PET EXOTIC LTDA | D33: 45678 | E33: =MONTH('BOLETAS 2025'!$D33) -> 1 | F33: 2056 | G33: 780442174 | H33: COMERCIALIZADORA D Y E SPA | I33: 12000 | J33: PAGADO | K33: DEBITO | L33: Mercancia - Proveedores
A34: =D34-TODAY() -> -363 | B34: BOLETA | C34: PET EXOTIC LTDA | D34: 45685 | E34: =MONTH('BOLETAS 2025'!$D34) -> 1 | F34: 2093276 | G34: 761670239 | H34: HUERTO SUR | I34: 3493 | J34: PAGADO | K34: DEBITO | L34: Mercancia - Proveedores
A35: =D35-TODAY() -> -361 | B35: BOLETA | C35: PET EXOTIC LTDA | D35: 45687 | E35: =MONTH('BOLETAS 2025'!$D35) -> 1 | F35: 1163313031 | G35: 761349465 | H35: SUPERMERCADO LIDER | I35: 112257 | J35: PAGADO | K35: DEBITO | L35: Mercancia - Proveedores
A36: =D36-TODAY() -> -361 | B36: BOLETA | C36: PET EXOTIC LTDA | D36: 45687 | E36: =MONTH('BOLETAS 2025'!$D36) -> 1 | F36: 2093382 | G36: 761670239 | H36: HUERTO SUR | I36: 3290 | J36: PAGADO | K36: DEBITO | L36: Mercancia - Proveedores
A37: =D37-TODAY() -> -369 | B37: BOLETA | C37: PET EXOTIC LTDA | D37: 45679 | E37: =MONTH('BOLETAS 2025'!$D37) -> 1 | F37: 1163342542 | G37: 76134946-5 | H37: SUPERMERCADO LIDER | I37: 47624 | J37: PAGADO | K37: EFECTIVO | L37: Mercancia - Proveedores
A38: =D38-TODAY() -> -367 | B38: BOLETA | C38: PET EXOTIC LTDA | D38: 45681 | E38: =MONTH('BOLETAS 2025'!$D38) -> 1 | F38: 2985085556 | G38: 81201000K | H38: CENCOSUD RETAIL S.A | I38: 52418 | J38: PAGADO | K38: DEBITO | L38: Mercancia - Proveedores
A39: =D39-TODAY() -> -369 | B39: BOLETA | C39: PET EXOTIC LTDA | D39: 45679 | E39: =MONTH('BOLETAS 2025'!$D39) -> 1 | F39: 246458 | G39: 898072002 | H39: FARMACIAS CRUZ VERDE | I39: 7383 | J39: PAGADO | K39: DEBITO | L39: Mercancia - Proveedores
A40: =D40-TODAY() -> -359 | B40: BOLETA | C40: PET EXOTIC LTDA | D40: 45689 | E40: =MONTH('BOLETAS 2025'!$D40) -> 2 | F40: 44042 | G40: 7553843k | H40: GENOVEVA DEL CARMEN | I40: 2600 | J40: PAGADO | K40: DEBITO | L40: Mercancia - Proveedores
A41: =D41-TODAY() -> -359 | B41: BOLETA | C41: PET EXOTIC LTDA | D41: 45689 | E41: =MONTH('BOLETAS 2025'!$D41) -> 2 | I41: 5000 | J41: PAGADO | L41: Mercancia - Proveedores
A42: =D42-TODAY() -> -359 | B42: BOLETA | C42: PET EXOTIC LTDA | D42: 45689 | E42: =MONTH('BOLETAS 2025'!$D42) -> 2 | F42: 77978686 | G42: 764333101 | H42: CENCOSUD SHOPPING S.A | I42: 1650 | J42: PAGADO | K42: DEBITO | L42: Mercancia - Proveedores
A43: =D43-TODAY() -> -358 | B43: BOLETA | C43: PET EXOTIC LTDA | D43: 45690 | E43: =MONTH('BOLETAS 2025'!$D43) -> 2 | F43: 34428 | G43: 968111302 | H43: FAGASE S.A | I43: 1690 | J43: PAGADO | K43: DEBITO | L43: Mercancia - Proveedores
A44: =D44-TODAY() -> -358 | B44: BOLETA | C44: PET EXOTIC LTDA | D44: 45690 | E44: =MONTH('BOLETAS 2025'!$D44) -> 2 | F44: 34427 | G44: 96811302 | H44: FAGASE S.A | I44: 5290 | J44: PAGADO | K44: DEBITO | L44: Mercancia - Proveedores
A45: =D45-TODAY() -> -357 | B45: BOLETA | C45: PET EXOTIC LTDA | D45: 45691 | E45: =MONTH('BOLETAS 2025'!$D45) -> 2 | F45: 19667 | G45: 898072002 | H45: CRUZ VERDE | I45: 1990 | J45: PAGADO | K45: DEBITO | L45: Mercancia - Proveedores
...

Sheet PROVEEDORES CREDITO
F2: PROVEEDORES CREDITO
A4: ESTADO | B4: PROVEEDOR | C4: RUT | D4: RAZON SOCIAL | E4: MONTO CREDITO | F4: MONTO UTILIZADO | G4: MONTO DISPONIBLE | H4: DESCRIPCION | I4: COMENTARIOS
D5: PROVEEDORES | E5: - | F5: -
A6: PENDIENTE | B6: CALS | C6: 81643200-6 | D6: COOPERATIVA AGRICOLA LECHERA STGO. | E6: 0 | F6: =SUMIFS('COMPRAS 2025'!$L:$L,'COMPRAS 2025'!$M:$M,'PROVEEDORES CREDITO'!A6,'COMPRAS 2025'!$I:$I,'PROVEEDORES CREDITO'!D6) -> 0 | G6: =E6-F6 -> 0 | H6: $1.000.000 (30 DIAS) LTDA / $1.000.000 (30 DIAS) SPA | I6: NO HAY CREDITO / SOLO CONTADO
A7: PENDIENTE | B7: EQUIVET | C7: 76533504-3 | D7: CONSULTORES Y SERVICIOS INFORMATICOS SRT SPA | E7: 1000000 | F7: =SUMIFS('COMPRAS 2025'!$L:$L,'COMPRAS 2025'!$M:$M,'PROVEEDORES CREDITO'!A7,'COMPRAS 2025'!$I:$I,'PROVEEDORES CREDITO'!D7) -> 0 | G7: =E7-F7 -> 1000000 | H7: $1.000.000 (60 DIAS) SPA / LTDA
A8: PENDIENTE | B8: ANIMAL CARE | C8: 76936850-7 | D8: ANIMAL CARE - ACWS S.A | E8: 1000000 | F8: =SUMIFS('COMPRAS 2025'!$L:$L,'COMPRAS 2025'!$M:$M,'PROVEEDORES CREDITO'!A8,'COMPRAS 2025'!$I:$I,'PROVEEDORES CREDITO'!D8) -> 0 | G8: =E8-F8 -> 1000000 | H8: $1.000.000 (30 DIAS) SPA | I8: PENDIENTE AGREGAR LTDA
A9: PENDIENTE | B9: P&P | C9: 76501918-4 | D9: POBLETE Y POBLETE LIMITADA | E9: 1000000 | F9: =SUMIFS('COMPRAS 2025'!$L:$L,'COMPRAS 2025'!$M:$M,'PROVEEDORES CREDITO'!A9,'COMPRAS 2025'!$I:$I,'PROVEEDORES CREDITO'!D9) -> 0 | G9: =E9-F9 -> 1000000 | H9: $1.000.000 (30 DIAS) SPA | I9: PENDIENTE AGREGAR LTDA
A10: PENDIENTE | B10: DIPROVET | C10: 76080982-9 | D10: DIPROVET DISTRIBUIDORA DE PRODUCTOS VETERINARIOS SPA | E10: 1500000 | F10: =SUMIFS('COMPRAS 2025'!$L:$L,'COMPRAS 2025'!$M:$M,'PROVEEDORES CREDITO'!A10,'COMPRAS 2025'!$I:$I,'PROVEEDORES CREDITO'!D10) -> 0 | G10: =E10-F10 -> 1500000 | H10: $1.500.000 (30 DIAS) LTDA
A11: PENDIENTE | B11: LEGUER | C11: 76199127-2 | D11: COMERCIAL LEGUER S.A | E11: 3000000 | F11: =SUMIFS('COMPRAS 2025'!$L:$L,'COMPRAS 2025'!$M:$M,'PROVEEDORES CREDITO'!A11,'COMPRAS 2025'!$I:$I,'PROVEEDORES CREDITO'!D11) -> 0 | G11: =E11-F11 -> 3000000 | H11: $3.000.000 (30 DIAS) LTDA
A12: PENDIENTE | B12: DYKONOS | C12: 76218200-9 | D12: DYKONOS CIA LIMITADA | E12: 500000 | F12: =SUMIFS('COMPRAS 2025'!$L:$L,'COMPRAS 2025'!$M:$M,'PROVEEDORES CREDITO'!A12,'COMPRAS 2025'!$I:$I,'PROVEEDORES CREDITO'!D12) -> 0 | G12: =E12-F12 -> 500000 | H12: $500.000 (30 DIAS) LTDA
A13: PENDIENTE | B13: CLINICAL MARKET | C13: 76111113-2 | D13: CLINICAL MARKET S.A. | E13: 1000000 | F13: =SUMIFS('COMPRAS 2025'!$L:$L,'COMPRAS 2025'!$M:$M,'PROVEEDORES CREDITO'!A13,'COMPRAS 2025'!$I:$I,'PROVEEDORES CREDITO'!D13) -> 0 | G13: =E13-F13 -> 1000000 | H13: $1.000.000 (15 DIAS) LTDA
A14: PENDIENTE | E14: 0 | F14: =SUMIFS('COMPRAS 2025'!$L:$L,'COMPRAS 2025'!$M:$M,'PROVEEDORES CREDITO'!A14,'COMPRAS 2025'!$I:$I,'PROVEEDORES CREDITO'!D14) -> 0 | G14: =E14-F14 -> 0
A15: PENDIENTE | E15: 0 | F15: =SUMIFS('COMPRAS 2025'!$L:$L,'COMPRAS 2025'!$M:$M,'PROVEEDORES CREDITO'!A15,'COMPRAS 2025'!$I:$I,'PROVEEDORES CREDITO'!D15) -> 0 | G15: =E15-F15 -> 0
A16: PENDIENTE | E16: 0 | F16: =SUMIFS('COMPRAS 2025'!$L:$L,'COMPRAS 2025'!$M:$M,'PROVEEDORES CREDITO'!A16,'COMPRAS 2025'!$I:$I,'PROVEEDORES CREDITO'!D16) -> 0 | G16: =E16-F16 -> 0
D17: TOTALES | E17: =SUM(E5:E16) -> 9000000 | F17: =SUM(F5:F16) -> 0 | G17: =SUM(G5:G16) -> 9000000

Sheet LISTA PROVEEDORES
A1: 77147998-7 | B1: INVERSIONES GIORGIO JULIAN GRANDI CORRO EIRL
A2: 77034255- 4 | B2: QUINTAVET SPA
A3: 76936850-7 | B3: ANIMAL CARE - ACWS S.A
A4: 76501918-4 | B4: POBLETE Y POBLETE LIMITADA
A5: 76839842-9 | B5: COMERCIALIZADORA MGASES SPA
A6: 81643200-6 | B6: COOPERATIVA AGRICOLA LECHERA STGO.
A7: 76080982-9 | B7: DIPROVET DISTRIBUIDORA DE PRODUCTOS VETERINARIOS SPA
A8: 76979850-1 | B8: FABRICA DE BANDEJAS LIMITADA
A9: 11635852-2 | B9: PAOLA DEBORAH STACK LARA
A10: 76157270-9 | B10: SOCIEDAD COMERCIAL AQUAMUNDO LIMITADA
A11: - | B11: CANVA
A12: 96806980-2 | B12: ENTEL PCS TELECOMUNICACIONES SA
... A43: 76134946-5 | B43: SUPERMERCADO LIDER

Sheet DATOS
A1: Comisiones
A2: Mercancia - Proveedores
A3: Remuneraciones
A4: Honorarios Profesionales
A5: Servicios Contables
A6: Publicidad y Marketing
A7: Arriendo y Gastos Comunes
A8: Servicio Electricidad
A9: Servicio Agua
A10: Servicio Telefonía
A11: Servicio Internet
A12: Gastos de Oficina
... A23: Combustible
